Workbook

Sheet Instructions
A1: Golf Trip Scoring — how to run a trip
A3: BEFORE THE TRIP (Setup sheet — yellow cells are the only editable ones)
A4: 1. Enter the trip name and year.
A5: 2. Enter each player's name and Starting H'cap (Golflink no. and nickname are optional).
A6: Leave unused player rows completely blank — they are ignored everywhere.
A7: 3. For each round, enter the course name and the Par and Stroke Index (SI) of every hole.
A8: The 'SI check' row must show OK (each of 1-18 used exactly once). Leave unused rounds blank.
A10: EACH DAY (Round sheets — organisers enter everything from the physical cards)
A11: 1. Enter each player's gross score per hole in the yellow Score cells.
A12: Enter 0 (or leave blank) for a wiped hole — it scores no points.
A13: 2. If a card was filled out incorrectly, enter a 1 or 2 point Card penalty for that player.
A14: The penalty reduces their Round points, daily position and handicap outcome,
... A39: Add them once via Automate > New Script, paste the code, Save Script.

Sheet Setup
A1: Trip Name:
A2: Year: | G2: Courses — enter course name, then Par and Stroke Index for each hole
G3: Round 1 | I3: Round 2 | K3: Round 3 | M3: Round 4 | O3: Round 5 | Q3: Round 6 | S3: Round 7 | U3: Round 8 | W3: Round 9 | Y3: Round 10
A4: No. | B4: Player Name | C4: Golflink No. | D4: Nickname | E4: Starting H'cap | F4: Course:
A5: 1 | F5: Hole | G5: Par | H5: SI | I5: Par | J5: SI | K5: Par | L5: SI | M5: Par | N5: SI | O5: Par | P5: SI | Q5: Par | R5: SI | S5: Par | T5: SI | U5: Par | V5: SI | W5: Par | X5: SI | Y5: Par | Z5: SI
A6: 2 | F6: 1
A7: 3 | F7: 2
A8: 4 | F8: 3
A9: 5 | F9: 4
A10: 6 | F10: 5
A11: 7 | F11: 6
A12: 8 | F12: 7
A13: 9 | F13: 8
A14: 10 | F14: 9
A15: 11 | F15: 10
A16: 12 | F16: 11
A17: 13 | F17: 12
... A23: 19 | F23: 18
A24: 20 | F24: Par total | G24: =IF(COUNT(G6:G23)=0,"",SUM(G6:G23)) | I24: =IF(COUNT(I6:I23)=0,"",SUM(I6:I23)) | K24: =IF(COUNT(K6:K23)=0,"",SUM(K6:K23)) | M24: =IF(COUNT(M6:M23)=0,"",SUM(M6:M23)) | O24: =IF(COUNT(O6:O23)=0,"",SUM(O6:O23)) | Q24: =IF(COUNT(Q6:Q23)=0,"",SUM(Q6:Q23)) | S24: =IF(COUNT(S6:S23)=0,"",SUM(S6:S23)) | U24: =IF(COUNT(U6:U23)=0,"",SUM(U6:U23)) | W24: =IF(COUNT(W6:W23)=0,"",SUM(W6:W23)) | Y24: =IF(COUNT(Y6:Y23)=0,"",SUM(Y6:Y23))
A25: 21 | F25: SI check | G25: =IF(COUNT(H6:H23)=0,"",IF(AND(COUNT(H6:H23)=18,SUM(H6:H23)=171,SUMPRODUCT(--(COUNTIF(H6:H23,H6:H23)>1))=0),"OK","CHECK")) | I25: =IF(COUNT(J6:J23)=0,"",IF(AND(COUNT(J6:J23)=18,SUM(J6:J23)=171,SUMPRODUCT(--(COUNTIF(J6:J23,J6:J23)>1))=0),"OK","CHECK")) | K25: =IF(COUNT(L6:L23)=0,"",IF(AND(COUNT(L6:L23)=18,SUM(L6:L23)=171,SUMPRODUCT(--(COUNTIF(L6:L23,L6:L23)>1))=0),"OK","CHECK")) | M25: =IF(COUNT(N6:N23)=0,"",IF(AND(COUNT(N6:N23)=18,SUM(N6:N23)=171,SUMPRODUCT(--(COUNTIF(N6:N23,N6:N23)>1))=0),"OK","CHECK")) | O25: =IF(COUNT(P6:P23)=0,"",IF(AND(COUNT(P6:P23)=18,SUM(P6:P23)=171,SUMPRODUCT(--(COUNTIF(P6:P23,P6:P23)>1))=0),"OK","CHECK")) | Q25: =IF(COUNT(R6:R23)=0,"",IF(AND(COUNT(R6:R23)=18,SUM(R6:R23)=171,SUMPRODUCT(--(COUNTIF(R6:R23,R6:R23)>1))=0),"OK","CHECK")) | S25: =IF(COUNT(T6:T23)=0,"",IF(AND(COUNT(T6:T23)=18,SUM(T6:T23)=171,SUMPRODUCT(--(COUNTIF(T6:T23,T6:T23)>1))=0),"OK","CHECK")) | U25: =IF(COUNT(V6:V23)=0,"",IF(AND(COUNT(V6:V23)=18,SUM(V6:V23)=171,SUMPRODUCT(--(COUNTIF(V6:V23,V6:V23)>1))=0),"OK","CHECK")) | W25: =IF(COUNT(X6:X23)=0,"",IF(AND(COUNT(X6:X23)=18,SUM(X6:X23)=171,SUMPRODUCT(--(COUNTIF(X6:X23,X6:X23)>1))=0),"OK","CHECK")) | Y25: =IF(COUNT(Z6:Z23)=0,"",IF(AND(COUNT(Z6:Z23)=18,SUM(Z6:Z23)=171,SUMPRODUCT(--(COUNTIF(Z6:Z23,Z6:Z23)>1))=0),"OK","CHECK"))
A26: 22
A27: 23
A28: 24
A29: 25
A30: 26
A31: 27
A32: 28
A33: 29
A34: 30
A35: 31
A36: 32

Sheet Leaderboard
A1: Leaderboard | Y1: =MAX(('Round 1'!$S$31>0)*1,('Round 2'!$S$31>0)*2,('Round 3'!$S$31>0)*3,('Round 4'!$S$31>0)*4,('Round 5'!$S$31>0)*5,('Round 6'!$S$31>0)*6,('Round 7'!$S$31>0)*7,('Round 8'!$S$31>0)*8,('Round 9'!$S$31>0)*9,('Round 10'!$S$31>0)*10)
A2: Pos | B2: Player | C2: Total | D2: Rd 1 | E2: Pos | F2: Rd 2 | G2: Pos | H2: Rd 3 | I2: Pos | J2: Rd 4 | K2: Pos | L2: Rd 5 | M2: Pos | N2: Rd 6 | O2: Pos | P2: Rd 7 | Q2: Pos | R2: Rd 8 | S2: Pos | T2: Rd 9 | U2: Pos | V2: Rd 10 | W2: Pos
A3: =IF($B3="","",1+SUMPRODUCT(($B$3:$B$34<>"")*(($C$3:$C$34>C3)+(($C$3:$C$34=C3)*($Y$3:$Y$34>Y3))))) | B3: =IF(Setup!B5="","",Setup!B5) | C3: =IF($B3="","",SUM(D3,F3,H3,J3,L3,N3,P3,R3,T3,V3)) | D3: =IF($B3="","",IF('Round 1'!$S$31=0,"",'Round 1'!$F$32)) | E3: =IF($B3="","",IF('Round 1'!$S$31=0,"",'Round 1'!$Q$32)) | F3: =IF($B3="","",IF('Round 2'!$S$31=0,"",'Round 2'!$F$32)) | G3: =IF($B3="","",IF('Round 2'!$S$31=0,"",'Round 2'!$Q$32)) | H3: =IF($B3="","",IF('Round 3'!$S$31=0,"",'Round 3'!$F$32)) | I3: =IF($B3="","",IF('Round 3'!$S$31=0,"",'Round 3'!$Q$32)) | J3: =IF($B3="","",IF('Round 4'!$S$31=0,"",'Round 4'!$F$32)) | K3: =IF($B3="","",IF('Round 4'!$S$31=0,"",'Round 4'!$Q$32)) | L3: =IF($B3="","",IF('Round 5'!$S$31=0,"",'Round 5'!$F$32)) | M3: =IF($B3="","",IF('Round 5'!$S$31=0,"",'Round 5'!$Q$32)) | N3: =IF($B3="","",IF('Round 6'!$S$31=0,"",'Round 6'!$F$32)) | O3: =IF($B3="","",IF('Round 6'!$S$31=0,"",'Round 6'!$Q$32)) | P3: =IF($B3="","",IF('Round 7'!$S$31=0,"",'Round 7'!$F$32)) | Q3: =IF($B3="","",IF('Round 7'!$S$31=0,"",'Round 7'!$Q$32)) | R3: =IF($B3="","",IF('Round 8'!$S$31=0,"",'Round 8'!$F$32)) | S3: =IF($B3="","",IF('Round 8'!$S$31=0,"",'Round 8'!$Q$32)) | T3: =IF($B3="","",IF('Round 9'!$S$31=0,"",'Round 9'!$F$32)) | U3: =IF($B3="","",IF('Round 9'!$S$31=0,"",'Round 9'!$Q$32)) | V3: =IF($B3="","",IF('Round 10'!$S$31=0,"",'Round 10'!$F$32)) | W3: =IF($B3="","",IF('Round 10'!$S$31=0,"",'Round 10'!$Q$32)) | Y3: =IF(OR($B3="",$Y$1=0),0,CHOOSE($Y$1,'Round 1'!$P$32,'Round 2'!$P$32,'Round 3'!$P$32,'Round 4'!$P$32,'Round 5'!$P$32,'Round 6'!$P$32,'Round 7'!$P$32,'Round 8'!$P$32,'Round 9'!$P$32,'Round 10'!$P$32))
A4: =IF($B4="","",1+SUMPRODUCT(($B$3:$B$34<>"")*(($C$3:$C$34>C4)+(($C$3:$C$34=C4)*($Y$3:$Y$34>Y4))))) | B4: =IF(Setup!B6="","",Setup!B6) | C4: =IF($B4="","",SUM(D4,F4,H4,J4,L4,N4,P4,R4,T4,V4)) | D4: =IF($B4="","",IF('Round 1'!$S$31=0,"",'Round 1'!$F$33)) | E4: =IF($B4="","",IF('Round 1'!$S$31=0,"",'Round 1'!$Q$33)) | F4: =IF($B4="","",IF('Round 2'!$S$31=0,"",'Round 2'!$F$33)) | G4: =IF($B4="","",IF('Round 2'!$S$31=0,"",'Round 2'!$Q$33)) | H4: =IF($B4="","",IF('Round 3'!$S$31=0,"",'Round 3'!$F$33)) | I4: =IF($B4="","",IF('Round 3'!$S$31=0,"",'Round 3'!$Q$33)) | J4: =IF($B4="","",IF('Round 4'!$S$31=0,"",'Round 4'!$F$33)) | K4: =IF($B4="","",IF('Round 4'!$S$31=0,"",'Round 4'!$Q$33)) | L4: =IF($B4="","",IF('Round 5'!$S$31=0,"",'Round 5'!$F$33)) | M4: =IF($B4="","",IF('Round 5'!$S$31=0,"",'Round 5'!$Q$33)) | N4: =IF($B4="","",IF('Round 6'!$S$31=0,"",'Round 6'!$F$33)) | O4: =IF($B4="","",IF('Round 6'!$S$31=0,"",'Round 6'!$Q$33)) | P4: =IF($B4="","",IF('Round 7'!$S$31=0,"",'Round 7'!$F$33)) | Q4: =IF($B4="","",IF('Round 7'!$S$31=0,"",'Round 7'!$Q$33)) | R4: =IF($B4="","",IF('Round 8'!$S$31=0,"",'Round 8'!$F$33)) | S4: =IF($B4="","",IF('Round 8'!$S$31=0,"",'Round 8'!$Q$33)) | T4: =IF($B4="","",IF('Round 9'!$S$31=0,"",'Round 9'!$F$33)) | U4: =IF($B4="","",IF('Round 9'!$S$31=0,"",'Round 9'!$Q$33)) | V4: =IF($B4="","",IF('Round 10'!$S$31=0,"",'Round 10'!$F$33)) | W4: =IF($B4="","",IF('Round 10'!$S$31=0,"",'Round 10'!$Q$33)) | Y4: =IF(OR($B4="",$Y$1=0),0,CHOOSE($Y$1,'Round 1'!$P$33,'Round 2'!$P$33,'Round 3'!$P$33,'Round 4'!$P$33,'Round 5'!$P$33,'Round 6'!$P$33,'Round 7'!$P$33,'Round 8'!$P$33,'Round 9'!$P$33,'Round 10'!$P$33))
A5: =IF($B5="","",1+SUMPRODUCT(($B$3:$B$34<>"")*(($C$3:$C$34>C5)+(($C$3:$C$34=C5)*($Y$3:$Y$34>Y5))))) | B5: =IF(Setup!B7="","",Setup!B7) | C5: =IF($B5="","",SUM(D5,F5,H5,J5,L5,N5,P5,R5,T5,V5)) | D5: =IF($B5="","",IF('Round 1'!$S$31=0,"",'Round 1'!$F$34)) | E5: =IF($B5="","",IF('Round 1'!$S$31=0,"",'Round 1'!$Q$34)) | F5: =IF($B5="","",IF('Round 2'!$S$31=0,"",'Round 2'!$F$34)) | G5: =IF($B5="","",IF('Round 2'!$S$31=0,"",'Round 2'!$Q$34)) | H5: =IF($B5="","",IF('Round 3'!$S$31=0,"",'Round 3'!$F$34)) | I5: =IF($B5="","",IF('Round 3'!$S$31=0,"",'Round 3'!$Q$34)) | J5: =IF($B5="","",IF('Round 4'!$S$31=0,"",'Round 4'!$F$34)) | K5: =IF($B5="","",IF('Round 4'!$S$31=0,"",'Round 4'!$Q$34)) | L5: =IF($B5="","",IF('Round 5'!$S$31=0,"",'Round 5'!$F$34)) | M5: =IF($B5="","",IF('Round 5'!$S$31=0,"",'Round 5'!$Q$34)) | N5: =IF($B5="","",IF('Round 6'!$S$31=0,"",'Round 6'!$F$34)) | O5: =IF($B5="","",IF('Round 6'!$S$31=0,"",'Round 6'!$Q$34)) | P5: =IF($B5="","",IF('Round 7'!$S$31=0,"",'Round 7'!$F$34)) | Q5: =IF($B5="","",IF('Round 7'!$S$31=0,"",'Round 7'!$Q$34)) | R5: =IF($B5="","",IF('Round 8'!$S$31=0,"",'Round 8'!$F$34)) | S5: =IF($B5="","",IF('Round 8'!$S$31=0,"",'Round 8'!$Q$34)) | T5: =IF($B5="","",IF('Round 9'!$S$31=0,"",'Round 9'!$F$34)) | U5: =IF($B5="","",IF('Round 9'!$S$31=0,"",'Round 9'!$Q$34)) | V5: =IF($B5="","",IF('Round 10'!$S$31=0,"",'Round 10'!$F$34)) | W5: =IF($B5="","",IF('Round 10'!$S$31=0,"",'Round 10'!$Q$34)) | Y5: =IF(OR($B5="",$Y$1=0),0,CHOOSE($Y$1,'Round 1'!$P$34,'Round 2'!$P$34,'Round 3'!$P$34,'Round 4'!$P$34,'Round 5'!$P$34,'Round 6'!$P$34,'Round 7'!$P$34,'Round 8'!$P$34,'Round 9'!$P$34,'Round 10'!$P$34))
A6: =IF($B6="","",1+SUMPRODUCT(($B$3:$B$34<>"")*(($C$3:$C$34>C6)+(($C$3:$C$34=C6)*($Y$3:$Y$34>Y6))))) | B6: =IF(Setup!B8="","",Setup!B8) | C6: =IF($B6="","",SUM(D6,F6,H6,J6,L6,N6,P6,R6,T6,V6)) | D6: =IF($B6="","",IF('Round 1'!$S$31=0,"",'Round 1'!$F$35)) | E6: =IF($B6="","",IF('Round 1'!$S$31=0,"",'Round 1'!$Q$35)) | F6: =IF($B6="","",IF('Round 2'!$S$31=0,"",'Round 2'!$F$35)) | G6: =IF($B6="","",IF('Round 2'!$S$31=0,"",'Round 2'!$Q$35)) | H6: =IF($B6="","",IF('Round 3'!$S$31=0,"",'Round 3'!$F$35)) | I6: =IF($B6="","",IF('Round 3'!$S$31=0,"",'Round 3'!$Q$35)) | J6: =IF($B6="","",IF('Round 4'!$S$31=0,"",'Round 4'!$F$35)) | K6: =IF($B6="","",IF('Round 4'!$S$31=0,"",'Round 4'!$Q$35)) | L6: =IF($B6="","",IF('Round 5'!$S$31=0,"",'Round 5'!$F$35)) | M6: =IF($B6="","",IF('Round 5'!$S$31=0,"",'Round 5'!$Q$35)) | N6: =IF($B6="","",IF('Round 6'!$S$31=0,"",'Round 6'!$F$35)) | O6: =IF($B6="","",IF('Round 6'!$S$31=0,"",'Round 6'!$Q$35)) | P6: =IF($B6="","",IF('Round 7'!$S$31=0,"",'Round 7'!$F$35)) | Q6: =IF($B6="","",IF('Round 7'!$S$31=0,"",'Round 7'!$Q$35)) | R6: =IF($B6="","",IF('Round 8'!$S$31=0,"",'Round 8'!$F$35)) | S6: =IF($B6="","",IF('Round 8'!$S$31=0,"",'Round 8'!$Q$35)) | T6: =IF($B6="","",IF('Round 9'!$S$31=0,"",'Round 9'!$F$35)) | U6: =IF($B6="","",IF('Round 9'!$S$31=0,"",'Round 9'!$Q$35)) | V6: =IF($B6="","",IF('Round 10'!$S$31=0,"",'Round 10'!$F$35)) | W6: =IF($B6="","",IF('Round 10'!$S$31=0,"",'Round 10'!$Q$35)) | Y6: =IF(OR($B6="",$Y$1=0),0,CHOOSE($Y$1,'Round 1'!$P$35,'Round 2'!$P$35,'Round 3'!$P$35,'Round 4'!$P$35,'Round 5'!$P$35,'Round 6'!$P$35,'Round 7'!$P$35,'Round 8'!$P$35,'Round 9'!$P$35,'Round 10'!$P$35))
A7: =IF($B7="","",1+SUMPRODUCT(($B$3:$B$34<>"")*(($C$3:$C$34>C7)+(($C$3:$C$34=C7)*($Y$3:$Y$34>Y7))))) | B7: =IF(Setup!B9="","",Setup!B9) | C7: =IF($B7="","",SUM(D7,F7,H7,J7,L7,N7,P7,R7,T7,V7)) | D7: =IF($B7="","",IF('Round 1'!$S$31=0,"",'Round 1'!$F$36)) | E7: =IF($B7="","",IF('Round 1'!$S$31=0,"",'Round 1'!$Q$36)) | F7: =IF($B7="","",IF('Round 2'!$S$31=0,"",'Round 2'!$F$36)) | G7: =IF($B7="","",IF('Round 2'!$S$31=0,"",'Round 2'!$Q$36)) | H7: =IF($B7="","",IF('Round 3'!$S$31=0,"",'Round 3'!$F$36)) | I7: =IF($B7="","",IF('Round 3'!$S$31=0,"",'Round 3'!$Q$36)) | J7: =IF($B7="","",IF('Round 4'!$S$31=0,"",'Round 4'!$F$36)) | K7: =IF($B7="","",IF('Round 4'!$S$31=0,"",'Round 4'!$Q$36)) | L7: =IF($B7="","",IF('Round 5'!$S$31=0,"",'Round 5'!$F$36)) | M7: =IF($B7="","",IF('Round 5'!$S$31=0,"",'Round 5'!$Q$36)) | N7: =IF($B7="","",IF('Round 6'!$S$31=0,"",'Round 6'!$F$36)) | O7: =IF($B7="","",IF('Round 6'!$S$31=0,"",'Round 6'!$Q$36)) | P7: =IF($B7="","",IF('Round 7'!$S$31=0,"",'Round 7'!$F$36)) | Q7: =IF($B7="","",IF('Round 7'!$S$31=0,"",'Round 7'!$Q$36)) | R7: =IF($B7="","",IF('Round 8'!$S$31=0,"",'Round 8'!$F$36)) | S7: =IF($B7="","",IF('Round 8'!$S$31=0,"",'Round 8'!$Q$36)) | T7: =IF($B7="","",IF('Round 9'!$S$31=0,"",'Round 9'!$F$36)) | U7: =IF($B7="","",IF('Round 9'!$S$31=0,"",'Round 9'!$Q$36)) | V7: =IF($B7="","",IF('Round 10'!$S$31=0,"",'Round 10'!$F$36)) | W7: =IF($B7="","",IF('Round 10'!$S$31=0,"",'Round 10'!$Q$36)) | Y7: =IF(OR($B7="",$Y$1=0),0,CHOOSE($Y$1,'Round 1'!$P$36,'Round 2'!$P$36,'Round 3'!$P$36,'Round 4'!$P$36,'Round 5'!$P$36,'Round 6'!$P$36,'Round 7'!$P$36,'Round 8'!$P$36,'Round 9'!$P$36,'Round 10'!$P$36))
A8: =IF($B8="","",1+SUMPRODUCT(($B$3:$B$34<>"")*(($C$3:$C$34>C8)+(($C$3:$C$34=C8)*($Y$3:$Y$34>Y8))))) | B8: =IF(Setup!B10="","",Setup!B10) | C8: =IF($B8="","",SUM(D8,F8,H8,J8,L8,N8,P8,R8,T8,V8)) | D8: =IF($B8="","",IF('Round 1'!$S$31=0,"",'Round 1'!$F$37)) | E8: =IF($B8="","",IF('Round 1'!$S$31=0,"",'Round 1'!$Q$37)) | F8: =IF($B8="","",IF('Round 2'!$S$31=0,"",'Round 2'!$F$37)) | G8: =IF($B8="","",IF('Round 2'!$S$31=0,"",'Round 2'!$Q$37)) | H8: =IF($B8="","",IF('Round 3'!$S$31=0,"",'Round 3'!$F$37)) | I8: =IF($B8="","",IF('Round 3'!$S$31=0,"",'Round 3'!$Q$37)) | J8: =IF($B8="","",IF('Round 4'!$S$31=0,"",'Round 4'!$F$37)) | K8: =IF($B8="","",IF('Round 4'!$S$31=0,"",'Round 4'!$Q$37)) | L8: =IF($B8="","",IF('Round 5'!$S$31=0,"",'Round 5'!$F$37)) | M8: =IF($B8="","",IF('Round 5'!$S$31=0,"",'Round 5'!$Q$37)) | N8: =IF($B8="","",IF('Round 6'!$S$31=0,"",'Round 6'!$F$37)) | O8: =IF($B8="","",IF('Round 6'!$S$31=0,"",'Round 6'!$Q$37)) | P8: =IF($B8="","",IF('Round 7'!$S$31=0,"",'Round 7'!$F$37)) | Q8: =IF($B8="","",IF('Round 7'!$S$31=0,"",'Round 7'!$Q$37)) | R8: =IF($B8="","",IF('Round 8'!$S$31=0,"",'Round 8'!$F$37)) | S8: =IF($B8="","",IF('Round 8'!$S$31=0,"",'Round 8'!$Q$37)) | T8: =IF($B8="","",IF('Round 9'!$S$31=0,"",'Round 9'!$F$37)) | U8: =IF($B8="","",IF('Round 9'!$S$31=0,"",'Round 9'!$Q$37)) | V8: =IF($B8="","",IF('Round 10'!$S$31=0,"",'Round 10'!$F$37)) | W8: =IF($B8="","",IF('Round 10'!$S$31=0,"",'Round 10'!$Q$37)) | Y8: =IF(OR($B8="",$Y$1=0),0,CHOOSE($Y$1,'Round 1'!$P$37,'Round 2'!$P$37,'Round 3'!$P$37,'Round 4'!$P$37,'Round 5'!$P$37,'Round 6'!$P$37,'Round 7'!$P$37,'Round 8'!$P$37,'Round 9'!$P$37,'Round 10'!$P$37))
A9: =IF($B9="","",1+SUMPRODUCT(($B$3:$B$34<>"")*(($C$3:$C$34>C9)+(($C$3:$C$34=C9)*($Y$3:$Y$34>Y9))))) | B9: =IF(Setup!B11="","",Setup!B11) | C9: =IF($B9="","",SUM(D9,F9,H9,J9,L9,N9,P9,R9,T9,V9)) | D9: =IF($B9="","",IF('Round 1'!$S$31=0,"",'Round 1'!$F$38)) | E9: =IF($B9="","",IF('Round 1'!$S$31=0,"",'Round 1'!$Q$38)) | F9: =IF($B9="","",IF('Round 2'!$S$31=0,"",'Round 2'!$F$38)) | G9: =IF($B9="","",IF('Round 2'!$S$31=0,"",'Round 2'!$Q$38)) | H9: =IF($B9="","",IF('Round 3'!$S$31=0,"",'Round 3'!$F$38)) | I9: =IF($B9="","",IF('Round 3'!$S$31=0,"",'Round 3'!$Q$38)) | J9: =IF($B9="","",IF('Round 4'!$S$31=0,"",'Round 4'!$F$38)) | K9: =IF($B9="","",IF('Round 4'!$S$31=0,"",'Round 4'!$Q$38)) | L9: =IF($B9="","",IF('Round 5'!$S$31=0,"",'Round 5'!$F$38)) | M9: =IF($B9="","",IF('Round 5'!$S$31=0,"",'Round 5'!$Q$38)) | N9: =IF($B9="","",IF('Round 6'!$S$31=0,"",'Round 6'!$F$38)) | O9: =IF($B9="","",IF('Round 6'!$S$31=0,"",'Round 6'!$Q$38)) | P9: =IF($B9="","",IF('Round 7'!$S$31=0,"",'Round 7'!$F$38)) | Q9: =IF($B9="","",IF('Round 7'!$S$31=0,"",'Round 7'!$Q$38)) | R9: =IF($B9="","",IF('Round 8'!$S$31=0,"",'Round 8'!$F$38)) | S9: =IF($B9="","",IF('Round 8'!$S$31=0,"",'Round 8'!$Q$38)) | T9: =IF($B9="","",IF('Round 9'!$S$31=0,"",'Round 9'!$F$38)) | U9: =IF($B9="","",IF('Round 9'!$S$31=0,"",'Round 9'!$Q$38)) | V9: =IF($B9="","",IF('Round 10'!$S$31=0,"",'Round 10'!$F$38)) | W9: =IF($B9="","",IF('Round 10'!$S$31=0,"",'Round 10'!$Q$38)) | Y9: =IF(OR($B9="",$Y$1=0),0,CHOOSE($Y$1,'Round 1'!$P$38,'Round 2'!$P$38,'Round 3'!$P$38,'Round 4'!$P$38,'Round 5'!$P$38,'Round 6'!$P$38,'Round 7'!$P$38,'Round 8'!$P$38,'Round 9'!$P$38,'Round 10'!$P$38))
A10: =IF($B10="","",1+SUMPRODUCT(($B$3:$B$34<>"")*(($C$3:$C$34>C10)+(($C$3:$C$34=C10)*($Y$3:$Y$34>Y10))))) | B10: =IF(Setup!B12="","",Setup!B12) | C10: =IF($B10="","",SUM(D10,F10,H10,J10,L10,N10,P10,R10,T10,V10)) | D10: =IF($B10="","",IF('Round 1'!$S$31=0,"",'Round 1'!$F$39)) | E10: =IF($B10="","",IF('Round 1'!$S$31=0,"",'Round 1'!$Q$39)) | F10: =IF($B10="","",IF('Round 2'!$S$31=0,"",'Round 2'!$F$39)) | G10: =IF($B10="","",IF('Round 2'!$S$31=0,"",'Round 2'!$Q$39)) | H10: =IF($B10="","",IF('Round 3'!$S$31=0,"",'Round 3'!$F$39)) | I10: =IF($B10="","",IF('Round 3'!$S$31=0,"",'Round 3'!$Q$39)) | J10: =IF($B10="","",IF('Round 4'!$S$31=0,"",'Round 4'!$F$39)) | K10: =IF($B10="","",IF('Round 4'!$S$31=0,"",'Round 4'!$Q$39)) | L10: =IF($B10="","",IF('Round 5'!$S$31=0,"",'Round 5'!$F$39)) | M10: =IF($B10="","",IF('Round 5'!$S$31=0,"",'Round 5'!$Q$39)) | N10: =IF($B10="","",IF('Round 6'!$S$31=0,"",'Round 6'!$F$39)) | O10: =IF($B10="","",IF('Round 6'!$S$31=0,"",'Round 6'!$Q$39)) | P10: =IF($B10="","",IF('Round 7'!$S$31=0,"",'Round 7'!$F$39)) | Q10: =IF($B10="","",IF('Round 7'!$S$31=0,"",'Round 7'!$Q$39)) | R10: =IF($B10="","",IF('Round 8'!$S$31=0,"",'Round 8'!$F$39)) | S10: =IF($B10="","",IF('Round 8'!$S$31=0,"",'Round 8'!$Q$39)) | T10: =IF($B10="","",IF('Round 9'!$S$31=0,"",'Round 9'!$F$39)) | U10: =IF($B10="","",IF('Round 9'!$S$31=0,"",'Round 9'!$Q$39)) | V10: =IF($B10="","",IF('Round 10'!$S$31=0,"",'Round 10'!$F$39)) | W10: =IF($B10="","",IF('Round 10'!$S$31=0,"",'Round 10'!$Q$39)) | Y10: =IF(OR($B10="",$Y$1=0),0,CHOOSE($Y$1,'Round 1'!$P$39,'Round 2'!$P$39,'Round 3'!$P$39,'Round 4'!$P$39,'Round 5'!$P$39,'Round 6'!$P$39,'Round 7'!$P$39,'Round 8'!$P$39,'Round 9'!$P$39,'Round 10'!$P$39))
A11: =IF($B11="","",1+SUMPRODUCT(($B$3:$B$34<>"")*(($C$3:$C$34>C11)+(($C$3:$C$34=C11)*($Y$3:$Y$34>Y11))))) | B11: =IF(Setup!B13="","",Setup!B13) | C11: =IF($B11="","",SUM(D11,F11,H11,J11,L11,N11,P11,R11,T11,V11)) | D11: =IF($B11="","",IF('Round 1'!$S$31=0,"",'Round 1'!$F$40)) | E11: =IF($B11="","",IF('Round 1'!$S$31=0,"",'Round 1'!$Q$40)) | F11: =IF($B11="","",IF('Round 2'!$S$31=0,"",'Round 2'!$F$40)) | G11: =IF($B11="","",IF('Round 2'!$S$31=0,"",'Round 2'!$Q$40)) | H11: =IF($B11="","",IF('Round 3'!$S$31=0,"",'Round 3'!$F$40)) | I11: =IF($B11="","",IF('Round 3'!$S$31=0,"",'Round 3'!$Q$40)) | J11: =IF($B11="","",IF('Round 4'!$S$31=0,"",'Round 4'!$F$40)) | K11: =IF($B11="","",IF('Round 4'!$S$31=0,"",'Round 4'!$Q$40)) | L11: =IF($B11="","",IF('Round 5'!$S$31=0,"",'Round 5'!$F$40)) | M11: =IF($B11="","",IF('Round 5'!$S$31=0,"",'Round 5'!$Q$40)) | N11: =IF($B11="","",IF('Round 6'!$S$31=0,"",'Round 6'!$F$40)) | O11: =IF($B11="","",IF('Round 6'!$S$31=0,"",'Round 6'!$Q$40)) | P11: =IF($B11="","",IF('Round 7'!$S$31=0,"",'Round 7'!$F$40)) | Q11: =IF($B11="","",IF('Round 7'!$S$31=0,"",'Round 7'!$Q$40)) | R11: =IF($B11="","",IF('Round 8'!$S$31=0,"",'Round 8'!$F$40)) | S11: =IF($B11="","",IF('Round 8'!$S$31=0,"",'Round 8'!$Q$40)) | T11: =IF($B11="","",IF('Round 9'!$S$31=0,"",'Round 9'!$F$40)) | U11: =IF($B11="","",IF('Round 9'!$S$31=0,"",'Round 9'!$Q$40)) | V11: =IF($B11="","",IF('Round 10'!$S$31=0,"",'Round 10'!$F$40)) | W11: =IF($B11="","",IF('Round 10'!$S$31=0,"",'Round 10'!$Q$40)) | Y11: =IF(OR($B11="",$Y$1=0),0,CHOOSE($Y$1,'Round 1'!$P$40,'Round 2'!$P$40,'Round 3'!$P$40,'Round 4'!$P$40,'Round 5'!$P$40,'Round 6'!$P$40,'Round 7'!$P$40,'Round 8'!$P$40,'Round 9'!$P$40,'Round 10'!$P$40))
A12: =IF($B12="","",1+SUMPRODUCT(($B$3:$B$34<>"")*(($C$3:$C$34>C12)+(($C$3:$C$34=C12)*($Y$3:$Y$34>Y12))))) | B12: =IF(Setup!B14="","",Setup!B14) | C12: =IF($B12="","",SUM(D12,F12,H12,J12,L12,N12,P12,R12,T12,V12)) | D12: =IF($B12="","",IF('Round 1'!$S$31=0,"",'Round 1'!$F$41)) | E12: =IF($B12="","",IF('Round 1'!$S$31=0,"",'Round 1'!$Q$41)) | F12: =IF($B12="","",IF('Round 2'!$S$31=0,"",'Round 2'!$F$41)) | G12: =IF($B12="","",IF('Round 2'!$S$31=0,"",'Round 2'!$Q$41)) | H12: =IF($B12="","",IF('Round 3'!$S$31=0,"",'Round 3'!$F$41)) | I12: =IF($B12="","",IF('Round 3'!$S$31=0,"",'Round 3'!$Q$41)) | J12: =IF($B12="","",IF('Round 4'!$S$31=0,"",'Round 4'!$F$41)) | K12: =IF($B12="","",IF('Round 4'!$S$31=0,"",'Round 4'!$Q$41)) | L12: =IF($B12="","",IF('Round 5'!$S$31=0,"",'Round 5'!$F$41)) | M12: =IF($B12="","",IF('Round 5'!$S$31=0,"",'Round 5'!$Q$41)) | N12: =IF($B12="","",IF('Round 6'!$S$31=0,"",'Round 6'!$F$41)) | O12: =IF($B12="","",IF('Round 6'!$S$31=0,"",'Round 6'!$Q$41)) | P12: =IF($B12="","",IF('Round 7'!$S$31=0,"",'Round 7'!$F$41)) | Q12: =IF($B12="","",IF('Round 7'!$S$31=0,"",'Round 7'!$Q$41)) | R12: =IF($B12="","",IF('Round 8'!$S$31=0,"",'Round 8'!$F$41)) | S12: =IF($B12="","",IF('Round 8'!$S$31=0,"",'Round 8'!$Q$41)) | T12: =IF($B12="","",IF('Round 9'!$S$31=0,"",'Round 9'!$F$41)) | U12: =IF($B12="","",IF('Round 9'!$S$31=0,"",'Round 9'!$Q$41)) | V12: =IF($B12="","",IF('Round 10'!$S$31=0,"",'Round 10'!$F$41)) | W12: =IF($B12="","",IF('Round 10'!$S$31=0,"",'Round 10'!$Q$41)) | Y12: =IF(OR($B12="",$Y$1=0),0,CHOOSE($Y$1,'Round 1'!$P$41,'Round 2'!$P$41,'Round 3'!$P$41,'Round 4'!$P$41,'Round 5'!$P$41,'Round 6'!$P$41,'Round 7'!$P$41,'Round 8'!$P$41,'Round 9'!$P$41,'Round 10'!$P$41))
A13: =IF($B13="","",1+SUMPRODUCT(($B$3:$B$34<>"")*(($C$3:$C$34>C13)+(($C$3:$C$34=C13)*($Y$3:$Y$34>Y13))))) | B13: =IF(Setup!B15="","",Setup!B15) | C13: =IF($B13="","",SUM(D13,F13,H13,J13,L13,N13,P13,R13,T13,V13)) | D13: =IF($B13="","",IF('Round 1'!$S$31=0,"",'Round 1'!$F$42)) | E13: =IF($B13="","",IF('Round 1'!$S$31=0,"",'Round 1'!$Q$42)) | F13: =IF($B13="","",IF('Round 2'!$S$31=0,"",'Round 2'!$F$42)) | G13: =IF($B13="","",IF('Round 2'!$S$31=0,"",'Round 2'!$Q$42)) | H13: =IF($B13="","",IF('Round 3'!$S$31=0,"",'Round 3'!$F$42)) | I13: =IF($B13="","",IF('Round 3'!$S$31=0,"",'Round 3'!$Q$42)) | J13: =IF($B13="","",IF('Round 4'!$S$31=0,"",'Round 4'!$F$42)) | K13: =IF($B13="","",IF('Round 4'!$S$31=0,"",'Round 4'!$Q$42)) | L13: =IF($B13="","",IF('Round 5'!$S$31=0,"",'Round 5'!$F$42)) | M13: =IF($B13="","",IF('Round 5'!$S$31=0,"",'Round 5'!$Q$42)) | N13: =IF($B13="","",IF('Round 6'!$S$31=0,"",'Round 6'!$F$42)) | O13: =IF($B13="","",IF('Round 6'!$S$31=0,"",'Round 6'!$Q$42)) | P13: =IF($B13="","",IF('Round 7'!$S$31=0,"",'Round 7'!$F$42)) | Q13: =IF($B13="","",IF('Round 7'!$S$31=0,"",'Round 7'!$Q$42)) | R13: =IF($B13="","",IF('Round 8'!$S$31=0,"",'Round 8'!$F$42)) | S13: =IF($B13="","",IF('Round 8'!$S$31=0,"",'Round 8'!$Q$42)) | T13: =IF($B13="","",IF('Round 9'!$S$31=0,"",'Round 9'!$F$42)) | U13: =IF($B13="","",IF('Round 9'!$S$31=0,"",'Round 9'!$Q$42)) | V13: =IF($B13="","",IF('Round 10'!$S$31=0,"",'Round 10'!$F$42)) | W13: =IF($B13="","",IF('Round 10'!$S$31=0,"",'Round 10'!$Q$42)) | Y13: =IF(OR($B13="",$Y$1=0),0,CHOOSE($Y$1,'Round 1'!$P$42,'Round 2'!$P$42,'Round 3'!$P$42,'Round 4'!$P$42,'Round 5'!$P$42,'Round 6'!$P$42,'Round 7'!$P$42,'Round 8'!$P$42,'Round 9'!$P$42,'Round 10'!$P$42))
A14: =IF($B14="","",1+SUMPRODUCT(($B$3:$B$34<>"")*(($C$3:$C$34>C14)+(($C$3:$C$34=C14)*($Y$3:$Y$34>Y14))))) | B14: =IF(Setup!B16="","",Setup!B16) | C14: =IF($B14="","",SUM(D14,F14,H14,J14,L14,N14,P14,R14,T14,V14)) | D14: =IF($B14="","",IF('Round 1'!$S$31=0,"",'Round 1'!$F$43)) | E14: =IF($B14="","",IF('Round 1'!$S$31=0,"",'Round 1'!$Q$43)) | F14: =IF($B14="","",IF('Round 2'!$S$31=0,"",'Round 2'!$F$43)) | G14: =IF($B14="","",IF('Round 2'!$S$31=0,"",'Round 2'!$Q$43)) | H14: =IF($B14="","",IF('Round 3'!$S$31=0,"",'Round 3'!$F$43)) | I14: =IF($B14="","",IF('Round 3'!$S$31=0,"",'Round 3'!$Q$43)) | J14: =IF($B14="","",IF('Round 4'!$S$31=0,"",'Round 4'!$F$43)) | K14: =IF($B14="","",IF('Round 4'!$S$31=0,"",'Round 4'!$Q$43)) | L14: =IF($B14="","",IF('Round 5'!$S$31=0,"",'Round 5'!$F$43)) | M14: =IF($B14="","",IF('Round 5'!$S$31=0,"",'Round 5'!$Q$43)) | N14: =IF($B14="","",IF('Round 6'!$S$31=0,"",'Round 6'!$F$43)) | O14: =IF($B14="","",IF('Round 6'!$S$31=0,"",'Round 6'!$Q$43)) | P14: =IF($B14="","",IF('Round 7'!$S$31=0,"",'Round 7'!$F$43)) | Q14: =IF($B14="","",IF('Round 7'!$S$31=0,"",'Round 7'!$Q$43)) | R14: =IF($B14="","",IF('Round 8'!$S$31=0,"",'Round 8'!$F$43)) | S14: =IF($B14="","",IF('Round 8'!$S$31=0,"",'Round 8'!$Q$43)) | T14: =IF($B14="","",IF('Round 9'!$S$31=0,"",'Round 9'!$F$43)) | U14: =IF($B14="","",IF('Round 9'!$S$31=0,"",'Round 9'!$Q$43)) | V14: =IF($B14="","",IF('Round 10'!$S$31=0,"",'Round 10'!$F$43)) | W14: =IF($B14="","",IF('Round 10'!$S$31=0,"",'Round 10'!$Q$43)) | Y14: =IF(OR($B14="",$Y$1=0),0,CHOOSE($Y$1,'Round 1'!$P$43,'Round 2'!$P$43,'Round 3'!$P$43,'Round 4'!$P$43,'Round 5'!$P$43,'Round 6'!$P$43,'Round 7'!$P$43,'Round 8'!$P$43,'Round 9'!$P$43,'Round 10'!$P$43))
A15: =IF($B15="","",1+SUMPRODUCT(($B$3:$B$34<>"")*(($C$3:$C$34>C15)+(($C$3:$C$34=C15)*($Y$3:$Y$34>Y15))))) | B15: =IF(Setup!B17="","",Setup!B17) | C15: =IF($B15="","",SUM(D15,F15,H15,J15,L15,N15,P15,R15,T15,V15)) | D15: =IF($B15="","",IF('Round 1'!$S$31=0,"",'Round 1'!$F$44)) | E15: =IF($B15="","",IF('Round 1'!$S$31=0,"",'Round 1'!$Q$44)) | F15: =IF($B15="","",IF('Round 2'!$S$31=0,"",'Round 2'!$F$44)) | G15: =IF($B15="","",IF('Round 2'!$S$31=0,"",'Round 2'!$Q$44)) | H15: =IF($B15="","",IF('Round 3'!$S$31=0,"",'Round 3'!$F$44)) | I15: =IF($B15="","",IF('Round 3'!$S$31=0,"",'Round 3'!$Q$44)) | J15: =IF($B15="","",IF('Round 4'!$S$31=0,"",'Round 4'!$F$44)) | K15: =IF($B15="","",IF('Round 4'!$S$31=0,"",'Round 4'!$Q$44)) | L15: =IF($B15="","",IF('Round 5'!$S$31=0,"",'Round 5'!$F$44)) | M15: =IF($B15="","",IF('Round 5'!$S$31=0,"",'Round 5'!$Q$44)) | N15: =IF($B15="","",IF('Round 6'!$S$31=0,"",'Round 6'!$F$44)) | O15: =IF($B15="","",IF('Round 6'!$S$31=0,"",'Round 6'!$Q$44)) | P15: =IF($B15="","",IF('Round 7'!$S$31=0,"",'Round 7'!$F$44)) | Q15: =IF($B15="","",IF('Round 7'!$S$31=0,"",'Round 7'!$Q$44)) | R15: =IF($B15="","",IF('Round 8'!$S$31=0,"",'Round 8'!$F$44)) | S15: =IF($B15="","",IF('Round 8'!$S$31=0,"",'Round 8'!$Q$44)) | T15: =IF($B15="","",IF('Round 9'!$S$31=0,"",'Round 9'!$F$44)) | U15: =IF($B15="","",IF('Round 9'!$S$31=0,"",'Round 9'!$Q$44)) | V15: =IF($B15="","",IF('Round 10'!$S$31=0,"",'Round 10'!$F$44)) | W15: =IF($B15="","",IF('Round 10'!$S$31=0,"",'Round 10'!$Q$44)) | Y15: =IF(OR($B15="",$Y$1=0),0,CHOOSE($Y$1,'Round 1'!$P$44,'Round 2'!$P$44,'Round 3'!$P$44,'Round 4'!$P$44,'Round 5'!$P$44,'Round 6'!$P$44,'Round 7'!$P$44,'Round 8'!$P$44,'Round 9'!$P$44,'Round 10'!$P$44))
A16: =IF($B16="","",1+SUMPRODUCT(($B$3:$B$34<>"")*(($C$3:$C$34>C16)+(($C$3:$C$34=C16)*($Y$3:$Y$34>Y16))))) | B16: =IF(Setup!B18="","",Setup!B18) | C16: =IF($B16="","",SUM(D16,F16,H16,J16,L16,N16,P16,R16,T16,V16)) | D16: =IF($B16="","",IF('Round 1'!$S$31=0,"",'Round 1'!$F$45)) | E16: =IF($B16="","",IF('Round 1'!$S$31=0,"",'Round 1'!$Q$45)) | F16: =IF($B16="","",IF('Round 2'!$S$31=0,"",'Round 2'!$F$45)) | G16: =IF($B16="","",IF('Round 2'!$S$31=0,"",'Round 2'!$Q$45)) | H16: =IF($B16="","",IF('Round 3'!$S$31=0,"",'Round 3'!$F$45)) | I16: =IF($B16="","",IF('Round 3'!$S$31=0,"",'Round 3'!$Q$45)) | J16: =IF($B16="","",IF('Round 4'!$S$31=0,"",'Round 4'!$F$45)) | K16: =IF($B16="","",IF('Round 4'!$S$31=0,"",'Round 4'!$Q$45)) | L16: =IF($B16="","",IF('Round 5'!$S$31=0,"",'Round 5'!$F$45)) | M16: =IF($B16="","",IF('Round 5'!$S$31=0,"",'Round 5'!$Q$45)) | N16: =IF($B16="","",IF('Round 6'!$S$31=0,"",'Round 6'!$F$45)) | O16: =IF($B16="","",IF('Round 6'!$S$31=0,"",'Round 6'!$Q$45)) | P16: =IF($B16="","",IF('Round 7'!$S$31=0,"",'Round 7'!$F$45)) | Q16: =IF($B16="","",IF('Round 7'!$S$31=0,"",'Round 7'!$Q$45)) | R16: =IF($B16="","",IF('Round 8'!$S$31=0,"",'Round 8'!$F$45)) | S16: =IF($B16="","",IF('Round 8'!$S$31=0,"",'Round 8'!$Q$45)) | T16: =IF($B16="","",IF('Round 9'!$S$31=0,"",'Round 9'!$F$45)) | U16: =IF($B16="","",IF('Round 9'!$S$31=0,"",'Round 9'!$Q$45)) | V16: =IF($B16="","",IF('Round 10'!$S$31=0,"",'Round 10'!$F$45)) | W16: =IF($B16="","",IF('Round 10'!$S$31=0,"",'Round 10'!$Q$45)) | Y16: =IF(OR($B16="",$Y$1=0),0,CHOOSE($Y$1,'Round 1'!$P$45,'Round 2'!$P$45,'Round 3'!$P$45,'Round 4'!$P$45,'Round 5'!$P$45,'Round 6'!$P$45,'Round 7'!$P$45,'Round 8'!$P$45,'Round 9'!$P$45,'Round 10'!$P$45))
A17: =IF($B17="","",1+SUMPRODUCT(($B$3:$B$34<>"")*(($C$3:$C$34>C17)+(($C$3:$C$34=C17)*($Y$3:$Y$34>Y17))))) | B17: =IF(Setup!B19="","",Setup!B19) | C17: =IF($B17="","",SUM(D17,F17,H17,J17,L17,N17,P17,R17,T17,V17)) | D17: =IF($B17="","",IF('Round 1'!$S$31=0,"",'Round 1'!$F$46)) | E17: =IF($B17="","",IF('Round 1'!$S$31=0,"",'Round 1'!$Q$46)) | F17: =IF($B17="","",IF('Round 2'!$S$31=0,"",'Round 2'!$F$46)) | G17: =IF($B17="","",IF('Round 2'!$S$31=0,"",'Round 2'!$Q$46)) | H17: =IF($B17="","",IF('Round 3'!$S$31=0,"",'Round 3'!$F$46)) | I17: =IF($B17="","",IF('Round 3'!$S$31=0,"",'Round 3'!$Q$46)) | J17: =IF($B17="","",IF('Round 4'!$S$31=0,"",'Round 4'!$F$46)) | K17: =IF($B17="","",IF('Round 4'!$S$31=0,"",'Round 4'!$Q$46)) | L17: =IF($B17="","",IF('Round 5'!$S$31=0,"",'Round 5'!$F$46)) | M17: =IF($B17="","",IF('Round 5'!$S$31=0,"",'Round 5'!$Q$46)) | N17: =IF($B17="","",IF('Round 6'!$S$31=0,"",'Round 6'!$F$46)) | O17: =IF($B17="","",IF('Round 6'!$S$31=0,"",'Round 6'!$Q$46)) | P17: =IF($B17="","",IF('Round 7'!$S$31=0,"",'Round 7'!$F$46)) | Q17: =IF($B17="","",IF('Round 7'!$S$31=0,"",'Round 7'!$Q$46)) | R17: =IF($B17="","",IF('Round 8'!$S$31=0,"",'Round 8'!$F$46)) | S17: =IF($B17="","",IF('Round 8'!$S$31=0,"",'Round 8'!$Q$46)) | T17: =IF($B17="","",IF('Round 9'!$S$31=0,"",'Round 9'!$F$46)) | U17: =IF($B17="","",IF('Round 9'!$S$31=0,"",'Round 9'!$Q$46)) | V17: =IF($B17="","",IF('Round 10'!$S$31=0,"",'Round 10'!$F$46)) | W17: =IF($B17="","",IF('Round 10'!$S$31=0,"",'Round 10'!$Q$46)) | Y17: =IF(OR($B17="",$Y$1=0),0,CHOOSE($Y$1,'Round 1'!$P$46,'Round 2'!$P$46,'Round 3'!$P$46,'Round 4'!$P$46,'Round 5'!$P$46,'Round 6'!$P$46,'Round 7'!$P$46,'Round 8'!$P$46,'Round 9'!$P$46,'Round 10'!$P$46))
A18: =IF($B18="","",1+SUMPRODUCT(($B$3:$B$34<>"")*(($C$3:$C$34>C18)+(($C$3:$C$34=C18)*($Y$3:$Y$34>Y18))))) | B18: =IF(Setup!B20="","",Setup!B20) | C18: =IF($B18="","",SUM(D18,F18,H18,J18,L18,N18,P18,R18,T18,V18)) | D18: =IF($B18="","",IF('Round 1'!$S$31=0,"",'Round 1'!$F$47)) | E18: =IF($B18="","",IF('Round 1'!$S$31=0,"",'Round 1'!$Q$47)) | F18: =IF($B18="","",IF('Round 2'!$S$31=0,"",'Round 2'!$F$47)) | G18: =IF($B18="","",IF('Round 2'!$S$31=0,"",'Round 2'!$Q$47)) | H18: =IF($B18="","",IF('Round 3'!$S$31=0,"",'Round 3'!$F$47)) | I18: =IF($B18="","",IF('Round 3'!$S$31=0,"",'Round 3'!$Q$47)) | J18: =IF($B18="","",IF('Round 4'!$S$31=0,"",'Round 4'!$F$47)) | K18: =IF($B18="","",IF('Round 4'!$S$31=0,"",'Round 4'!$Q$47)) | L18: =IF($B18="","",IF('Round 5'!$S$31=0,"",'Round 5'!$F$47)) | M18: =IF($B18="","",IF('Round 5'!$S$31=0,"",'Round 5'!$Q$47)) | N18: =IF($B18="","",IF('Round 6'!$S$31=0,"",'Round 6'!$F$47)) | O18: =IF($B18="","",IF('Round 6'!$S$31=0,"",'Round 6'!$Q$47)) | P18: =IF($B18="","",IF('Round 7'!$S$31=0,"",'Round 7'!$F$47)) | Q18: =IF($B18="","",IF('Round 7'!$S$31=0,"",'Round 7'!$Q$47)) | R18: =IF($B18="","",IF('Round 8'!$S$31=0,"",'Round 8'!$F$47)) | S18: =IF($B18="","",IF('Round 8'!$S$31=0,"",'Round 8'!$Q$47)) | T18: =IF($B18="","",IF('Round 9'!$S$31=0,"",'Round 9'!$F$47)) | U18: =IF($B18="","",IF('Round 9'!$S$31=0,"",'Round 9'!$Q$47)) | V18: =IF($B18="","",IF('Round 10'!$S$31=0,"",'Round 10'!$F$47)) | W18: =IF($B18="","",IF('Round 10'!$S$31=0,"",'Round 10'!$Q$47)) | Y18: =IF(OR($B18="",$Y$1=0),0,CHOOSE($Y$1,'Round 1'!$P$47,'Round 2'!$P$47,'Round 3'!$P$47,'Round 4'!$P$47,'Round 5'!$P$47,'Round 6'!$P$47,'Round 7'!$P$47,'Round 8'!$P$47,'Round 9'!$P$47,'Round 10'!$P$47))
A19: =IF($B19="","",1+SUMPRODUCT(($B$3:$B$34<>"")*(($C$3:$C$34>C19)+(($C$3:$C$34=C19)*($Y$3:$Y$34>Y19))))) | B19: =IF(Setup!B21="","",Setup!B21) | C19: =IF($B19="","",SUM(D19,F19,H19,J19,L19,N19,P19,R19,T19,V19)) | D19: =IF($B19="","",IF('Round 1'!$S$31=0,"",'Round 1'!$F$48)) | E19: =IF($B19="","",IF('Round 1'!$S$31=0,"",'Round 1'!$Q$48)) | F19: =IF($B19="","",IF('Round 2'!$S$31=0,"",'Round 2'!$F$48)) | G19: =IF($B19="","",IF('Round 2'!$S$31=0,"",'Round 2'!$Q$48)) | H19: =IF($B19="","",IF('Round 3'!$S$31=0,"",'Round 3'!$F$48)) | I19: =IF($B19="","",IF('Round 3'!$S$31=0,"",'Round 3'!$Q$48)) | J19: =IF($B19="","",IF('Round 4'!$S$31=0,"",'Round 4'!$F$48)) | K19: =IF($B19="","",IF('Round 4'!$S$31=0,"",'Round 4'!$Q$48)) | L19: =IF($B19="","",IF('Round 5'!$S$31=0,"",'Round 5'!$F$48)) | M19: =IF($B19="","",IF('Round 5'!$S$31=0,"",'Round 5'!$Q$48)) | N19: =IF($B19="","",IF('Round 6'!$S$31=0,"",'Round 6'!$F$48)) | O19: =IF($B19="","",IF('Round 6'!$S$31=0,"",'Round 6'!$Q$48)) | P19: =IF($B19="","",IF('Round 7'!$S$31=0,"",'Round 7'!$F$48)) | Q19: =IF($B19="","",IF('Round 7'!$S$31=0,"",'Round 7'!$Q$48)) | R19: =IF($B19="","",IF('Round 8'!$S$31=0,"",'Round 8'!$F$48)) | S19: =IF($B19="","",IF('Round 8'!$S$31=0,"",'Round 8'!$Q$48)) | T19: =IF($B19="","",IF('Round 9'!$S$31=0,"",'Round 9'!$F$48)) | U19: =IF($B19="","",IF('Round 9'!$S$31=0,"",'Round 9'!$Q$48)) | V19: =IF($B19="","",IF('Round 10'!$S$31=0,"",'Round 10'!$F$48)) | W19: =IF($B19="","",IF('Round 10'!$S$31=0,"",'Round 10'!$Q$48)) | Y19: =IF(OR($B19="",$Y$1=0),0,CHOOSE($Y$1,'Round 1'!$P$48,'Round 2'!$P$48,'Round 3'!$P$48,'Round 4'!$P$48,'Round 5'!$P$48,'Round 6'!$P$48,'Round 7'!$P$48,'Round 8'!$P$48,'Round 9'!$P$48,'Round 10'!$P$48))
A20: =IF($B20="","",1+SUMPRODUCT(($B$3:$B$34<>"")*(($C$3:$C$34>C20)+(($C$3:$C$34=C20)*($Y$3:$Y$34>Y20))))) | B20: =IF(Setup!B22="","",Setup!B22) | C20: =IF($B20="","",SUM(D20,F20,H20,J20,L20,N20,P20,R20,T20,V20)) | D20: =IF($B20="","",IF('Round 1'!$S$31=0,"",'Round 1'!$F$49)) | E20: =IF($B20="","",IF('Round 1'!$S$31=0,"",'Round 1'!$Q$49)) | F20: =IF($B20="","",IF('Round 2'!$S$31=0,"",'Round 2'!$F$49)) | G20: =IF($B20="","",IF('Round 2'!$S$31=0,"",'Round 2'!$Q$49)) | H20: =IF($B20="","",IF('Round 3'!$S$31=0,"",'Round 3'!$F$49)) | I20: =IF($B20="","",IF('Round 3'!$S$31=0,"",'Round 3'!$Q$49)) | J20: =IF($B20="","",IF('Round 4'!$S$31=0,"",'Round 4'!$F$49)) | K20: =IF($B20="","",IF('Round 4'!$S$31=0,"",'Round 4'!$Q$49)) | L20: =IF($B20="","",IF('Round 5'!$S$31=0,"",'Round 5'!$F$49)) | M20: =IF($B20="","",IF('Round 5'!$S$31=0,"",'Round 5'!$Q$49)) | N20: =IF($B20="","",IF('Round 6'!$S$31=0,"",'Round 6'!$F$49)) | O20: =IF($B20="","",IF('Round 6'!$S$31=0,"",'Round 6'!$Q$49)) | P20: =IF($B20="","",IF('Round 7'!$S$31=0,"",'Round 7'!$F$49)) | Q20: =IF($B20="","",IF('Round 7'!$S$31=0,"",'Round 7'!$Q$49)) | R20: =IF($B20="","",IF('Round 8'!$S$31=0,"",'Round 8'!$F$49)) | S20: =IF($B20="","",IF('Round 8'!$S$31=0,"",'Round 8'!$Q$49)) | T20: =IF($B20="","",IF('Round 9'!$S$31=0,"",'Round 9'!$F$49)) | U20: =IF($B20="","",IF('Round 9'!$S$31=0,"",'Round 9'!$Q$49)) | V20: =IF($B20="","",IF('Round 10'!$S$31=0,"",'Round 10'!$F$49)) | W20: =IF($B20="","",IF('Round 10'!$S$31=0,"",'Round 10'!$Q$49)) | Y20: =IF(OR($B20="",$Y$1=0),0,CHOOSE($Y$1,'Round 1'!$P$49,'Round 2'!$P$49,'Round 3'!$P$49,'Round 4'!$P$49,'Round 5'!$P$49,'Round 6'!$P$49,'Round 7'!$P$49,'Round 8'!$P$49,'Round 9'!$P$49,'Round 10'!$P$49))
A21: =IF($B21="","",1+SUMPRODUCT(($B$3:$B$34<>"")*(($C$3:$C$34>C21)+(($C$3:$C$34=C21)*($Y$3:$Y$34>Y21))))) | B21: =IF(Setup!B23="","",Setup!B23) | C21: =IF($B21="","",SUM(D21,F21,H21,J21,L21,N21,P21,R21,T21,V21)) | D21: =IF($B21="","",IF('Round 1'!$S$31=0,"",'Round 1'!$F$50)) | E21: =IF($B21="","",IF('Round 1'!$S$31=0,"",'Round 1'!$Q$50)) | F21: =IF($B21="","",IF('Round 2'!$S$31=0,"",'Round 2'!$F$50)) | G21: =IF($B21="","",IF('Round 2'!$S$31=0,"",'Round 2'!$Q$50)) | H21: =IF($B21="","",IF('Round 3'!$S$31=0,"",'Round 3'!$F$50)) | I21: =IF($B21="","",IF('Round 3'!$S$31=0,"",'Round 3'!$Q$50)) | J21: =IF($B21="","",IF('Round 4'!$S$31=0,"",'Round 4'!$F$50)) | K21: =IF($B21="","",IF('Round 4'!$S$31=0,"",'Round 4'!$Q$50)) | L21: =IF($B21="","",IF('Round 5'!$S$31=0,"",'Round 5'!$F$50)) | M21: =IF($B21="","",IF('Round 5'!$S$31=0,"",'Round 5'!$Q$50)) | N21: =IF($B21="","",IF('Round 6'!$S$31=0,"",'Round 6'!$F$50)) | O21: =IF($B21="","",IF('Round 6'!$S$31=0,"",'Round 6'!$Q$50)) | P21: =IF($B21="","",IF('Round 7'!$S$31=0,"",'Round 7'!$F$50)) | Q21: =IF($B21="","",IF('Round 7'!$S$31=0,"",'Round 7'!$Q$50)) | R21: =IF($B21="","",IF('Round 8'!$S$31=0,"",'Round 8'!$F$50)) | S21: =IF($B21="","",IF('Round 8'!$S$31=0,"",'Round 8'!$Q$50)) | T21: =IF($B21="","",IF('Round 9'!$S$31=0,"",'Round 9'!$F$50)) | U21: =IF($B21="","",IF('Round 9'!$S$31=0,"",'Round 9'!$Q$50)) | V21: =IF($B21="","",IF('Round 10'!$S$31=0,"",'Round 10'!$F$50)) | W21: =IF($B21="","",IF('Round 10'!$S$31=0,"",'Round 10'!$Q$50)) | Y21: =IF(OR($B21="",$Y$1=0),0,CHOOSE($Y$1,'Round 1'!$P$50,'Round 2'!$P$50,'Round 3'!$P$50,'Round 4'!$P$50,'Round 5'!$P$50,'Round 6'!$P$50,'Round 7'!$P$50,'Round 8'!$P$50,'Round 9'!$P$50,'Round 10'!$P$50))
A22: =IF($B22="","",1+SUMPRODUCT(($B$3:$B$34<>"")*(($C$3:$C$34>C22)+(($C$3:$C$34=C22)*($Y$3:$Y$34>Y22))))) | B22: =IF(Setup!B24="","",Setup!B24) | C22: =IF($B22="","",SUM(D22,F22,H22,J22,L22,N22,P22,R22,T22,V22)) | D22: =IF($B22="","",IF('Round 1'!$S$31=0,"",'Round 1'!$F$51)) | E22: =IF($B22="","",IF('Round 1'!$S$31=0,"",'Round 1'!$Q$51)) | F22: =IF($B22="","",IF('Round 2'!$S$31=0,"",'Round 2'!$F$51)) | G22: =IF($B22="","",IF('Round 2'!$S$31=0,"",'Round 2'!$Q$51)) | H22: =IF($B22="","",IF('Round 3'!$S$31=0,"",'Round 3'!$F$51)) | I22: =IF($B22="","",IF('Round 3'!$S$31=0,"",'Round 3'!$Q$51)) | J22: =IF($B22="","",IF('Round 4'!$S$31=0,"",'Round 4'!$F$51)) | K22: =IF($B22="","",IF('Round 4'!$S$31=0,"",'Round 4'!$Q$51)) | L22: =IF($B22="","",IF('Round 5'!$S$31=0,"",'Round 5'!$F$51)) | M22: =IF($B22="","",IF('Round 5'!$S$31=0,"",'Round 5'!$Q$51)) | N22: =IF($B22="","",IF('Round 6'!$S$31=0,"",'Round 6'!$F$51)) | O22: =IF($B22="","",IF('Round 6'!$S$31=0,"",'Round 6'!$Q$51)) | P22: =IF($B22="","",IF('Round 7'!$S$31=0,"",'Round 7'!$F$51)) | Q22: =IF($B22="","",IF('Round 7'!$S$31=0,"",'Round 7'!$Q$51)) | R22: =IF($B22="","",IF('Round 8'!$S$31=0,"",'Round 8'!$F$51)) | S22: =IF($B22="","",IF('Round 8'!$S$31=0,"",'Round 8'!$Q$51)) | T22: =IF($B22="","",IF('Round 9'!$S$31=0,"",'Round 9'!$F$51)) | U22: =IF($B22="","",IF('Round 9'!$S$31=0,"",'Round 9'!$Q$51)) | V22: =IF($B22="","",IF('Round 10'!$S$31=0,"",'Round 10'!$F$51)) | W22: =IF($B22="","",IF('Round 10'!$S$31=0,"",'Round 10'!$Q$51)) | Y22: =IF(OR($B22="",$Y$1=0),0,CHOOSE($Y$1,'Round 1'!$P$51,'Round 2'!$P$51,'Round 3'!$P$51,'Round 4'!$P$51,'Round 5'!$P$51,'Round 6'!$P$51,'Round 7'!$P$51,'Round 8'!$P$51,'Round 9'!$P$51,'Round 10'!$P$51))
A23: =IF($B23="","",1+SUMPRODUCT(($B$3:$B$34<>"")*(($C$3:$C$34>C23)+(($C$3:$C$34=C23)*($Y$3:$Y$34>Y23))))) | B23: =IF(Setup!B25="","",Setup!B25) | C23: =IF($B23="","",SUM(D23,F23,H23,J23,L23,N23,P23,R23,T23,V23)) | D23: =IF($B23="","",IF('Round 1'!$S$31=0,"",'Round 1'!$F$52)) | E23: =IF($B23="","",IF('Round 1'!$S$31=0,"",'Round 1'!$Q$52)) | F23: =IF($B23="","",IF('Round 2'!$S$31=0,"",'Round 2'!$F$52)) | G23: =IF($B23="","",IF('Round 2'!$S$31=0,"",'Round 2'!$Q$52)) | H23: =IF($B23="","",IF('Round 3'!$S$31=0,"",'Round 3'!$F$52)) | I23: =IF($B23="","",IF('Round 3'!$S$31=0,"",'Round 3'!$Q$52)) | J23: =IF($B23="","",IF('Round 4'!$S$31=0,"",'Round 4'!$F$52)) | K23: =IF($B23="","",IF('Round 4'!$S$31=0,"",'Round 4'!$Q$52)) | L23: =IF($B23="","",IF('Round 5'!$S$31=0,"",'Round 5'!$F$52)) | M23: =IF($B23="","",IF('Round 5'!$S$31=0,"",'Round 5'!$Q$52)) | N23: =IF($B23="","",IF('Round 6'!$S$31=0,"",'Round 6'!$F$52)) | O23: =IF($B23="","",IF('Round 6'!$S$31=0,"",'Round 6'!$Q$52)) | P23: =IF($B23="","",IF('Round 7'!$S$31=0,"",'Round 7'!$F$52)) | Q23: =IF($B23="","",IF('Round 7'!$S$31=0,"",'Round 7'!$Q$52)) | R23: =IF($B23="","",IF('Round 8'!$S$31=0,"",'Round 8'!$F$52)) | S23: =IF($B23="","",IF('Round 8'!$S$31=0,"",'Round 8'!$Q$52)) | T23: =IF($B23="","",IF('Round 9'!$S$31=0,"",'Round 9'!$F$52)) | U23: =IF($B23="","",IF('Round 9'!$S$31=0,"",'Round 9'!$Q$52)) | V23: =IF($B23="","",IF('Round 10'!$S$31=0,"",'Round 10'!$F$52)) | W23: =IF($B23="","",IF('Round 10'!$S$31=0,"",'Round 10'!$Q$52)) | Y23: =IF(OR($B23="",$Y$1=0),0,CHOOSE($Y$1,'Round 1'!$P$52,'Round 2'!$P$52,'Round 3'!$P$52,'Round 4'!$P$52,'Round 5'!$P$52,'Round 6'!$P$52,'Round 7'!$P$52,'Round 8'!$P$52,'Round 9'!$P$52,'Round 10'!$P$52))
A24: =IF($B24="","",1+SUMPRODUCT(($B$3:$B$34<>"")*(($C$3:$C$34>C24)+(($C$3:$C$34=C24)*($Y$3:$Y$34>Y24))))) | B24: =IF(Setup!B26="","",Setup!B26) | C24: =IF($B24="","",SUM(D24,F24,H24,J24,L24,N24,P24,R24,T24,V24)) | D24: =IF($B24="","",IF('Round 1'!$S$31=0,"",'Round 1'!$F$53)) | E24: =IF($B24="","",IF('Round 1'!$S$31=0,"",'Round 1'!$Q$53)) | F24: =IF($B24="","",IF('Round 2'!$S$31=0,"",'Round 2'!$F$53)) | G24: =IF($B24="","",IF('Round 2'!$S$31=0,"",'Round 2'!$Q$53)) | H24: =IF($B24="","",IF('Round 3'!$S$31=0,"",'Round 3'!$F$53)) | I24: =IF($B24="","",IF('Round 3'!$S$31=0,"",'Round 3'!$Q$53)) | J24: =IF($B24="","",IF('Round 4'!$S$31=0,"",'Round 4'!$F$53)) | K24: =IF($B24="","",IF('Round 4'!$S$31=0,"",'Round 4'!$Q$53)) | L24: =IF($B24="","",IF('Round 5'!$S$31=0,"",'Round 5'!$F$53)) | M24: =IF($B24="","",IF('Round 5'!$S$31=0,"",'Round 5'!$Q$53)) | N24: =IF($B24="","",IF('Round 6'!$S$31=0,"",'Round 6'!$F$53)) | O24: =IF($B24="","",IF('Round 6'!$S$31=0,"",'Round 6'!$Q$53)) | P24: =IF($B24="","",IF('Round 7'!$S$31=0,"",'Round 7'!$F$53)) | Q24: =IF($B24="","",IF('Round 7'!$S$31=0,"",'Round 7'!$Q$53)) | R24: =IF($B24="","",IF('Round 8'!$S$31=0,"",'Round 8'!$F$53)) | S24: =IF($B24="","",IF('Round 8'!$S$31=0,"",'Round 8'!$Q$53)) | T24: =IF($B24="","",IF('Round 9'!$S$31=0,"",'Round 9'!$F$53)) | U24: =IF($B24="","",IF('Round 9'!$S$31=0,"",'Round 9'!$Q$53)) | V24: =IF($B24="","",IF('Round 10'!$S$31=0,"",'Round 10'!$F$53)) | W24: =IF($B24="","",IF('Round 10'!$S$31=0,"",'Round 10'!$Q$53)) | Y24: =IF(OR($B24="",$Y$1=0),0,CHOOSE($Y$1,'Round 1'!$P$53,'Round 2'!$P$53,'Round 3'!$P$53,'Round 4'!$P$53,'Round 5'!$P$53,'Round 6'!$P$53,'Round 7'!$P$53,'Round 8'!$P$53,'Round 9'!$P$53,'Round 10'!$P$53))
A25: =IF($B25="","",1+SUMPRODUCT(($B$3:$B$34<>"")*(($C$3:$C$34>C25)+(($C$3:$C$34=C25)*($Y$3:$Y$34>Y25))))) | B25: =IF(Setup!B27="","",Setup!B27) | C25: =IF($B25="","",SUM(D25,F25,H25,J25,L25,N25,P25,R25,T25,V25)) | D25: =IF($B25="","",IF('Round 1'!$S$31=0,"",'Round 1'!$F$54)) | E25: =IF($B25="","",IF('Round 1'!$S$31=0,"",'Round 1'!$Q$54)) | F25: =IF($B25="","",IF('Round 2'!$S$31=0,"",'Round 2'!$F$54)) | G25: =IF($B25="","",IF('Round 2'!$S$31=0,"",'Round 2'!$Q$54)) | H25: =IF($B25="","",IF('Round 3'!$S$31=0,"",'Round 3'!$F$54)) | I25: =IF($B25="","",IF('Round 3'!$S$31=0,"",'Round 3'!$Q$54)) | J25: =IF($B25="","",IF('Round 4'!$S$31=0,"",'Round 4'!$F$54)) | K25: =IF($B25="","",IF('Round 4'!$S$31=0,"",'Round 4'!$Q$54)) | L25: =IF($B25="","",IF('Round 5'!$S$31=0,"",'Round 5'!$F$54)) | M25: =IF($B25="","",IF('Round 5'!$S$31=0,"",'Round 5'!$Q$54)) | N25: =IF($B25="","",IF('Round 6'!$S$31=0,"",'Round 6'!$F$54)) | O25: =IF($B25="","",IF('Round 6'!$S$31=0,"",'Round 6'!$Q$54)) | P25: =IF($B25="","",IF('Round 7'!$S$31=0,"",'Round 7'!$F$54)) | Q25: =IF($B25="","",IF('Round 7'!$S$31=0,"",'Round 7'!$Q$54)) | R25: =IF($B25="","",IF('Round 8'!$S$31=0,"",'Round 8'!$F$54)) | S25: =IF($B25="","",IF('Round 8'!$S$31=0,"",'Round 8'!$Q$54)) | T25: =IF($B25="","",IF('Round 9'!$S$31=0,"",'Round 9'!$F$54)) | U25: =IF($B25="","",IF('Round 9'!$S$31=0,"",'Round 9'!$Q$54)) | V25: =IF($B25="","",IF('Round 10'!$S$31=0,"",'Round 10'!$F$54)) | W25: =IF($B25="","",IF('Round 10'!$S$31=0,"",'Round 10'!$Q$54)) | Y25: =IF(OR($B25="",$Y$1=0),0,CHOOSE($Y$1,'Round 1'!$P$54,'Round 2'!$P$54,'Round 3'!$P$54,'Round 4'!$P$54,'Round 5'!$P$54,'Round 6'!$P$54,'Round 7'!$P$54,'Round 8'!$P$54,'Round 9'!$P$54,'Round 10'!$P$54))
A26: =IF($B26="","",1+SUMPRODUCT(($B$3:$B$34<>"")*(($C$3:$C$34>C26)+(($C$3:$C$34=C26)*($Y$3:$Y$34>Y26))))) | B26: =IF(Setup!B28="","",Setup!B28) | C26: =IF($B26="","",SUM(D26,F26,H26,J26,L26,N26,P26,R26,T26,V26)) | D26: =IF($B26="","",IF('Round 1'!$S$31=0,"",'Round 1'!$F$55)) | E26: =IF($B26="","",IF('Round 1'!$S$31=0,"",'Round 1'!$Q$55)) | F26: =IF($B26="","",IF('Round 2'!$S$31=0,"",'Round 2'!$F$55)) | G26: =IF($B26="","",IF('Round 2'!$S$31=0,"",'Round 2'!$Q$55)) | H26: =IF($B26="","",IF('Round 3'!$S$31=0,"",'Round 3'!$F$55)) | I26: =IF($B26="","",IF('Round 3'!$S$31=0,"",'Round 3'!$Q$55)) | J26: =IF($B26="","",IF('Round 4'!$S$31=0,"",'Round 4'!$F$55)) | K26: =IF($B26="","",IF('Round 4'!$S$31=0,"",'Round 4'!$Q$55)) | L26: =IF($B26="","",IF('Round 5'!$S$31=0,"",'Round 5'!$F$55)) | M26: =IF($B26="","",IF('Round 5'!$S$31=0,"",'Round 5'!$Q$55)) | N26: =IF($B26="","",IF('Round 6'!$S$31=0,"",'Round 6'!$F$55)) | O26: =IF($B26="","",IF('Round 6'!$S$31=0,"",'Round 6'!$Q$55)) | P26: =IF($B26="","",IF('Round 7'!$S$31=0,"",'Round 7'!$F$55)) | Q26: =IF($B26="","",IF('Round 7'!$S$31=0,"",'Round 7'!$Q$55)) | R26: =IF($B26="","",IF('Round 8'!$S$31=0,"",'Round 8'!$F$55)) | S26: =IF($B26="","",IF('Round 8'!$S$31=0,"",'Round 8'!$Q$55)) | T26: =IF($B26="","",IF('Round 9'!$S$31=0,"",'Round 9'!$F$55)) | U26: =IF($B26="","",IF('Round 9'!$S$31=0,"",'Round 9'!$Q$55)) | V26: =IF($B26="","",IF('Round 10'!$S$31=0,"",'Round 10'!$F$55)) | W26: =IF($B26="","",IF('Round 10'!$S$31=0,"",'Round 10'!$Q$55)) | Y26: =IF(OR($B26="",$Y$1=0),0,CHOOSE($Y$1,'Round 1'!$P$55,'Round 2'!$P$55,'Round 3'!$P$55,'Round 4'!$P$55,'Round 5'!$P$55,'Round 6'!$P$55,'Round 7'!$P$55,'Round 8'!$P$55,'Round 9'!$P$55,'Round 10'!$P$55))
A27: =IF($B27="","",1+SUMPRODUCT(($B$3:$B$34<>"")*(($C$3:$C$34>C27)+(($C$3:$C$34=C27)*($Y$3:$Y$34>Y27))))) | B27: =IF(Setup!B29="","",Setup!B29) | C27: =IF($B27="","",SUM(D27,F27,H27,J27,L27,N27,P27,R27,T27,V27)) | D27: =IF($B27="","",IF('Round 1'!$S$31=0,"",'Round 1'!$F$56)) | E27: =IF($B27="","",IF('Round 1'!$S$31=0,"",'Round 1'!$Q$56)) | F27: =IF($B27="","",IF('Round 2'!$S$31=0,"",'Round 2'!$F$56)) | G27: =IF($B27="","",IF('Round 2'!$S$31=0,"",'Round 2'!$Q$56)) | H27: =IF($B27="","",IF('Round 3'!$S$31=0,"",'Round 3'!$F$56)) | I27: =IF($B27="","",IF('Round 3'!$S$31=0,"",'Round 3'!$Q$56)) | J27: =IF($B27="","",IF('Round 4'!$S$31=0,"",'Round 4'!$F$56)) | K27: =IF($B27="","",IF('Round 4'!$S$31=0,"",'Round 4'!$Q$56)) | L27: =IF($B27="","",IF('Round 5'!$S$31=0,"",'Round 5'!$F$56)) | M27: =IF($B27="","",IF('Round 5'!$S$31=0,"",'Round 5'!$Q$56)) | N27: =IF($B27="","",IF('Round 6'!$S$31=0,"",'Round 6'!$F$56)) | O27: =IF($B27="","",IF('Round 6'!$S$31=0,"",'Round 6'!$Q$56)) | P27: =IF($B27="","",IF('Round 7'!$S$31=0,"",'Round 7'!$F$56)) | Q27: =IF($B27="","",IF('Round 7'!$S$31=0,"",'Round 7'!$Q$56)) | R27: =IF($B27="","",IF('Round 8'!$S$31=0,"",'Round 8'!$F$56)) | S27: =IF($B27="","",IF('Round 8'!$S$31=0,"",'Round 8'!$Q$56)) | T27: =IF($B27="","",IF('Round 9'!$S$31=0,"",'Round 9'!$F$56)) | U27: =IF($B27="","",IF('Round 9'!$S$31=0,"",'Round 9'!$Q$56)) | V27: =IF($B27="","",IF('Round 10'!$S$31=0,"",'Round 10'!$F$56)) | W27: =IF($B27="","",IF('Round 10'!$S$31=0,"",'Round 10'!$Q$56)) | Y27: =IF(OR($B27="",$Y$1=0),0,CHOOSE($Y$1,'Round 1'!$P$56,'Round 2'!$P$56,'Round 3'!$P$56,'Round 4'!$P$56,'Round 5'!$P$56,'Round 6'!$P$56,'Round 7'!$P$56,'Round 8'!$P$56,'Round 9'!$P$56,'Round 10'!$P$56))
A28: =IF($B28="","",1+SUMPRODUCT(($B$3:$B$34<>"")*(($C$3:$C$34>C28)+(($C$3:$C$34=C28)*($Y$3:$Y$34>Y28))))) | B28: =IF(Setup!B30="","",Setup!B30) | C28: =IF($B28="","",SUM(D28,F28,H28,J28,L28,N28,P28,R28,T28,V28)) | D28: =IF($B28="","",IF('Round 1'!$S$31=0,"",'Round 1'!$F$57)) | E28: =IF($B28="","",IF('Round 1'!$S$31=0,"",'Round 1'!$Q$57)) | F28: =IF($B28="","",IF('Round 2'!$S$31=0,"",'Round 2'!$F$57)) | G28: =IF($B28="","",IF('Round 2'!$S$31=0,"",'Round 2'!$Q$57)) | H28: =IF($B28="","",IF('Round 3'!$S$31=0,"",'Round 3'!$F$57)) | I28: =IF($B28="","",IF('Round 3'!$S$31=0,"",'Round 3'!$Q$57)) | J28: =IF($B28="","",IF('Round 4'!$S$31=0,"",'Round 4'!$F$57)) | K28: =IF($B28="","",IF('Round 4'!$S$31=0,"",'Round 4'!$Q$57)) | L28: =IF($B28="","",IF('Round 5'!$S$31=0,"",'Round 5'!$F$57)) | M28: =IF($B28="","",IF('Round 5'!$S$31=0,"",'Round 5'!$Q$57)) | N28: =IF($B28="","",IF('Round 6'!$S$31=0,"",'Round 6'!$F$57)) | O28: =IF($B28="","",IF('Round 6'!$S$31=0,"",'Round 6'!$Q$57)) | P28: =IF($B28="","",IF('Round 7'!$S$31=0,"",'Round 7'!$F$57)) | Q28: =IF($B28="","",IF('Round 7'!$S$31=0,"",'Round 7'!$Q$57)) | R28: =IF($B28="","",IF('Round 8'!$S$31=0,"",'Round 8'!$F$57)) | S28: =IF($B28="","",IF('Round 8'!$S$31=0,"",'Round 8'!$Q$57)) | T28: =IF($B28="","",IF('Round 9'!$S$31=0,"",'Round 9'!$F$57)) | U28: =IF($B28="","",IF('Round 9'!$S$31=0,"",'Round 9'!$Q$57)) | V28: =IF($B28="","",IF('Round 10'!$S$31=0,"",'Round 10'!$F$57)) | W28: =IF($B28="","",IF('Round 10'!$S$31=0,"",'Round 10'!$Q$57)) | Y28: =IF(OR($B28="",$Y$1=0),0,CHOOSE($Y$1,'Round 1'!$P$57,'Round 2'!$P$57,'Round 3'!$P$57,'Round 4'!$P$57,'Round 5'!$P$57,'Round 6'!$P$57,'Round 7'!$P$57,'Round 8'!$P$57,'Round 9'!$P$57,'Round 10'!$P$57))
A29: =IF($B29="","",1+SUMPRODUCT(($B$3:$B$34<>"")*(($C$3:$C$34>C29)+(($C$3:$C$34=C29)*($Y$3:$Y$34>Y29))))) | B29: =IF(Setup!B31="","",Setup!B31) | C29: =IF($B29="","",SUM(D29,F29,H29,J29,L29,N29,P29,R29,T29,V29)) | D29: =IF($B29="","",IF('Round 1'!$S$31=0,"",'Round 1'!$F$58)) | E29: =IF($B29="","",IF('Round 1'!$S$31=0,"",'Round 1'!$Q$58)) | F29: =IF($B29="","",IF('Round 2'!$S$31=0,"",'Round 2'!$F$58)) | G29: =IF($B29="","",IF('Round 2'!$S$31=0,"",'Round 2'!$Q$58)) | H29: =IF($B29="","",IF('Round 3'!$S$31=0,"",'Round 3'!$F$58)) | I29: =IF($B29="","",IF('Round 3'!$S$31=0,"",'Round 3'!$Q$58)) | J29: =IF($B29="","",IF('Round 4'!$S$31=0,"",'Round 4'!$F$58)) | K29: =IF($B29="","",IF('Round 4'!$S$31=0,"",'Round 4'!$Q$58)) | L29: =IF($B29="","",IF('Round 5'!$S$31=0,"",'Round 5'!$F$58)) | M29: =IF($B29="","",IF('Round 5'!$S$31=0,"",'Round 5'!$Q$58)) | N29: =IF($B29="","",IF('Round 6'!$S$31=0,"",'Round 6'!$F$58)) | O29: =IF($B29="","",IF('Round 6'!$S$31=0,"",'Round 6'!$Q$58)) | P29: =IF($B29="","",IF('Round 7'!$S$31=0,"",'Round 7'!$F$58)) | Q29: =IF($B29="","",IF('Round 7'!$S$31=0,"",'Round 7'!$Q$58)) | R29: =IF($B29="","",IF('Round 8'!$S$31=0,"",'Round 8'!$F$58)) | S29: =IF($B29="","",IF('Round 8'!$S$31=0,"",'Round 8'!$Q$58)) | T29: =IF($B29="","",IF('Round 9'!$S$31=0,"",'Round 9'!$F$58)) | U29: =IF($B29="","",IF('Round 9'!$S$31=0,"",'Round 9'!$Q$58)) | V29: =IF($B29="","",IF('Round 10'!$S$31=0,"",'Round 10'!$F$58)) | W29: =IF($B29="","",IF('Round 10'!$S$31=0,"",'Round 10'!$Q$58)) | Y29: =IF(OR($B29="",$Y$1=0),0,CHOOSE($Y$1,'Round 1'!$P$58,'Round 2'!$P$58,'Round 3'!$P$58,'Round 4'!$P$58,'Round 5'!$P$58,'Round 6'!$P$58,'Round 7'!$P$58,'Round 8'!$P$58,'Round 9'!$P$58,'Round 10'!$P$58))
A30: =IF($B30="","",1+SUMPRODUCT(($B$3:$B$34<>"")*(($C$3:$C$34>C30)+(($C$3:$C$34=C30)*($Y$3:$Y$34>Y30))))) | B30: =IF(Setup!B32="","",Setup!B32) | C30: =IF($B30="","",SUM(D30,F30,H30,J30,L30,N30,P30,R30,T30,V30)) | D30: =IF($B30="","",IF('Round 1'!$S$31=0,"",'Round 1'!$F$59)) | E30: =IF($B30="","",IF('Round 1'!$S$31=0,"",'Round 1'!$Q$59)) | F30: =IF($B30="","",IF('Round 2'!$S$31=0,"",'Round 2'!$F$59)) | G30: =IF($B30="","",IF('Round 2'!$S$31=0,"",'Round 2'!$Q$59)) | H30: =IF($B30="","",IF('Round 3'!$S$31=0,"",'Round 3'!$F$59)) | I30: =IF($B30="","",IF('Round 3'!$S$31=0,"",'Round 3'!$Q$59)) | J30: =IF($B30="","",IF('Round 4'!$S$31=0,"",'Round 4'!$F$59)) | K30: =IF($B30="","",IF('Round 4'!$S$31=0,"",'Round 4'!$Q$59)) | L30: =IF($B30="","",IF('Round 5'!$S$31=0,"",'Round 5'!$F$59)) | M30: =IF($B30="","",IF('Round 5'!$S$31=0,"",'Round 5'!$Q$59)) | N30: =IF($B30="","",IF('Round 6'!$S$31=0,"",'Round 6'!$F$59)) | O30: =IF($B30="","",IF('Round 6'!$S$31=0,"",'Round 6'!$Q$59)) | P30: =IF($B30="","",IF('Round 7'!$S$31=0,"",'Round 7'!$F$59)) | Q30: =IF($B30="","",IF('Round 7'!$S$31=0,"",'Round 7'!$Q$59)) | R30: =IF($B30="","",IF('Round 8'!$S$31=0,"",'Round 8'!$F$59)) | S30: =IF($B30="","",IF('Round 8'!$S$31=0,"",'Round 8'!$Q$59)) | T30: =IF($B30="","",IF('Round 9'!$S$31=0,"",'Round 9'!$F$59)) | U30: =IF($B30="","",IF('Round 9'!$S$31=0,"",'Round 9'!$Q$59)) | V30: =IF($B30="","",IF('Round 10'!$S$31=0,"",'Round 10'!$F$59)) | W30: =IF($B30="","",IF('Round 10'!$S$31=0,"",'Round 10'!$Q$59)) | Y30: =IF(OR($B30="",$Y$1=0),0,CHOOSE($Y$1,'Round 1'!$P$59,'Round 2'!$P$59,'Round 3'!$P$59,'Round 4'!$P$59,'Round 5'!$P$59,'Round 6'!$P$59,'Round 7'!$P$59,'Round 8'!$P$59,'Round 9'!$P$59,'Round 10'!$P$59))
A31: =IF($B31="","",1+SUMPRODUCT(($B$3:$B$34<>"")*(($C$3:$C$34>C31)+(($C$3:$C$34=C31)*($Y$3:$Y$34>Y31))))) | B31: =IF(Setup!B33="","",Setup!B33) | C31: =IF($B31="","",SUM(D31,F31,H31,J31,L31,N31,P31,R31,T31,V31)) | D31: =IF($B31="","",IF('Round 1'!$S$31=0,"",'Round 1'!$F$60)) | E31: =IF($B31="","",IF('Round 1'!$S$31=0,"",'Round 1'!$Q$60)) | F31: =IF($B31="","",IF('Round 2'!$S$31=0,"",'Round 2'!$F$60)) | G31: =IF($B31="","",IF('Round 2'!$S$31=0,"",'Round 2'!$Q$60)) | H31: =IF($B31="","",IF('Round 3'!$S$31=0,"",'Round 3'!$F$60)) | I31: =IF($B31="","",IF('Round 3'!$S$31=0,"",'Round 3'!$Q$60)) | J31: =IF($B31="","",IF('Round 4'!$S$31=0,"",'Round 4'!$F$60)) | K31: =IF($B31="","",IF('Round 4'!$S$31=0,"",'Round 4'!$Q$60)) | L31: =IF($B31="","",IF('Round 5'!$S$31=0,"",'Round 5'!$F$60)) | M31: =IF($B31="","",IF('Round 5'!$S$31=0,"",'Round 5'!$Q$60)) | N31: =IF($B31="","",IF('Round 6'!$S$31=0,"",'Round 6'!$F$60)) | O31: =IF($B31="","",IF('Round 6'!$S$31=0,"",'Round 6'!$Q$60)) | P31: =IF($B31="","",IF('Round 7'!$S$31=0,"",'Round 7'!$F$60)) | Q31: =IF($B31="","",IF('Round 7'!$S$31=0,"",'Round 7'!$Q$60)) | R31: =IF($B31="","",IF('Round 8'!$S$31=0,"",'Round 8'!$F$60)) | S31: =IF($B31="","",IF('Round 8'!$S$31=0,"",'Round 8'!$Q$60)) | T31: =IF($B31="","",IF('Round 9'!$S$31=0,"",'Round 9'!$F$60)) | U31: =IF($B31="","",IF('Round 9'!$S$31=0,"",'Round 9'!$Q$60)) | V31: =IF($B31="","",IF('Round 10'!$S$31=0,"",'Round 10'!$F$60)) | W31: =IF($B31="","",IF('Round 10'!$S$31=0,"",'Round 10'!$Q$60)) | Y31: =IF(OR($B31="",$Y$1=0),0,CHOOSE($Y$1,'Round 1'!$P$60,'Round 2'!$P$60,'Round 3'!$P$60,'Round 4'!$P$60,'Round 5'!$P$60,'Round 6'!$P$60,'Round 7'!$P$60,'Round 8'!$P$60,'Round 9'!$P$60,'Round 10'!$P$60))
A32: =IF($B32="","",1+SUMPRODUCT(($B$3:$B$34<>"")*(($C$3:$C$34>C32)+(($C$3:$C$34=C32)*($Y$3:$Y$34>Y32))))) | B32: =IF(Setup!B34="","",Setup!B34) | C32: =IF($B32="","",SUM(D32,F32,H32,J32,L32,N32,P32,R32,T32,V32)) | D32: =IF($B32="","",IF('Round 1'!$S$31=0,"",'Round 1'!$F$61)) | E32: =IF($B32="","",IF('Round 1'!$S$31=0,"",'Round 1'!$Q$61)) | F32: =IF($B32="","",IF('Round 2'!$S$31=0,"",'Round 2'!$F$61)) | G32: =IF($B32="","",IF('Round 2'!$S$31=0,"",'Round 2'!$Q$61)) | H32: =IF($B32="","",IF('Round 3'!$S$31=0,"",'Round 3'!$F$61)) | I32: =IF($B32="","",IF('Round 3'!$S$31=0,"",'Round 3'!$Q$61)) | J32: =IF($B32="","",IF('Round 4'!$S$31=0,"",'Round 4'!$F$61)) | K32: =IF($B32="","",IF('Round 4'!$S$31=0,"",'Round 4'!$Q$61)) | L32: =IF($B32="","",IF('Round 5'!$S$31=0,"",'Round 5'!$F$61)) | M32: =IF($B32="","",IF('Round 5'!$S$31=0,"",'Round 5'!$Q$61)) | N32: =IF($B32="","",IF('Round 6'!$S$31=0,"",'Round 6'!$F$61)) | O32: =IF($B32="","",IF('Round 6'!$S$31=0,"",'Round 6'!$Q$61)) | P32: =IF($B32="","",IF('Round 7'!$S$31=0,"",'Round 7'!$F$61)) | Q32: =IF($B32="","",IF('Round 7'!$S$31=0,"",'Round 7'!$Q$61)) | R32: =IF($B32="","",IF('Round 8'!$S$31=0,"",'Round 8'!$F$61)) | S32: =IF($B32="","",IF('Round 8'!$S$31=0,"",'Round 8'!$Q$61)) | T32: =IF($B32="","",IF('Round 9'!$S$31=0,"",'Round 9'!$F$61)) | U32: =IF($B32="","",IF('Round 9'!$S$31=0,"",'Round 9'!$Q$61)) | V32: =IF($B32="","",IF('Round 10'!$S$31=0,"",'Round 10'!$F$61)) | W32: =IF($B32="","",IF('Round 10'!$S$31=0,"",'Round 10'!$Q$61)) | Y32: =IF(OR($B32="",$Y$1=0),0,CHOOSE($Y$1,'Round 1'!$P$61,'Round 2'!$P$61,'Round 3'!$P$61,'Round 4'!$P$61,'Round 5'!$P$61,'Round 6'!$P$61,'Round 7'!$P$61,'Round 8'!$P$61,'Round 9'!$P$61,'Round 10'!$P$61))
A33: =IF($B33="","",1+SUMPRODUCT(($B$3:$B$34<>"")*(($C$3:$C$34>C33)+(($C$3:$C$34=C33)*($Y$3:$Y$34>Y33))))) | B33: =IF(Setup!B35="","",Setup!B35) | C33: =IF($B33="","",SUM(D33,F33,H33,J33,L33,N33,P33,R33,T33,V33)) | D33: =IF($B33="","",IF('Round 1'!$S$31=0,"",'Round 1'!$F$62)) | E33: =IF($B33="","",IF('Round 1'!$S$31=0,"",'Round 1'!$Q$62)) | F33: =IF($B33="","",IF('Round 2'!$S$31=0,"",'Round 2'!$F$62)) | G33: =IF($B33="","",IF('Round 2'!$S$31=0,"",'Round 2'!$Q$62)) | H33: =IF($B33="","",IF('Round 3'!$S$31=0,"",'Round 3'!$F$62)) | I33: =IF($B33="","",IF('Round 3'!$S$31=0,"",'Round 3'!$Q$62)) | J33: =IF($B33="","",IF('Round 4'!$S$31=0,"",'Round 4'!$F$62)) | K33: =IF($B33="","",IF('Round 4'!$S$31=0,"",'Round 4'!$Q$62)) | L33: =IF($B33="","",IF('Round 5'!$S$31=0,"",'Round 5'!$F$62)) | M33: =IF($B33="","",IF('Round 5'!$S$31=0,"",'Round 5'!$Q$62)) | N33: =IF($B33="","",IF('Round 6'!$S$31=0,"",'Round 6'!$F$62)) | O33: =IF($B33="","",IF('Round 6'!$S$31=0,"",'Round 6'!$Q$62)) | P33: =IF($B33="","",IF('Round 7'!$S$31=0,"",'Round 7'!$F$62)) | Q33: =IF($B33="","",IF('Round 7'!$S$31=0,"",'Round 7'!$Q$62)) | R33: =IF($B33="","",IF('Round 8'!$S$31=0,"",'Round 8'!$F$62)) | S33: =IF($B33="","",IF('Round 8'!$S$31=0,"",'Round 8'!$Q$62)) | T33: =IF($B33="","",IF('Round 9'!$S$31=0,"",'Round 9'!$F$62)) | U33: =IF($B33="","",IF('Round 9'!$S$31=0,"",'Round 9'!$Q$62)) | V33: =IF($B33="","",IF('Round 10'!$S$31=0,"",'Round 10'!$F$62)) | W33: =IF($B33="","",IF('Round 10'!$S$31=0,"",'Round 10'!$Q$62)) | Y33: =IF(OR($B33="",$Y$1=0),0,CHOOSE($Y$1,'Round 1'!$P$62,'Round 2'!$P$62,'Round 3'!$P$62,'Round 4'!$P$62,'Round 5'!$P$62,'Round 6'!$P$62,'Round 7'!$P$62,'Round 8'!$P$62,'Round 9'!$P$62,'Round 10'!$P$62))
A34: =IF($B34="","",1+SUMPRODUCT(($B$3:$B$34<>"")*(($C$3:$C$34>C34)+(($C$3:$C$34=C34)*($Y$3:$Y$34>Y34))))) | B34: =IF(Setup!B36="","",Setup!B36) | C34: =IF($B34="","",SUM(D34,F34,H34,J34,L34,N34,P34,R34,T34,V34)) | D34: =IF($B34="","",IF('Round 1'!$S$31=0,"",'Round 1'!$F$63)) | E34: =IF($B34="","",IF('Round 1'!$S$31=0,"",'Round 1'!$Q$63)) | F34: =IF($B34="","",IF('Round 2'!$S$31=0,"",'Round 2'!$F$63)) | G34: =IF($B34="","",IF('Round 2'!$S$31=0,"",'Round 2'!$Q$63)) | H34: =IF($B34="","",IF('Round 3'!$S$31=0,"",'Round 3'!$F$63)) | I34: =IF($B34="","",IF('Round 3'!$S$31=0,"",'Round 3'!$Q$63)) | J34: =IF($B34="","",IF('Round 4'!$S$31=0,"",'Round 4'!$F$63)) | K34: =IF($B34="","",IF('Round 4'!$S$31=0,"",'Round 4'!$Q$63)) | L34: =IF($B34="","",IF('Round 5'!$S$31=0,"",'Round 5'!$F$63)) | M34: =IF($B34="","",IF('Round 5'!$S$31=0,"",'Round 5'!$Q$63)) | N34: =IF($B34="","",IF('Round 6'!$S$31=0,"",'Round 6'!$F$63)) | O34: =IF($B34="","",IF('Round 6'!$S$31=0,"",'Round 6'!$Q$63)) | P34: =IF($B34="","",IF('Round 7'!$S$31=0,"",'Round 7'!$F$63)) | Q34: =IF($B34="","",IF('Round 7'!$S$31=0,"",'Round 7'!$Q$63)) | R34: =IF($B34="","",IF('Round 8'!$S$31=0,"",'Round 8'!$F$63)) | S34: =IF($B34="","",IF('Round 8'!$S$31=0,"",'Round 8'!$Q$63)) | T34: =IF($B34="","",IF('Round 9'!$S$31=0,"",'Round 9'!$F$63)) | U34: =IF($B34="","",IF('Round 9'!$S$31=0,"",'Round 9'!$Q$63)) | V34: =IF($B34="","",IF('Round 10'!$S$31=0,"",'Round 10'!$F$63)) | W34: =IF($B34="","",IF('Round 10'!$S$31=0,"",'Round 10'!$Q$63)) | Y34: =IF(OR($B34="",$Y$1=0),0,CHOOSE($Y$1,'Round 1'!$P$63,'Round 2'!$P$63,'Round 3'!$P$63,'Round 4'!$P$63,'Round 5'!$P$63,'Round 6'!$P$63,'Round 7'!$P$63,'Round 8'!$P$63,'Round 9'!$P$63,'Round 10'!$P$63))

Sheet Handicapping
A1: Players on trip: | B1: =COUNTA(Setup!$B$5:$B$36)
A3: No. | B3: Player | C3: Start H'cap | D3: Rd 1 | E3: Rd 2 | F3: Rd 3 | G3: Rd 4 | H3: Rd 5 | I3: Rd 6 | J3: Rd 7 | K3: Rd 8 | L3: Rd 9 | M3: Rd 10 | N3: End H'cap | O3: Total +/-
A4: 1 | B4: =IF(Setup!B5="","",Setup!B5) | C4: =IF($B4="","",N(Setup!E5)) | D4: =IF($B4="","",$C4) | E4: =IF($B4="","",D4+IF('Round 1'!$S$31>0,N(INDEX($B$40:$B$71,'Round 1'!$Q$32)),0)) | F4: =IF($B4="","",E4+IF('Round 2'!$S$31>0,N(INDEX($B$40:$B$71,'Round 2'!$Q$32)),0)) | G4: =IF($B4="","",F4+IF('Round 3'!$S$31>0,N(INDEX($B$40:$B$71,'Round 3'!$Q$32)),0)) | H4: =IF($B4="","",G4+IF('Round 4'!$S$31>0,N(INDEX($B$40:$B$71,'Round 4'!$Q$32)),0)) | I4: =IF($B4="","",H4+IF('Round 5'!$S$31>0,N(INDEX($B$40:$B$71,'Round 5'!$Q$32)),0)) | J4: =IF($B4="","",I4+IF('Round 6'!$S$31>0,N(INDEX($B$40:$B$71,'Round 6'!$Q$32)),0)) | K4: =IF($B4="","",J4+IF('Round 7'!$S$31>0,N(INDEX($B$40:$B$71,'Round 7'!$Q$32)),0)) | L4: =IF($B4="","",K4+IF('Round 8'!$S$31>0,N(INDEX($B$40:$B$71,'Round 8'!$Q$32)),0)) | M4: =IF($B4="","",L4+IF('Round 9'!$S$31>0,N(INDEX($B$40:$B$71,'Round 9'!$Q$32)),0)) | N4: =IF($B4="","",M4+IF('Round 10'!$S$31>0,N(INDEX($B$40:$B$71,'Round 10'!$Q$32)),0)) | O4: =IF($B4="","",N4-$C4)
