Workbook

Sheet Leaderboard
A1: Total | B1: Position | D1: Player | E1: Rd.1 | F1: Position | H1: Rd.2 | I1: Position | K1: Rd.3 | L1: Position | N1: Rd.4 | O1: Position | Q1: Rd.5 | R1: Position
A2: =SUM(E2+H2+K2+N2+Q2) -> #REF! | B2: =RANK(A2, $A$2:$A$10, 0) -> #REF! | E2: ='Daily Scoring'!X25 -> 0 | F2: =RANK(E2,$E$2:$E$10,0) -> #REF! | H2: ='Daily Scoring'!AQ25 -> 0 | I2: =RANK(H2,$H$2:$H$10,0) -> 1 | K2: ='Daily Scoring'!#REF! -> #REF! | L2: =RANK(K2,$K$2:$K$10,0) -> #REF! | N2: ='Daily Scoring'!#REF! -> #REF! | O2: =RANK(N2,$N$2:$N$10,0) -> #REF! | Q2: ='Daily Scoring'!#REF! -> #REF! | R2: =RANK(Q2,$Q$2:$Q$10,0) -> #REF!
A3: =SUM(E3+H3+K3+N3+Q3) -> #REF! | B3: =RANK(A3, $A$2:$A$10, 0) -> #REF! | E3: ='Daily Scoring'!Z25 -> 0 | F3: =RANK(E3,$E$2:$E$10,0) -> #REF! | H3: ='Daily Scoring'!AS25 -> 0 | I3: =RANK(H3,$H$2:$H$10,0) -> 1 | K3: ='Daily Scoring'!#REF! -> #REF! | L3: =RANK(K3,$K$2:$K$10,0) -> #REF! | N3: ='Daily Scoring'!#REF! -> #REF! | O3: =RANK(N3,$N$2:$N$10,0) -> #REF! | Q3: ='Daily Scoring'!#REF! -> #REF! | R3: =RANK(Q3,$Q$2:$Q$10,0) -> #REF!
A4: =SUM(E4+H4+K4+N4+Q4) -> #REF! | B4: =RANK(A4, $A$2:$A$10, 0) -> #REF! | E4: ='Daily Scoring'!AB25 -> 0 | F4: =RANK(E4,$E$2:$E$10,0) -> #REF! | H4: ='Daily Scoring'!AU25 -> 0 | I4: =RANK(H4,$H$2:$H$10,0) -> 1 | K4: ='Daily Scoring'!#REF! -> #REF! | L4: =RANK(K4,$K$2:$K$10,0) -> #REF! | N4: ='Daily Scoring'!#REF! -> #REF! | O4: =RANK(N4,$N$2:$N$10,0) -> #REF! | Q4: ='Daily Scoring'!#REF! -> #REF! | R4: =RANK(Q4,$Q$2:$Q$10,0) -> #REF!
A5: =SUM(E5+H5+K5+N5+Q5) -> #REF! | B5: =RANK(A5, $A$2:$A$10, 0) -> #REF! | E5: ='Daily Scoring'!AE25 -> 0 | F5: =RANK(E5,$E$2:$E$10,0) -> #REF! | H5: ='Daily Scoring'!AW25 -> 0 | I5: =RANK(H5,$H$2:$H$10,0) -> 1 | K5: ='Daily Scoring'!#REF! -> #REF! | L5: =RANK(K5,$K$2:$K$10,0) -> #REF! | N5: ='Daily Scoring'!#REF! -> #REF! | O5: =RANK(N5,$N$2:$N$10,0) -> #REF! | Q5: ='Daily Scoring'!#REF! -> #REF! | R5: =RANK(Q5,$Q$2:$Q$10,0) -> #REF!
A6: =SUM(E6+H6+K6+N6+Q6) -> #REF! | B6: =RANK(A6, $A$2:$A$10, 0) -> #REF! | E6: ='Daily Scoring'!AF25 -> 0 | F6: =RANK(E6,$E$2:$E$10,0) -> #REF! | H6: ='Daily Scoring'!AY25 -> 0 | I6: =RANK(H6,$H$2:$H$10,0) -> 1 | K6: ='Daily Scoring'!#REF! -> #REF! | L6: =RANK(K6,$K$2:$K$10,0) -> #REF! | N6: ='Daily Scoring'!#REF! -> #REF! | O6: =RANK(N6,$N$2:$N$10,0) -> #REF! | Q6: ='Daily Scoring'!#REF! -> #REF! | R6: =RANK(Q6,$Q$2:$Q$10,0) -> #REF!
A7: =SUM(E7+H7+K7+N7+Q7) -> #REF! | B7: =RANK(A7, $A$2:$A$10, 0) -> #REF! | E7: ='Daily Scoring'!AH25 -> 0 | F7: =RANK(E7,$E$2:$E$10,0) -> #REF! | H7: ='Daily Scoring'!BA25 -> 0 | I7: =RANK(H7,$H$2:$H$10,0) -> 1 | K7: ='Daily Scoring'!#REF! -> #REF! | L7: =RANK(K7,$K$2:$K$10,0) -> #REF! | N7: ='Daily Scoring'!#REF! -> #REF! | O7: =RANK(N7,$N$2:$N$10,0) -> #REF! | Q7: ='Daily Scoring'!#REF! -> #REF! | R7: =RANK(Q7,$Q$2:$Q$10,0) -> #REF!
A8: =SUM(E8+H8+K8+N8+Q8) -> #REF! | B8: =RANK(A8, $A$2:$A$10, 0) -> #REF! | E8: ='Daily Scoring'!#REF! -> #REF! | F8: =RANK(E8,$E$2:$E$10,0) -> #REF! | H8: ='Daily Scoring'!BC25 -> 0 | I8: =RANK(H8,$H$2:$H$10,0) -> 1 | K8: ='Daily Scoring'!#REF! -> #REF! | L8: =RANK(K8,$K$2:$K$10,0) -> #REF! | N8: ='Daily Scoring'!#REF! -> #REF! | O8: =RANK(N8,$N$2:$N$10,0) -> #REF! | Q8: ='Daily Scoring'!#REF! -> #REF! | R8: =RANK(Q8,$Q$2:$Q$10,0) -> #REF!
A9: =SUM(E9+H9+K9+N9+Q9) -> #REF! | B9: =RANK(A9, $A$2:$A$10, 0) -> #REF! | E9: ='Daily Scoring'!#REF! -> #REF! | F9: =RANK(E9,$E$2:$E$10,0) -> #REF! | H9: ='Daily Scoring'!BE25 -> 0 | I9: =RANK(H9,$H$2:$H$10,0) -> 1 | K9: ='Daily Scoring'!#REF! -> #REF! | L9: =RANK(K9,$K$2:$K$10,0) -> #REF! | N9: ='Daily Scoring'!#REF! -> #REF! | O9: =RANK(N9,$N$2:$N$10,0) -> #REF! | Q9: ='Daily Scoring'!#REF! -> #REF! | R9: =RANK(Q9,$Q$2:$Q$10,0) -> #REF!
A10: =SUM(E10+H10+K10+N10+Q10) -> #REF! | B10: =RANK(A10, $A$2:$A$10, 0) -> #REF! | E10: ='Daily Scoring'!#REF! -> #REF! | F10: =RANK(E10,$E$2:$E$10,0) -> #REF! | H10: ='Daily Scoring'!BG25 -> 0 | I10: =RANK(H10,$H$2:$H$10,0) -> 1 | K10: ='Daily Scoring'!#REF! -> #REF! | L10: =RANK(K10,$K$2:$K$10,0) -> #REF! | N10: ='Daily Scoring'!#REF! -> #REF! | O10: =RANK(N10,$N$2:$N$10,0) -> #REF! | Q10: ='Daily Scoring'!#REF! -> #REF! | R10: =RANK(Q10,$Q$2:$Q$10,0) -> #REF!
A11: =SUM(E11+H11+K11+N11+Q11) -> #REF! | B11: =RANK(A11, $A$2:$A$10, 0) -> #REF! | E11: ='Daily Scoring'!#REF! -> #REF! | F11: =RANK(E11,$E$2:$E$10,0) -> #REF! | H11: ='Daily Scoring'!AQ34 -> 0 | I11: =RANK(H11,$H$2:$H$10,0) -> 1 | K11: ='Daily Scoring'!#REF! -> #REF! | L11: =RANK(K11,$K$2:$K$10,0) -> #REF! | N11: ='Daily Scoring'!#REF! -> #REF! | O11: =RANK(N11,$N$2:$N$10,0) -> #REF! | Q11: ='Daily Scoring'!#REF! -> #REF! | R11: =RANK(Q11,$Q$2:$Q$10,0) -> #REF!
A12: =SUM(E12+H12+K12+N12+Q12) -> #REF! | B12: =RANK(A12, $A$2:$A$10, 0) -> #REF! | E12: ='Daily Scoring'!#REF! -> #REF! | F12: =RANK(E12,$E$2:$E$10,0) -> #REF! | H12: ='Daily Scoring'!AS34 -> 0 | I12: =RANK(H12,$H$2:$H$10,0) -> 1 | K12: ='Daily Scoring'!#REF! -> #REF! | L12: =RANK(K12,$K$2:$K$10,0) -> #REF! | N12: ='Daily Scoring'!#REF! -> #REF! | O12: =RANK(N12,$N$2:$N$10,0) -> #REF! | Q12: ='Daily Scoring'!#REF! -> #REF! | R12: =RANK(Q12,$Q$2:$Q$10,0) -> #REF!
A13: =SUM(E13+H13+K13+N13+Q13) -> #REF! | B13: =RANK(A13, $A$2:$A$10, 0) -> #REF! | E13: ='Daily Scoring'!#REF! -> #REF! | F13: =RANK(E13,$E$2:$E$10,0) -> #REF! | H13: ='Daily Scoring'!AU34 -> 0 | I13: =RANK(H13,$H$2:$H$10,0) -> 1 | K13: ='Daily Scoring'!#REF! -> #REF! | L13: =RANK(K13,$K$2:$K$10,0) -> #REF! | N13: ='Daily Scoring'!#REF! -> #REF! | O13: =RANK(N13,$N$2:$N$10,0) -> #REF! | Q13: ='Daily Scoring'!#REF! -> #REF! | R13: =RANK(Q13,$Q$2:$Q$10,0) -> #REF!
A14: =SUM(E14+H14+K14+N14+Q14) -> #REF! | B14: =RANK(A14, $A$2:$A$10, 0) -> #REF! | E14: ='Daily Scoring'!#REF! -> #REF! | F14: =RANK(E14,$E$2:$E$10,0) -> #REF! | H14: ='Daily Scoring'!AW34 -> 0 | I14: =RANK(H14,$H$2:$H$10,0) -> 1 | K14: ='Daily Scoring'!#REF! -> #REF! | L14: =RANK(K14,$K$2:$K$10,0) -> #REF! | N14: ='Daily Scoring'!#REF! -> #REF! | O14: =RANK(N14,$N$2:$N$10,0) -> #REF! | Q14: ='Daily Scoring'!#REF! -> #REF! | R14: =RANK(Q14,$Q$2:$Q$10,0) -> #REF!
A15: =SUM(E15+H15+K15+N15+Q15) -> #REF! | B15: =RANK(A15, $A$2:$A$10, 0) -> #REF! | E15: ='Daily Scoring'!#REF! -> #REF! | F15: =RANK(E15,$E$2:$E$10,0) -> #REF! | H15: ='Daily Scoring'!AY34 -> 0 | I15: =RANK(H15,$H$2:$H$10,0) -> 1 | K15: ='Daily Scoring'!#REF! -> #REF! | L15: =RANK(K15,$K$2:$K$10,0) -> #REF! | N15: ='Daily Scoring'!#REF! -> #REF! | O15: =RANK(N15,$N$2:$N$10,0) -> #REF! | Q15: ='Daily Scoring'!#REF! -> #REF! | R15: =RANK(Q15,$Q$2:$Q$10,0) -> #REF!
A16: =SUM(E16+H16+K16+N16+Q16) -> #REF! | B16: =RANK(A16, $A$2:$A$10, 0) -> #REF! | E16: ='Daily Scoring'!#REF! -> #REF! | F16: =RANK(E16,$E$2:$E$10,0) -> #REF! | H16: ='Daily Scoring'!BA34 -> 0 | I16: =RANK(H16,$H$2:$H$10,0) -> 1 | K16: ='Daily Scoring'!#REF! -> #REF! | L16: =RANK(K16,$K$2:$K$10,0) -> #REF! | N16: ='Daily Scoring'!#REF! -> #REF! | O16: =RANK(N16,$N$2:$N$10,0) -> #REF! | Q16: ='Daily Scoring'!#REF! -> #REF! | R16: =RANK(Q16,$Q$2:$Q$10,0) -> #REF!
A17: =SUM(E17+H17+K17+N17+Q17) -> #REF! | B17: =RANK(A17, $A$2:$A$10, 0) -> #REF! | E17: ='Daily Scoring'!#REF! -> #REF! | F17: =RANK(E17,$E$2:$E$10,0) -> #REF! | H17: ='Daily Scoring'!BC34 -> 0 | I17: =RANK(H17,$H$2:$H$10,0) -> 1 | K17: ='Daily Scoring'!#REF! -> #REF! | L17: =RANK(K17,$K$2:$K$10,0) -> #REF! | N17: ='Daily Scoring'!#REF! -> #REF! | O17: =RANK(N17,$N$2:$N$10,0) -> #REF! | Q17: ='Daily Scoring'!#REF! -> #REF! | R17: =RANK(Q17,$Q$2:$Q$10,0) -> #REF!

Sheet Handicapping
A1: Total Rounds: | B1: 5
A2: Golflink No. | B2: Player | C2: Leaderboard | D2: GA | E2: {=_xlfn.SEQUENCE(1,B1,1,1)} -> 1 | F2: 2 | G2: 3 | H2: 4 | I2: 5 | K2: Total +/-
A3: 4090903820 | B3: Attiwill, Scott | C3: Trawler | D3: 14 | E3: =D3 -> 14 | F3: =_xlfn.XLOOKUP(_xlfn.XLOOKUP($B3,Leaderboard!$D$2:$D$10,Leaderboard!F$2:F$10),$A$23:$A$31,$B$23:$B$31)+E3 -> #N/A | G3: =_xlfn.XLOOKUP(_xlfn.XLOOKUP($B3,Leaderboard!$D$2:$D$10,Leaderboard!I$2:I$10),$A$23:$A$31,$B$23:$B$31)+F3 -> #N/A | H3: =_xlfn.XLOOKUP(_xlfn.XLOOKUP($B3,Leaderboard!$D$2:$D$10,Leaderboard!L$2:L$10),$A$23:$A$31,$B$23:$B$31)+G3 -> #N/A | I3: =_xlfn.XLOOKUP(_xlfn.XLOOKUP($B3,Leaderboard!$D$2:$D$10,Leaderboard!R$2:R$10),$A$23:$A$31,$B$23:$B$31)+H3 -> #N/A
A4: 4090901889 | B4: Hoy, John | C4: Johnny | D4: 8 | E4: =D4 -> 8 | F4: =_xlfn.XLOOKUP(_xlfn.XLOOKUP($B4,Leaderboard!$D$2:$D$10,Leaderboard!F$2:F$10),$A$23:$A$31,$B$23:$B$31)+E4 -> #N/A | G4: =_xlfn.XLOOKUP(_xlfn.XLOOKUP($B4,Leaderboard!$D$2:$D$10,Leaderboard!I$2:I$10),$A$23:$A$31,$B$23:$B$31)+F4 -> #N/A | H4: =_xlfn.XLOOKUP(_xlfn.XLOOKUP($B4,Leaderboard!$D$2:$D$10,Leaderboard!L$2:L$10),$A$23:$A$31,$B$23:$B$31)+G4 -> #N/A | I4: =_xlfn.XLOOKUP(_xlfn.XLOOKUP($B4,Leaderboard!$D$2:$D$10,Leaderboard!R$2:R$10),$A$23:$A$31,$B$23:$B$31)+H4 -> #N/A
A5: 4140302911 | B5: Ireland, Kev | C5: Kebbie | D5: 12 | E5: =D5 -> 12 | F5: =_xlfn.XLOOKUP(_xlfn.XLOOKUP($B5,Leaderboard!$D$2:$D$10,Leaderboard!F$2:F$10),$A$23:$A$31,$B$23:$B$31)+E5 -> #N/A | G5: =_xlfn.XLOOKUP(_xlfn.XLOOKUP($B5,Leaderboard!$D$2:$D$10,Leaderboard!I$2:I$10),$A$23:$A$31,$B$23:$B$31)+F5 -> #N/A | H5: =_xlfn.XLOOKUP(_xlfn.XLOOKUP($B5,Leaderboard!$D$2:$D$10,Leaderboard!L$2:L$10),$A$23:$A$31,$B$23:$B$31)+G5 -> #N/A | I5: =_xlfn.XLOOKUP(_xlfn.XLOOKUP($B5,Leaderboard!$D$2:$D$10,Leaderboard!R$2:R$10),$A$23:$A$31,$B$23:$B$31)+H5 -> #N/A
A6: 4090904266 | B6: Lay, Greg | C6: Greg | D6: 12 | E6: =D6 -> 12 | F6: =_xlfn.XLOOKUP(_xlfn.XLOOKUP($B6,Leaderboard!$D$2:$D$10,Leaderboard!F$2:F$10),$A$23:$A$31,$B$23:$B$31)+E6 -> #N/A | G6: =_xlfn.XLOOKUP(_xlfn.XLOOKUP($B6,Leaderboard!$D$2:$D$10,Leaderboard!I$2:I$10),$A$23:$A$31,$B$23:$B$31)+F6 -> #N/A | H6: =_xlfn.XLOOKUP(_xlfn.XLOOKUP($B6,Leaderboard!$D$2:$D$10,Leaderboard!L$2:L$10),$A$23:$A$31,$B$23:$B$31)+G6 -> #N/A | I6: =_xlfn.XLOOKUP(_xlfn.XLOOKUP($B6,Leaderboard!$D$2:$D$10,Leaderboard!R$2:R$10),$A$23:$A$31,$B$23:$B$31)+H6 -> #N/A
A7: 0 | B7: Leeson, Chris | C7: Leeso | D7: 25 | E7: =D7 -> 25 | F7: =_xlfn.XLOOKUP(_xlfn.XLOOKUP($B7,Leaderboard!$D$2:$D$10,Leaderboard!F$2:F$10),$A$23:$A$31,$B$23:$B$31)+E7 -> #N/A | G7: =_xlfn.XLOOKUP(_xlfn.XLOOKUP($B7,Leaderboard!$D$2:$D$10,Leaderboard!I$2:I$10),$A$23:$A$31,$B$23:$B$31)+F7 -> #N/A | H7: =_xlfn.XLOOKUP(_xlfn.XLOOKUP($B7,Leaderboard!$D$2:$D$10,Leaderboard!L$2:L$10),$A$23:$A$31,$B$23:$B$31)+G7 -> #N/A | I7: =_xlfn.XLOOKUP(_xlfn.XLOOKUP($B7,Leaderboard!$D$2:$D$10,Leaderboard!R$2:R$10),$A$23:$A$31,$B$23:$B$31)+H7 -> #N/A
A8: 4090904076 | B8: Maher, Joel | C8: Joel | D8: 16 | E8: =D8 -> 16 | F8: =_xlfn.XLOOKUP(_xlfn.XLOOKUP($B8,Leaderboard!$D$2:$D$10,Leaderboard!F$2:F$10),$A$23:$A$31,$B$23:$B$31)+E8 -> #N/A | G8: =_xlfn.XLOOKUP(_xlfn.XLOOKUP($B8,Leaderboard!$D$2:$D$10,Leaderboard!I$2:I$10),$A$23:$A$31,$B$23:$B$31)+F8 -> #N/A | H8: =_xlfn.XLOOKUP(_xlfn.XLOOKUP($B8,Leaderboard!$D$2:$D$10,Leaderboard!L$2:L$10),$A$23:$A$31,$B$23:$B$31)+G8 -> #N/A | I8: =_xlfn.XLOOKUP(_xlfn.XLOOKUP($B8,Leaderboard!$D$2:$D$10,Leaderboard!R$2:R$10),$A$23:$A$31,$B$23:$B$31)+H8 -> #N/A
A9: 4090905296 | B9: Marshall, Jayme | C9: Jamy | D9: 27 | E9: =D9 -> 27 | F9: =_xlfn.XLOOKUP(_xlfn.XLOOKUP($B9,Leaderboard!$D$2:$D$10,Leaderboard!F$2:F$10),$A$23:$A$31,$B$23:$B$31)+E9 -> #N/A | G9: =_xlfn.XLOOKUP(_xlfn.XLOOKUP($B9,Leaderboard!$D$2:$D$10,Leaderboard!I$2:I$10),$A$23:$A$31,$B$23:$B$31)+F9 -> #N/A | H9: =_xlfn.XLOOKUP(_xlfn.XLOOKUP($B9,Leaderboard!$D$2:$D$10,Leaderboard!L$2:L$10),$A$23:$A$31,$B$23:$B$31)+G9 -> #N/A | I9: =_xlfn.XLOOKUP(_xlfn.XLOOKUP($B9,Leaderboard!$D$2:$D$10,Leaderboard!R$2:R$10),$A$23:$A$31,$B$23:$B$31)+H9 -> #N/A
A10: 4090900096 | B10: McDowell, Steve | C10: Steve | D10: 12 | E10: =D10 -> 12 | F10: =_xlfn.XLOOKUP(_xlfn.XLOOKUP($B10,Leaderboard!$D$2:$D$10,Leaderboard!F$2:F$10),$A$23:$A$31,$B$23:$B$31)+E10 -> #N/A | G10: =_xlfn.XLOOKUP(_xlfn.XLOOKUP($B10,Leaderboard!$D$2:$D$10,Leaderboard!I$2:I$10),$A$23:$A$31,$B$23:$B$31)+F10 -> #N/A | H10: =_xlfn.XLOOKUP(_xlfn.XLOOKUP($B10,Leaderboard!$D$2:$D$10,Leaderboard!L$2:L$10),$A$23:$A$31,$B$23:$B$31)+G10 -> #N/A | I10: =_xlfn.XLOOKUP(_xlfn.XLOOKUP($B10,Leaderboard!$D$2:$D$10,Leaderboard!R$2:R$10),$A$23:$A$31,$B$23:$B$31)+H10 -> #N/A
A11: 4090904495 | B11: McEwan, Paul | C11: Wormy | D11: 21 | E11: =D11 -> 21 | F11: =_xlfn.XLOOKUP(_xlfn.XLOOKUP($B11,Leaderboard!$D$2:$D$10,Leaderboard!F$2:F$10),$A$23:$A$31,$B$23:$B$31)+E11 -> #N/A | G11: =_xlfn.XLOOKUP(_xlfn.XLOOKUP($B11,Leaderboard!$D$2:$D$10,Leaderboard!I$2:I$10),$A$23:$A$31,$B$23:$B$31)+F11 -> #N/A | H11: =_xlfn.XLOOKUP(_xlfn.XLOOKUP($B11,Leaderboard!$D$2:$D$10,Leaderboard!L$2:L$10),$A$23:$A$31,$B$23:$B$31)+G11 -> #N/A | I11: =_xlfn.XLOOKUP(_xlfn.XLOOKUP($B11,Leaderboard!$D$2:$D$10,Leaderboard!R$2:R$10),$A$23:$A$31,$B$23:$B$31)+H11 -> #N/A
A12: 4090903571 | B12: O'Callaghan. Joc | C12: Joc | D12: 14 | E12: =D12 -> 14 | F12: =_xlfn.XLOOKUP(_xlfn.XLOOKUP($B12,Leaderboard!$D$2:$D$10,Leaderboard!F$2:F$10),$A$23:$A$31,$B$23:$B$31)+E12 -> #N/A | G12: =_xlfn.XLOOKUP(_xlfn.XLOOKUP($B12,Leaderboard!$D$2:$D$10,Leaderboard!I$2:I$10),$A$23:$A$31,$B$23:$B$31)+F12 -> #N/A | H12: =_xlfn.XLOOKUP(_xlfn.XLOOKUP($B12,Leaderboard!$D$2:$D$10,Leaderboard!L$2:L$10),$A$23:$A$31,$B$23:$B$31)+G12 -> #N/A | I12: =_xlfn.XLOOKUP(_xlfn.XLOOKUP($B12,Leaderboard!$D$2:$D$10,Leaderboard!R$2:R$10),$A$23:$A$31,$B$23:$B$31)+H12 -> #N/A
A13: 4090901889 | B13: Perre, Anthony | C13: PB | D13: 6 | E13: =D13 -> 6 | F13: =_xlfn.XLOOKUP(_xlfn.XLOOKUP($B13,Leaderboard!$D$2:$D$10,Leaderboard!F$2:F$10),$A$23:$A$31,$B$23:$B$31)+E13 -> #N/A | G13: =_xlfn.XLOOKUP(_xlfn.XLOOKUP($B13,Leaderboard!$D$2:$D$10,Leaderboard!I$2:I$10),$A$23:$A$31,$B$23:$B$31)+F13 -> #N/A | H13: =_xlfn.XLOOKUP(_xlfn.XLOOKUP($B13,Leaderboard!$D$2:$D$10,Leaderboard!L$2:L$10),$A$23:$A$31,$B$23:$B$31)+G13 -> #N/A | I13: =_xlfn.XLOOKUP(_xlfn.XLOOKUP($B13,Leaderboard!$D$2:$D$10,Leaderboard!R$2:R$10),$A$23:$A$31,$B$23:$B$31)+H13 -> #N/A
A14: 4090901143 | B14: Rettke, Butch | C14: Butcher | D14: 18 | E14: =D14 -> 18 | F14: =_xlfn.XLOOKUP(_xlfn.XLOOKUP($B14,Leaderboard!$D$2:$D$10,Leaderboard!F$2:F$10),$A$23:$A$31,$B$23:$B$31)+E14 -> #N/A | G14: =_xlfn.XLOOKUP(_xlfn.XLOOKUP($B14,Leaderboard!$D$2:$D$10,Leaderboard!I$2:I$10),$A$23:$A$31,$B$23:$B$31)+F14 -> #N/A | H14: =_xlfn.XLOOKUP(_xlfn.XLOOKUP($B14,Leaderboard!$D$2:$D$10,Leaderboard!L$2:L$10),$A$23:$A$31,$B$23:$B$31)+G14 -> #N/A | I14: =_xlfn.XLOOKUP(_xlfn.XLOOKUP($B14,Leaderboard!$D$2:$D$10,Leaderboard!R$2:R$10),$A$23:$A$31,$B$23:$B$31)+H14 -> #N/A
... A18: 4090904680 | B18: Zillfleisch, David | C18: Zilly | D18: 8 | E18: =D18 -> 8 | F18: =_xlfn.XLOOKUP(_xlfn.XLOOKUP($B18,Leaderboard!$D$2:$D$10,Leaderboard!F$2:F$10),$A$23:$A$31,$B$23:$B$31)+E18 -> #N/A | G18: =_xlfn.XLOOKUP(_xlfn.XLOOKUP($B18,Leaderboard!$D$2:$D$10,Leaderboard!I$2:I$10),$A$23:$A$31,$B$23:$B$31)+F18 -> #N/A | H18: =_xlfn.XLOOKUP(_xlfn.XLOOKUP($B18,Leaderboard!$D$2:$D$10,Leaderboard!L$2:L$10),$A$23:$A$31,$B$23:$B$31)+G18 -> #N/A | I18: =_xlfn.XLOOKUP(_xlfn.XLOOKUP($B18,Leaderboard!$D$2:$D$10,Leaderboard!R$2:R$10),$A$23:$A$31,$B$23:$B$31)+H18 -> #N/A
A21: Daily Handicap Adjustment
A22: Position | B22: Amount
A23: 1 | B23: -2
A24: 2 | B24: -1.75
A25: 3 | B25: -1.5
A26: 4 | B26: -1.25
A27: 5 | B27: -1
A28: 6 | B28: -0.75
A29: 7 | B29: -0.5
A30: 8 | B30: -0.25
A31: 9 | B31: 0.25
A32: 10 | B32: 0.5
A33: 11 | B33: 0.75
A34: 12 | B34: 1
... A38: 16 | B38: 2

Sheet Daily Scoring
E1: 1 | G1: =E1+1 -> 2 | I1: =G1+1 -> 3 | K1: =I1+1 -> 4 | M1: =K1+1 -> 5 | O1: =M1+1 -> 6 | Q1: =O1+1 -> 7 | S1: =Q1+1 -> 8 | U1: =S1+1 -> 9 | W1: 1 | Y1: =W1+1 -> 2 | AA1: =Y1+1 -> 3 | AC1: =AA1+1 -> 4 | AE1: =AC1+1 -> 5 | AG1: =AE1+1 -> 6 | AI1: =AG1+1 -> 7 | AP1: 1 | AR1: =AP1+1 -> 2 | AT1: =AR1+1 -> 3 | AV1: =AT1+1 -> 4 | AX1: =AV1+1 -> 5 | AZ1: =AX1+1 -> 6 | BB1: =AZ1+1 -> 7 | BD1: =BB1+1 -> 8 | BF1: =BD1+1 -> 9 | BH1: 1 | BJ1: =BH1+1 -> 2 | BL1: =BJ1+1 -> 3 | BN1: =BL1+1 -> 4 | BP1: =BN1+1 -> 5 | BR1: =BP1+1 -> 6 | BT1: =BR1+1 -> 7 | CA1: 1 | CC1: =CA1+1 -> 2 | CE1: =CC1+1 -> 3 | CG1: =CE1+1 -> 4 | CI1: =CG1+1 -> 5 | CK1: =CI1+1 -> 6 | CM1: =CK1+1 -> 7 | CO1: =CM1+1 -> 8 | CQ1: =CO1+1 -> 9 | CS1: 1 | CU1: =CS1+1 -> 2 | CW1: =CU1+1 -> 3 | CY1: =CW1+1 -> 4 | DA1: =CY1+1 -> 5 | DC1: =DA1+1 -> 6 | DE1: =DC1+1 -> 7 | DL1: 1 | DN1: =DL1+1 -> 2 | DP1: =DN1+1 -> 3 | DR1: =DP1+1 -> 4 | DT1: =DR1+1 -> 5 | DV1: =DT1+1 -> 6 | DX1: =DV1+1 -> 7 | DZ1: =DX1+1 -> 8 | EB1: =DZ1+1 -> 9 | ED1: 1 | EF1: =ED1+1 -> 2 | EH1: =EF1+1 -> 3 | EJ1: =EH1+1 -> 4 | EL1: =EJ1+1 -> 5 | EN1: =EL1+1 -> 6 | EP1: =EN1+1 -> 7 | EW1: 1 | EY1: =EW1+1 -> 2 | FA1: =EY1+1 -> 3 | FC1: =FA1+1 -> 4 | FE1: =FC1+1 -> 5 | FG1: =FE1+1 -> 6 | FI1: =FG1+1 -> 7 | FK1: =FI1+1 -> 8 | FM1: =FK1+1 -> 9 | FO1: 1 | FQ1: =FO1+1 -> 2 | FS1: =FQ1+1 -> 3 | FU1: =FS1+1 -> 4 | FW1: =FU1+1 -> 5 | FY1: =FW1+1 -> 6 | GA1: =FY1+1 -> 7
A2: Eagle Ridge Golf Course | AL2: Moonah Links - Open Course | BW2: Monrington Golf Club | DH2: The Dunes Golf Links | ES2: St Andrew Beach Golf Course
A3: 1 | B3: Par | C3: SI | E3: Attiwill, Scott | F3: Result | G3: {=OFFSET(Handicapping!$B$2,G$1,,)} -> Hoy, John | H3: Result | I3: {=OFFSET(Handicapping!$B$2,I$1,,)} -> Ireland, Kev | J3: Result | K3: {=OFFSET(Handicapping!$B$2,K$1,,)} -> Lay, Greg | L3: Result | M3: {=OFFSET(Handicapping!$B$2,M$1,,)} -> Leeson, Chris | N3: Result | O3: {=OFFSET(Handicapping!$B$2,O$1,,)} -> Maher, Joel | P3: Result | Q3: {=OFFSET(Handicapping!$B$2,Q$1,,)} -> Marshall, Jayme | R3: Result | S3: {=OFFSET(Handicapping!$B$2,S$1,,)} -> McDowell, Steve | T3: Result | U3: {=OFFSET(Handicapping!$B$2,U$1,,)} -> McEwan, Paul | V3: Result | W3: O'Callaghan. Joc | X3: Result | Y3: Perre, Anthony | Z3: Result | AA3: Rettke, Butch | AB3: Result | AC3: Royan, Damien | AD3: Result | AE3: Tompkins, Lawrie | AF3: Result | AG3: Wesche, Gavin | AH3: Result | AI3: Zillfleisch, David | AJ3: Result | AL3: 1 | AM3: Par | AN3: SI | AP3: Attiwill, Scott | AQ3: Result | AR3: {=OFFSET(Handicapping!$B$2,AR$1,,)} -> Hoy, John | AS3: Result | AT3: {=OFFSET(Handicapping!$B$2,AT$1,,)} -> Ireland, Kev | AU3: Result | AV3: {=OFFSET(Handicapping!$B$2,AV$1,,)} -> Lay, Greg | AW3: Result | AX3: {=OFFSET(Handicapping!$B$2,AX$1,,)} -> Leeson, Chris | AY3: Result | AZ3: {=OFFSET(Handicapping!$B$2,AZ$1,,)} -> Maher, Joel | BA3: Result | BB3: {=OFFSET(Handicapping!$B$2,BB$1,,)} -> Marshall, Jayme | BC3: Result | BD3: {=OFFSET(Handicapping!$B$2,BD$1,,)} -> McDowell, Steve | BE3: Result | BF3: {=OFFSET(Handicapping!$B$2,BF$1,,)} -> McEwan, Paul | BG3: Result | BH3: O'Callaghan. Joc | BI3: Result | BJ3: Perre, Anthony | BK3: Result | BL3: Rettke, Butch | BM3: Result | BN3: Royan, Damien | BO3: Result | BP3: Tompkins, Lawrie | BQ3: Result | BR3: Wesche, Gavin | BS3: Result | BT3: Zillfleisch, David | BU3: Result | BW3: 1 | BX3: Par | BY3: SI | CA3: Attiwill, Scott | CB3: Result | CC3: {=OFFSET(Handicapping!$B$2,CC$1,,)} -> Hoy, John | CD3: Result | CE3: {=OFFSET(Handicapping!$B$2,CE$1,,)} -> Ireland, Kev | CF3: Result | CG3: {=OFFSET(Handicapping!$B$2,CG$1,,)} -> Lay, Greg | CH3: Result | CI3: {=OFFSET(Handicapping!$B$2,CI$1,,)} -> Leeson, Chris | CJ3: Result | CK3: {=OFFSET(Handicapping!$B$2,CK$1,,)} -> Maher, Joel | CL3: Result | CM3: {=OFFSET(Handicapping!$B$2,CM$1,,)} -> Marshall, Jayme | CN3: Result | CO3: {=OFFSET(Handicapping!$B$2,CO$1,,)} -> McDowell, Steve | CP3: Result | CQ3: {=OFFSET(Handicapping!$B$2,CQ$1,,)} -> McEwan, Paul | CR3: Result | CS3: O'Callaghan. Joc | CT3: Result | CU3: Perre, Anthony | CV3: Result | CW3: Rettke, Butch | CX3: Result | CY3: Royan, Damien | CZ3: Result | DA3: Tompkins, Lawrie | DB3: Result | DC3: Wesche, Gavin | DD3: Result | DE3: Zillfleisch, David | DF3: Result | DH3: 1 | DI3: Par | DJ3: SI | DL3: Attiwill, Scott | DM3: Result | DN3: {=OFFSET(Handicapping!$B$2,DN$1,,)} -> Hoy, John | DO3: Result | DP3: {=OFFSET(Handicapping!$B$2,DP$1,,)} -> Ireland, Kev | DQ3: Result | DR3: {=OFFSET(Handicapping!$B$2,DR$1,,)} -> Lay, Greg | DS3: Result | DT3: {=OFFSET(Handicapping!$B$2,DT$1,,)} -> Leeson, Chris | DU3: Result | DV3: {=OFFSET(Handicapping!$B$2,DV$1,,)} -> Maher, Joel | DW3: Result | DX3: {=OFFSET(Handicapping!$B$2,DX$1,,)} -> Marshall, Jayme | DY3: Result | DZ3: {=OFFSET(Handicapping!$B$2,DZ$1,,)} -> McDowell, Steve | EA3: Result | EB3: {=OFFSET(Handicapping!$B$2,EB$1,,)} -> McEwan, Paul | EC3: Result | ED3: O'Callaghan. Joc | EE3: Result | EF3: Perre, Anthony | EG3: Result | EH3: Rettke, Butch | EI3: Result | EJ3: Royan, Damien | EK3: Result | EL3: Tompkins, Lawrie | EM3: Result | EN3: Wesche, Gavin | EO3: Result | EP3: Zillfleisch, David | EQ3: Result | ES3: 1 | ET3: Par | EU3: SI | EW3: Attiwill, Scott | EX3: Result | EY3: {=OFFSET(Handicapping!$B$2,EY$1,,)} -> Hoy, John | EZ3: Result | FA3: {=OFFSET(Handicapping!$B$2,FA$1,,)} -> Ireland, Kev | FB3: Result | FC3: {=OFFSET(Handicapping!$B$2,FC$1,,)} -> Lay, Greg | FD3: Result | FE3: {=OFFSET(Handicapping!$B$2,FE$1,,)} -> Leeson, Chris | FF3: Result | FG3: {=OFFSET(Handicapping!$B$2,FG$1,,)} -> Maher, Joel | FH3: Result | FI3: {=OFFSET(Handicapping!$B$2,FI$1,,)} -> Marshall, Jayme | FJ3: Result | FK3: {=OFFSET(Handicapping!$B$2,FK$1,,)} -> McDowell, Steve | FL3: Result | FM3: {=OFFSET(Handicapping!$B$2,FM$1,,)} -> McEwan, Paul | FN3: Result | FO3: O'Callaghan. Joc | FP3: Result | FQ3: Perre, Anthony | FR3: Result | FS3: Rettke, Butch | FT3: Result | FU3: Royan, Damien | FV3: Result | FW3: Tompkins, Lawrie | FX3: Result | FY3: Wesche, Gavin | FZ3: Result | GA3: Zillfleisch, David | GB3: Result
A4: Daily H'Cap | E4: =ROUND(_xlfn.XLOOKUP(E3,Handicapping!$B$3:$B$18,Handicapping!$E$3:$E$18),0) -> 14 | G4: =ROUND(_xlfn.XLOOKUP(G3,Handicapping!$B$3:$B$18,Handicapping!$E$3:$E$18),0) -> 8 | I4: =ROUND(_xlfn.XLOOKUP(I3,Handicapping!$B$3:$B$18,Handicapping!$E$3:$E$18),0) -> 12 | K4: =ROUND(_xlfn.XLOOKUP(K3,Handicapping!$B$3:$B$18,Handicapping!$E$3:$E$18),0) -> 12 | M4: =ROUND(_xlfn.XLOOKUP(M3,Handicapping!$B$3:$B$18,Handicapping!$E$3:$E$18),0) -> 25 | O4: =ROUND(_xlfn.XLOOKUP(O3,Handicapping!$B$3:$B$18,Handicapping!$E$3:$E$18),0) -> 16 | Q4: =ROUND(_xlfn.XLOOKUP(Q3,Handicapping!$B$3:$B$18,Handicapping!$E$3:$E$18),0) -> 27 | S4: =ROUND(_xlfn.XLOOKUP(S3,Handicapping!$B$3:$B$18,Handicapping!$E$3:$E$18),0) -> 12 | U4: =ROUND(_xlfn.XLOOKUP(U3,Handicapping!$B$3:$B$18,Handicapping!$E$3:$E$18),0) -> 21 | W4: =ROUND(_xlfn.XLOOKUP(W3,Handicapping!$B$3:$B$18,Handicapping!$E$3:$E$18),0) -> 14 | Y4: =ROUND(_xlfn.XLOOKUP(Y3,Handicapping!$B$3:$B$18,Handicapping!$E$3:$E$18),0) -> 6 | AA4: =ROUND(_xlfn.XLOOKUP(AA3,Handicapping!$B$3:$B$18,Handicapping!$E$3:$E$18),0) -> 18 | AC4: =ROUND(_xlfn.XLOOKUP(AC3,Handicapping!$B$3:$B$18,Handicapping!$E$3:$E$18),0) -> 8 | AE4: =ROUND(_xlfn.XLOOKUP(AE3,Handicapping!$B$3:$B$18,Handicapping!$E$3:$E$18),0) -> 15 | AG4: =ROUND(_xlfn.XLOOKUP(AG3,Handicapping!$B$3:$B$18,Handicapping!$E$3:$E$18),0) -> 8 | AI4: =ROUND(_xlfn.XLOOKUP(AI3,Handicapping!$B$3:$B$18,Handicapping!$E$3:$E$18),0) -> 8 | AL4: Daily H'Cap | AP4: =ROUND(_xlfn.XLOOKUP(AP3,Handicapping!$B$3:$B$18,Handicapping!$E$3:$E$18),0) -> 14 | AR4: =ROUND(_xlfn.XLOOKUP(AR3,Handicapping!$B$3:$B$18,Handicapping!$E$3:$E$18),0) -> 8 | AT4: =ROUND(_xlfn.XLOOKUP(AT3,Handicapping!$B$3:$B$18,Handicapping!$E$3:$E$18),0) -> 12 | AV4: =ROUND(_xlfn.XLOOKUP(AV3,Handicapping!$B$3:$B$18,Handicapping!$E$3:$E$18),0) -> 12 | AX4: =ROUND(_xlfn.XLOOKUP(AX3,Handicapping!$B$3:$B$18,Handicapping!$E$3:$E$18),0) -> 25 | AZ4: =ROUND(_xlfn.XLOOKUP(AZ3,Handicapping!$B$3:$B$18,Handicapping!$E$3:$E$18),0) -> 16 | BB4: =ROUND(_xlfn.XLOOKUP(BB3,Handicapping!$B$3:$B$18,Handicapping!$E$3:$E$18),0) -> 27 | BD4: =ROUND(_xlfn.XLOOKUP(BD3,Handicapping!$B$3:$B$18,Handicapping!$E$3:$E$18),0) -> 12 | BF4: =ROUND(_xlfn.XLOOKUP(BF3,Handicapping!$B$3:$B$18,Handicapping!$E$3:$E$18),0) -> 21 | BH4: =ROUND(_xlfn.XLOOKUP(BH3,Handicapping!$B$3:$B$18,Handicapping!$E$3:$E$18),0) -> 14 | BJ4: =ROUND(_xlfn.XLOOKUP(BJ3,Handicapping!$B$3:$B$18,Handicapping!$E$3:$E$18),0) -> 6 | BL4: =ROUND(_xlfn.XLOOKUP(BL3,Handicapping!$B$3:$B$18,Handicapping!$E$3:$E$18),0) -> 18 | BN4: =ROUND(_xlfn.XLOOKUP(BN3,Handicapping!$B$3:$B$18,Handicapping!$E$3:$E$18),0) -> 8 | BP4: =ROUND(_xlfn.XLOOKUP(BP3,Handicapping!$B$3:$B$18,Handicapping!$E$3:$E$18),0) -> 15 | BR4: =ROUND(_xlfn.XLOOKUP(BR3,Handicapping!$B$3:$B$18,Handicapping!$E$3:$E$18),0) -> 8 | BT4: =ROUND(_xlfn.XLOOKUP(BT3,Handicapping!$B$3:$B$18,Handicapping!$E$3:$E$18),0) -> 8 | BW4: Daily H'Cap | CA4: =ROUND(_xlfn.XLOOKUP(CA3,Handicapping!$B$3:$B$18,Handicapping!$E$3:$E$18),0) -> 14 | CC4: =ROUND(_xlfn.XLOOKUP(CC3,Handicapping!$B$3:$B$18,Handicapping!$E$3:$E$18),0) -> 8 | CE4: =ROUND(_xlfn.XLOOKUP(CE3,Handicapping!$B$3:$B$18,Handicapping!$E$3:$E$18),0) -> 12 | CG4: =ROUND(_xlfn.XLOOKUP(CG3,Handicapping!$B$3:$B$18,Handicapping!$E$3:$E$18),0) -> 12 | CI4: =ROUND(_xlfn.XLOOKUP(CI3,Handicapping!$B$3:$B$18,Handicapping!$E$3:$E$18),0) -> 25 | CK4: =ROUND(_xlfn.XLOOKUP(CK3,Handicapping!$B$3:$B$18,Handicapping!$E$3:$E$18),0) -> 16 | CM4: =ROUND(_xlfn.XLOOKUP(CM3,Handicapping!$B$3:$B$18,Handicapping!$E$3:$E$18),0) -> 27 | CO4: =ROUND(_xlfn.XLOOKUP(CO3,Handicapping!$B$3:$B$18,Handicapping!$E$3:$E$18),0) -> 12 | CQ4: =ROUND(_xlfn.XLOOKUP(CQ3,Handicapping!$B$3:$B$18,Handicapping!$E$3:$E$18),0) -> 21 | CS4: =ROUND(_xlfn.XLOOKUP(CS3,Handicapping!$B$3:$B$18,Handicapping!$E$3:$E$18),0) -> 14 | CU4: =ROUND(_xlfn.XLOOKUP(CU3,Handicapping!$B$3:$B$18,Handicapping!$E$3:$E$18),0) -> 6 | CW4: =ROUND(_xlfn.XLOOKUP(CW3,Handicapping!$B$3:$B$18,Handicapping!$E$3:$E$18),0) -> 18 | CY4: =ROUND(_xlfn.XLOOKUP(CY3,Handicapping!$B$3:$B$18,Handicapping!$E$3:$E$18),0) -> 8 | DA4: =ROUND(_xlfn.XLOOKUP(DA3,Handicapping!$B$3:$B$18,Handicapping!$E$3:$E$18),0) -> 15 | DC4: =ROUND(_xlfn.XLOOKUP(DC3,Handicapping!$B$3:$B$18,Handicapping!$E$3:$E$18),0) -> 8 | DE4: =ROUND(_xlfn.XLOOKUP(DE3,Handicapping!$B$3:$B$18,Handicapping!$E$3:$E$18),0) -> 8 | DH4: Daily H'Cap | DL4: =ROUND(_xlfn.XLOOKUP(DL3,Handicapping!$B$3:$B$18,Handicapping!$E$3:$E$18),0) -> 14 | DN4: =ROUND(_xlfn.XLOOKUP(DN3,Handicapping!$B$3:$B$18,Handicapping!$E$3:$E$18),0) -> 8 | DP4: =ROUND(_xlfn.XLOOKUP(DP3,Handicapping!$B$3:$B$18,Handicapping!$E$3:$E$18),0) -> 12 | DR4: =ROUND(_xlfn.XLOOKUP(DR3,Handicapping!$B$3:$B$18,Handicapping!$E$3:$E$18),0) -> 12 | DT4: =ROUND(_xlfn.XLOOKUP(DT3,Handicapping!$B$3:$B$18,Handicapping!$E$3:$E$18),0) -> 25 | DV4: =ROUND(_xlfn.XLOOKUP(DV3,Handicapping!$B$3:$B$18,Handicapping!$E$3:$E$18),0) -> 16 | DX4: =ROUND(_xlfn.XLOOKUP(DX3,Handicapping!$B$3:$B$18,Handicapping!$E$3:$E$18),0) -> 27 | DZ4: =ROUND(_xlfn.XLOOKUP(DZ3,Handicapping!$B$3:$B$18,Handicapping!$E$3:$E$18),0) -> 12 | EB4: =ROUND(_xlfn.XLOOKUP(EB3,Handicapping!$B$3:$B$18,Handicapping!$E$3:$E$18),0) -> 21 | ED4: =ROUND(_xlfn.XLOOKUP(ED3,Handicapping!$B$3:$B$18,Handicapping!$E$3:$E$18),0) -> 14 | EF4: =ROUND(_xlfn.XLOOKUP(EF3,Handicapping!$B$3:$B$18,Handicapping!$E$3:$E$18),0) -> 6 | EH4: =ROUND(_xlfn.XLOOKUP(EH3,Handicapping!$B$3:$B$18,Handicapping!$E$3:$E$18),0) -> 18 | EJ4: =ROUND(_xlfn.XLOOKUP(EJ3,Handicapping!$B$3:$B$18,Handicapping!$E$3:$E$18),0) -> 8 | EL4: =ROUND(_xlfn.XLOOKUP(EL3,Handicapping!$B$3:$B$18,Handicapping!$E$3:$E$18),0) -> 15 | EN4: =ROUND(_xlfn.XLOOKUP(EN3,Handicapping!$B$3:$B$18,Handicapping!$E$3:$E$18),0) -> 8 | EP4: =ROUND(_xlfn.XLOOKUP(EP3,Handicapping!$B$3:$B$18,Handicapping!$E$3:$E$18),0) -> 8 | ES4: Daily H'Cap | EW4: =ROUND(_xlfn.XLOOKUP(EW3,Handicapping!$B$3:$B$18,Handicapping!$E$3:$E$18),0) -> 14 | EY4: =ROUND(_xlfn.XLOOKUP(EY3,Handicapping!$B$3:$B$18,Handicapping!$E$3:$E$18),0) -> 8 | FA4: =ROUND(_xlfn.XLOOKUP(FA3,Handicapping!$B$3:$B$18,Handicapping!$E$3:$E$18),0) -> 12 | FC4: =ROUND(_xlfn.XLOOKUP(FC3,Handicapping!$B$3:$B$18,Handicapping!$E$3:$E$18),0) -> 12 | FE4: =ROUND(_xlfn.XLOOKUP(FE3,Handicapping!$B$3:$B$18,Handicapping!$E$3:$E$18),0) -> 25 | FG4: =ROUND(_xlfn.XLOOKUP(FG3,Handicapping!$B$3:$B$18,Handicapping!$E$3:$E$18),0) -> 16 | FI4: =ROUND(_xlfn.XLOOKUP(FI3,Handicapping!$B$3:$B$18,Handicapping!$E$3:$E$18),0) -> 27 | FK4: =ROUND(_xlfn.XLOOKUP(FK3,Handicapping!$B$3:$B$18,Handicapping!$E$3:$E$18),0) -> 12 | FM4: =ROUND(_xlfn.XLOOKUP(FM3,Handicapping!$B$3:$B$18,Handicapping!$E$3:$E$18),0) -> 21 | FO4: =ROUND(_xlfn.XLOOKUP(FO3,Handicapping!$B$3:$B$18,Handicapping!$E$3:$E$18),0) -> 14 | FQ4: =ROUND(_xlfn.XLOOKUP(FQ3,Handicapping!$B$3:$B$18,Handicapping!$E$3:$E$18),0) -> 6 | FS4: =ROUND(_xlfn.XLOOKUP(FS3,Handicapping!$B$3:$B$18,Handicapping!$E$3:$E$18),0) -> 18 | FU4: =ROUND(_xlfn.XLOOKUP(FU3,Handicapping!$B$3:$B$18,Handicapping!$E$3:$E$18),0) -> 8 | FW4: =ROUND(_xlfn.XLOOKUP(FW3,Handicapping!$B$3:$B$18,Handicapping!$E$3:$E$18),0) -> 15 | FY4: =ROUND(_xlfn.XLOOKUP(FY3,Handicapping!$B$3:$B$18,Handicapping!$E$3:$E$18),0) -> 8 | GA4: =ROUND(_xlfn.XLOOKUP(GA3,Handicapping!$B$3:$B$18,Handicapping!$E$3:$E$18),0) -> 8
A5: 1 | B5: 4 | C5: 16 | D5: =C5+18 -> 34 | F5: =IF(E5=0,0,MAX(0,IF(E$4>18,IF($D5<=E$4,2,1),IF($C5<=E$4,1,0))-E5+$B5+2)) -> 0 | H5: =IF(G5=0,0,MAX(0,IF(G$4>18,IF($D5<=G$4,2,1),IF($C5<=G$4,1,0))-G5+$B5+2)) -> 0 | J5: =IF(I5=0,0,MAX(0,IF(I$4>18,IF($D5<=I$4,2,1),IF($C5<=I$4,1,0))-I5+$B5+2)) -> 0 | L5: =IF(K5=0,0,MAX(0,IF(K$4>18,IF($D5<=K$4,2,1),IF($C5<=K$4,1,0))-K5+$B5+2)) -> 0 | N5: =IF(M5=0,0,MAX(0,IF(M$4>18,IF($D5<=M$4,2,1),IF($C5<=M$4,1,0))-M5+$B5+2)) -> 0 | P5: =IF(O5=0,0,MAX(0,IF(O$4>18,IF($D5<=O$4,2,1),IF($C5<=O$4,1,0))-O5+$B5+2)) -> 0 | R5: =IF(Q5=0,0,MAX(0,IF(Q$4>18,IF($D5<=Q$4,2,1),IF($C5<=Q$4,1,0))-Q5+$B5+2)) -> 0 | T5: =IF(S5=0,0,MAX(0,IF(S$4>18,IF($D5<=S$4,2,1),IF($C5<=S$4,1,0))-S5+$B5+2)) -> 0 | V5: =IF(U5=0,0,MAX(0,IF(U$4>18,IF($D5<=U$4,2,1),IF($C5<=U$4,1,0))-U5+$B5+2)) -> 0 | X5: =IF(W5=0,0,MAX(0,IF(W$4>18,IF($D5<=W$4,2,1),IF($C5<=W$4,1,0))-W5+$B5+2)) -> 0 | Z5: =IF(Y5=0,0,MAX(0,IF(Y$4>18,IF($D5<=Y$4,2,1),IF($C5<=Y$4,1,0))-Y5+$B5+2)) -> 0 | AB5: =IF(AA5=0,0,MAX(0,IF(AA$4>18,IF($D5<=AA$4,2,1),IF($C5<=AA$4,1,0))-AA5+$B5+2)) -> 0 | AD5: =IF(AC5=0,0,MAX(0,IF(AC$4>18,IF($D5<=AC$4,2,1),IF($C5<=AC$4,1,0))-AC5+$B5+2)) -> 0 | AF5: =IF(AE5=0,0,MAX(0,IF(AE$4>18,IF($D5<=AE$4,2,1),IF($C5<=AE$4,1,0))-AE5+$B5+2)) -> 0 | AH5: =IF(AG5=0,0,MAX(0,IF(AG$4>18,IF($D5<=AG$4,2,1),IF($C5<=AG$4,1,0))-AG5+$B5+2)) -> 0 | AJ5: =IF(AI5=0,0,MAX(0,IF(AI$4>18,IF($D5<=AI$4,2,1),IF($C5<=AI$4,1,0))-AI5+$B5+2)) -> 0 | AL5: 1 | AM5: 4 | AN5: 16 | AO5: =AN5+18 -> 34 | AQ5: =IF(AP5=0,0,MAX(0,IF(AP$4>18,IF($D5<=AP$4,2,1),IF($C5<=AP$4,1,0))-AP5+$B5+2)) -> 0 | AS5: =IF(AR5=0,0,MAX(0,IF(AR$4>18,IF($D5<=AR$4,2,1),IF($C5<=AR$4,1,0))-AR5+$B5+2)) -> 0 | AU5: =IF(AT5=0,0,MAX(0,IF(AT$4>18,IF($D5<=AT$4,2,1),IF($C5<=AT$4,1,0))-AT5+$B5+2)) -> 0 | AW5: =IF(AV5=0,0,MAX(0,IF(AV$4>18,IF($D5<=AV$4,2,1),IF($C5<=AV$4,1,0))-AV5+$B5+2)) -> 0 | AY5: =IF(AX5=0,0,MAX(0,IF(AX$4>18,IF($D5<=AX$4,2,1),IF($C5<=AX$4,1,0))-AX5+$B5+2)) -> 0 | BA5: =IF(AZ5=0,0,MAX(0,IF(AZ$4>18,IF($D5<=AZ$4,2,1),IF($C5<=AZ$4,1,0))-AZ5+$B5+2)) -> 0 | BC5: =IF(BB5=0,0,MAX(0,IF(BB$4>18,IF($D5<=BB$4,2,1),IF($C5<=BB$4,1,0))-BB5+$B5+2)) -> 0 | BE5: =IF(BD5=0,0,MAX(0,IF(BD$4>18,IF($D5<=BD$4,2,1),IF($C5<=BD$4,1,0))-BD5+$B5+2)) -> 0 | BG5: =IF(BF5=0,0,MAX(0,IF(BF$4>18,IF($D5<=BF$4,2,1),IF($C5<=BF$4,1,0))-BF5+$B5+2)) -> 0 | BI5: =IF(BH5=0,0,MAX(0,IF(BH$4>18,IF($D5<=BH$4,2,1),IF($C5<=BH$4,1,0))-BH5+$B5+2)) -> 0 | BK5: =IF(BJ5=0,0,MAX(0,IF(BJ$4>18,IF($D5<=BJ$4,2,1),IF($C5<=BJ$4,1,0))-BJ5+$B5+2)) -> 0 | BM5: =IF(BL5=0,0,MAX(0,IF(BL$4>18,IF($D5<=BL$4,2,1),IF($C5<=BL$4,1,0))-BL5+$B5+2)) -> 0 | BO5: =IF(BN5=0,0,MAX(0,IF(BN$4>18,IF($D5<=BN$4,2,1),IF($C5<=BN$4,1,0))-BN5+$B5+2)) -> 0 | BQ5: =IF(BP5=0,0,MAX(0,IF(BP$4>18,IF($D5<=BP$4,2,1),IF($C5<=BP$4,1,0))-BP5+$B5+2)) -> 0 | BS5: =IF(BR5=0,0,MAX(0,IF(BR$4>18,IF($D5<=BR$4,2,1),IF($C5<=BR$4,1,0))-BR5+$B5+2)) -> 0 | BU5: =IF(BT5=0,0,MAX(0,IF(BT$4>18,IF($D5<=BT$4,2,1),IF($C5<=BT$4,1,0))-BT5+$B5+2)) -> 0 | BW5: 1 | BX5: 4 | BY5: 16 | BZ5: =BY5+18 -> 34 | CB5: =IF(CA5=0,0,MAX(0,IF(CA$4>18,IF($D5<=CA$4,2,1),IF($C5<=CA$4,1,0))-CA5+$B5+2)) -> 0 | CD5: =IF(CC5=0,0,MAX(0,IF(CC$4>18,IF($D5<=CC$4,2,1),IF($C5<=CC$4,1,0))-CC5+$B5+2)) -> 0 | CF5: =IF(CE5=0,0,MAX(0,IF(CE$4>18,IF($D5<=CE$4,2,1),IF($C5<=CE$4,1,0))-CE5+$B5+2)) -> 0 | CH5: =IF(CG5=0,0,MAX(0,IF(CG$4>18,IF($D5<=CG$4,2,1),IF($C5<=CG$4,1,0))-CG5+$B5+2)) -> 0 | CJ5: =IF(CI5=0,0,MAX(0,IF(CI$4>18,IF($D5<=CI$4,2,1),IF($C5<=CI$4,1,0))-CI5+$B5+2)) -> 0 | CL5: =IF(CK5=0,0,MAX(0,IF(CK$4>18,IF($D5<=CK$4,2,1),IF($C5<=CK$4,1,0))-CK5+$B5+2)) -> 0 | CN5: =IF(CM5=0,0,MAX(0,IF(CM$4>18,IF($D5<=CM$4,2,1),IF($C5<=CM$4,1,0))-CM5+$B5+2)) -> 0 | CP5: =IF(CO5=0,0,MAX(0,IF(CO$4>18,IF($D5<=CO$4,2,1),IF($C5<=CO$4,1,0))-CO5+$B5+2)) -> 0 | CR5: =IF(CQ5=0,0,MAX(0,IF(CQ$4>18,IF($D5<=CQ$4,2,1),IF($C5<=CQ$4,1,0))-CQ5+$B5+2)) -> 0 | CT5: =IF(CS5=0,0,MAX(0,IF(CS$4>18,IF($D5<=CS$4,2,1),IF($C5<=CS$4,1,0))-CS5+$B5+2)) -> 0 | CV5: =IF(CU5=0,0,MAX(0,IF(CU$4>18,IF($D5<=CU$4,2,1),IF($C5<=CU$4,1,0))-CU5+$B5+2)) -> 0 | CX5: =IF(CW5=0,0,MAX(0,IF(CW$4>18,IF($D5<=CW$4,2,1),IF($C5<=CW$4,1,0))-CW5+$B5+2)) -> 0 | CZ5: =IF(CY5=0,0,MAX(0,IF(CY$4>18,IF($D5<=CY$4,2,1),IF($C5<=CY$4,1,0))-CY5+$B5+2)) -> 0 | DB5: =IF(DA5=0,0,MAX(0,IF(DA$4>18,IF($D5<=DA$4,2,1),IF($C5<=DA$4,1,0))-DA5+$B5+2)) -> 0 | DD5: =IF(DC5=0,0,MAX(0,IF(DC$4>18,IF($D5<=DC$4,2,1),IF($C5<=DC$4,1,0))-DC5+$B5+2)) -> 0 | DF5: =IF(DE5=0,0,MAX(0,IF(DE$4>18,IF($D5<=DE$4,2,1),IF($C5<=DE$4,1,0))-DE5+$B5+2)) -> 0 | DH5: 1 | DI5: 4 | DJ5: 16 | DK5: =DJ5+18 -> 34 | DM5: =IF(DL5=0,0,MAX(0,IF(DL$4>18,IF($D5<=DL$4,2,1),IF($C5<=DL$4,1,0))-DL5+$B5+2)) -> 0 | DO5: =IF(DN5=0,0,MAX(0,IF(DN$4>18,IF($D5<=DN$4,2,1),IF($C5<=DN$4,1,0))-DN5+$B5+2)) -> 0 | DQ5: =IF(DP5=0,0,MAX(0,IF(DP$4>18,IF($D5<=DP$4,2,1),IF($C5<=DP$4,1,0))-DP5+$B5+2)) -> 0 | DS5: =IF(DR5=0,0,MAX(0,IF(DR$4>18,IF($D5<=DR$4,2,1),IF($C5<=DR$4,1,0))-DR5+$B5+2)) -> 0 | DU5: =IF(DT5=0,0,MAX(0,IF(DT$4>18,IF($D5<=DT$4,2,1),IF($C5<=DT$4,1,0))-DT5+$B5+2)) -> 0 | DW5: =IF(DV5=0,0,MAX(0,IF(DV$4>18,IF($D5<=DV$4,2,1),IF($C5<=DV$4,1,0))-DV5+$B5+2)) -> 0 | DY5: =IF(DX5=0,0,MAX(0,IF(DX$4>18,IF($D5<=DX$4,2,1),IF($C5<=DX$4,1,0))-DX5+$B5+2)) -> 0 | EA5: =IF(DZ5=0,0,MAX(0,IF(DZ$4>18,IF($D5<=DZ$4,2,1),IF($C5<=DZ$4,1,0))-DZ5+$B5+2)) -> 0 | EC5: =IF(EB5=0,0,MAX(0,IF(EB$4>18,IF($D5<=EB$4,2,1),IF($C5<=EB$4,1,0))-EB5+$B5+2)) -> 0 | EE5: =IF(ED5=0,0,MAX(0,IF(ED$4>18,IF($D5<=ED$4,2,1),IF($C5<=ED$4,1,0))-ED5+$B5+2)) -> 0 | EG5: =IF(EF5=0,0,MAX(0,IF(EF$4>18,IF($D5<=EF$4,2,1),IF($C5<=EF$4,1,0))-EF5+$B5+2)) -> 0 | EI5: =IF(EH5=0,0,MAX(0,IF(EH$4>18,IF($D5<=EH$4,2,1),IF($C5<=EH$4,1,0))-EH5+$B5+2)) -> 0 | EK5: =IF(EJ5=0,0,MAX(0,IF(EJ$4>18,IF($D5<=EJ$4,2,1),IF($C5<=EJ$4,1,0))-EJ5+$B5+2)) -> 0 | EM5: =IF(EL5=0,0,MAX(0,IF(EL$4>18,IF($D5<=EL$4,2,1),IF($C5<=EL$4,1,0))-EL5+$B5+2)) -> 0 | EO5: =IF(EN5=0,0,MAX(0,IF(EN$4>18,IF($D5<=EN$4,2,1),IF($C5<=EN$4,1,0))-EN5+$B5+2)) -> 0 | EQ5: =IF(EP5=0,0,MAX(0,IF(EP$4>18,IF($D5<=EP$4,2,1),IF($C5<=EP$4,1,0))-EP5+$B5+2)) -> 0 | ES5: 1 | ET5: 4 | EU5: 16 | EV5: =EU5+18 -> 34 | EX5: =IF(EW5=0,0,MAX(0,IF(EW$4>18,IF($D5<=EW$4,2,1),IF($C5<=EW$4,1,0))-EW5+$B5+2)) -> 0 | EZ5: =IF(EY5=0,0,MAX(0,IF(EY$4>18,IF($D5<=EY$4,2,1),IF($C5<=EY$4,1,0))-EY5+$B5+2)) -> 0 | FB5: =IF(FA5=0,0,MAX(0,IF(FA$4>18,IF($D5<=FA$4,2,1),IF($C5<=FA$4,1,0))-FA5+$B5+2)) -> 0 | FD5: =IF(FC5=0,0,MAX(0,IF(FC$4>18,IF($D5<=FC$4,2,1),IF($C5<=FC$4,1,0))-FC5+$B5+2)) -> 0 | FF5: =IF(FE5=0,0,MAX(0,IF(FE$4>18,IF($D5<=FE$4,2,1),IF($C5<=FE$4,1,0))-FE5+$B5+2)) -> 0 | FH5: =IF(FG5=0,0,MAX(0,IF(FG$4>18,IF($D5<=FG$4,2,1),IF($C5<=FG$4,1,0))-FG5+$B5+2)) -> 0 | FJ5: =IF(FI5=0,0,MAX(0,IF(FI$4>18,IF($D5<=FI$4,2,1),IF($C5<=FI$4,1,0))-FI5+$B5+2)) -> 0 | FL5: =IF(FK5=0,0,MAX(0,IF(FK$4>18,IF($D5<=FK$4,2,1),IF($C5<=FK$4,1,0))-FK5+$B5+2)) -> 0 | FN5: =IF(FM5=0,0,MAX(0,IF(FM$4>18,IF($D5<=FM$4,2,1),IF($C5<=FM$4,1,0))-FM5+$B5+2)) -> 0 | FP5: =IF(FO5=0,0,MAX(0,IF(FO$4>18,IF($D5<=FO$4,2,1),IF($C5<=FO$4,1,0))-FO5+$B5+2)) -> 0 | FR5: =IF(FQ5=0,0,MAX(0,IF(FQ$4>18,IF($D5<=FQ$4,2,1),IF($C5<=FQ$4,1,0))-FQ5+$B5+2)) -> 0 | FT5: =IF(FS5=0,0,MAX(0,IF(FS$4>18,IF($D5<=FS$4,2,1),IF($C5<=FS$4,1,0))-FS5+$B5+2)) -> 0 | FV5: =IF(FU5=0,0,MAX(0,IF(FU$4>18,IF($D5<=FU$4,2,1),IF($C5<=FU$4,1,0))-FU5+$B5+2)) -> 0 | FX5: =IF(FW5=0,0,MAX(0,IF(FW$4>18,IF($D5<=FW$4,2,1),IF($C5<=FW$4,1,0))-FW5+$B5+2)) -> 0 | FZ5: =IF(FY5=0,0,MAX(0,IF(FY$4>18,IF($D5<=FY$4,2,1),IF($C5<=FY$4,1,0))-FY5+$B5+2)) -> 0 | GB5: =IF(GA5=0,0,MAX(0,IF(GA$4>18,IF($D5<=GA$4,2,1),IF($C5<=GA$4,1,0))-GA5+$B5+2)) -> 0
A6: 2 | B6: 4 | C6: 10 | D6: =C6+18 -> 28 | F6: =IF(E6=0,0,MAX(0,IF(E$4>18,IF($D6<=E$4,2,1),IF($C6<=E$4,1,0))-E6+$B6+2)) -> 0 | H6: =IF(G6=0,0,MAX(0,IF(G$4>18,IF($D6<=G$4,2,1),IF($C6<=G$4,1,0))-G6+$B6+2)) -> 0 | J6: =IF(I6=0,0,MAX(0,IF(I$4>18,IF($D6<=I$4,2,1),IF($C6<=I$4,1,0))-I6+$B6+2)) -> 0 | L6: =IF(K6=0,0,MAX(0,IF(K$4>18,IF($D6<=K$4,2,1),IF($C6<=K$4,1,0))-K6+$B6+2)) -> 0 | N6: =IF(M6=0,0,MAX(0,IF(M$4>18,IF($D6<=M$4,2,1),IF($C6<=M$4,1,0))-M6+$B6+2)) -> 0 | P6: =IF(O6=0,0,MAX(0,IF(O$4>18,IF($D6<=O$4,2,1),IF($C6<=O$4,1,0))-O6+$B6+2)) -> 0 | R6: =IF(Q6=0,0,MAX(0,IF(Q$4>18,IF($D6<=Q$4,2,1),IF($C6<=Q$4,1,0))-Q6+$B6+2)) -> 0 | T6: =IF(S6=0,0,MAX(0,IF(S$4>18,IF($D6<=S$4,2,1),IF($C6<=S$4,1,0))-S6+$B6+2)) -> 0 | V6: =IF(U6=0,0,MAX(0,IF(U$4>18,IF($D6<=U$4,2,1),IF($C6<=U$4,1,0))-U6+$B6+2)) -> 0 | X6: =IF(W6=0,0,MAX(0,IF(W$4>18,IF($D6<=W$4,2,1),IF($C6<=W$4,1,0))-W6+$B6+2)) -> 0 | Z6: =IF(Y6=0,0,MAX(0,IF(Y$4>18,IF($D6<=Y$4,2,1),IF($C6<=Y$4,1,0))-Y6+$B6+2)) -> 0 | AB6: =IF(AA6=0,0,MAX(0,IF(AA$4>18,IF($D6<=AA$4,2,1),IF($C6<=AA$4,1,0))-AA6+$B6+2)) -> 0 | AD6: =IF(AC6=0,0,MAX(0,IF(AC$4>18,IF($D6<=AC$4,2,1),IF($C6<=AC$4,1,0))-AC6+$B6+2)) -> 0 | AF6: =IF(AE6=0,0,MAX(0,IF(AE$4>18,IF($D6<=AE$4,2,1),IF($C6<=AE$4,1,0))-AE6+$B6+2)) -> 0 | AH6: =IF(AG6=0,0,MAX(0,IF(AG$4>18,IF($D6<=AG$4,2,1),IF($C6<=AG$4,1,0))-AG6+$B6+2)) -> 0 | AJ6: =IF(AI6=0,0,MAX(0,IF(AI$4>18,IF($D6<=AI$4,2,1),IF($C6<=AI$4,1,0))-AI6+$B6+2)) -> 0 | AL6: 2 | AM6: 4 | AN6: 10 | AO6: =AN6+18 -> 28 | AQ6: =IF(AP6=0,0,MAX(0,IF(AP$4>18,IF($D6<=AP$4,2,1),IF($C6<=AP$4,1,0))-AP6+$B6+2)) -> 0 | AS6: =IF(AR6=0,0,MAX(0,IF(AR$4>18,IF($D6<=AR$4,2,1),IF($C6<=AR$4,1,0))-AR6+$B6+2)) -> 0 | AU6: =IF(AT6=0,0,MAX(0,IF(AT$4>18,IF($D6<=AT$4,2,1),IF($C6<=AT$4,1,0))-AT6+$B6+2)) -> 0 | AW6: =IF(AV6=0,0,MAX(0,IF(AV$4>18,IF($D6<=AV$4,2,1),IF($C6<=AV$4,1,0))-AV6+$B6+2)) -> 0 | AY6: =IF(AX6=0,0,MAX(0,IF(AX$4>18,IF($D6<=AX$4,2,1),IF($C6<=AX$4,1,0))-AX6+$B6+2)) -> 0 | BA6: =IF(AZ6=0,0,MAX(0,IF(AZ$4>18,IF($D6<=AZ$4,2,1),IF($C6<=AZ$4,1,0))-AZ6+$B6+2)) -> 0 | BC6: =IF(BB6=0,0,MAX(0,IF(BB$4>18,IF($D6<=BB$4,2,1),IF($C6<=BB$4,1,0))-BB6+$B6+2)) -> 0 | BE6: =IF(BD6=0,0,MAX(0,IF(BD$4>18,IF($D6<=BD$4,2,1),IF($C6<=BD$4,1,0))-BD6+$B6+2)) -> 0 | BG6: =IF(BF6=0,0,MAX(0,IF(BF$4>18,IF($D6<=BF$4,2,1),IF($C6<=BF$4,1,0))-BF6+$B6+2)) -> 0 | BI6: =IF(BH6=0,0,MAX(0,IF(BH$4>18,IF($D6<=BH$4,2,1),IF($C6<=BH$4,1,0))-BH6+$B6+2)) -> 0 | BK6: =IF(BJ6=0,0,MAX(0,IF(BJ$4>18,IF($D6<=BJ$4,2,1),IF($C6<=BJ$4,1,0))-BJ6+$B6+2)) -> 0 | BM6: =IF(BL6=0,0,MAX(0,IF(BL$4>18,IF($D6<=BL$4,2,1),IF($C6<=BL$4,1,0))-BL6+$B6+2)) -> 0 | BO6: =IF(BN6=0,0,MAX(0,IF(BN$4>18,IF($D6<=BN$4,2,1),IF($C6<=BN$4,1,0))-BN6+$B6+2)) -> 0 | BQ6: =IF(BP6=0,0,MAX(0,IF(BP$4>18,IF($D6<=BP$4,2,1),IF($C6<=BP$4,1,0))-BP6+$B6+2)) -> 0 | BS6: =IF(BR6=0,0,MAX(0,IF(BR$4>18,IF($D6<=BR$4,2,1),IF($C6<=BR$4,1,0))-BR6+$B6+2)) -> 0 | BU6: =IF(BT6=0,0,MAX(0,IF(BT$4>18,IF($D6<=BT$4,2,1),IF($C6<=BT$4,1,0))-BT6+$B6+2)) -> 0 | BW6: 2 | BX6: 4 | BY6: 10 | BZ6: =BY6+18 -> 28 | CB6: =IF(CA6=0,0,MAX(0,IF(CA$4>18,IF($D6<=CA$4,2,1),IF($C6<=CA$4,1,0))-CA6+$B6+2)) -> 0 | CD6: =IF(CC6=0,0,MAX(0,IF(CC$4>18,IF($D6<=CC$4,2,1),IF($C6<=CC$4,1,0))-CC6+$B6+2)) -> 0 | CF6: =IF(CE6=0,0,MAX(0,IF(CE$4>18,IF($D6<=CE$4,2,1),IF($C6<=CE$4,1,0))-CE6+$B6+2)) -> 0 | CH6: =IF(CG6=0,0,MAX(0,IF(CG$4>18,IF($D6<=CG$4,2,1),IF($C6<=CG$4,1,0))-CG6+$B6+2)) -> 0 | CJ6: =IF(CI6=0,0,MAX(0,IF(CI$4>18,IF($D6<=CI$4,2,1),IF($C6<=CI$4,1,0))-CI6+$B6+2)) -> 0 | CL6: =IF(CK6=0,0,MAX(0,IF(CK$4>18,IF($D6<=CK$4,2,1),IF($C6<=CK$4,1,0))-CK6+$B6+2)) -> 0 | CN6: =IF(CM6=0,0,MAX(0,IF(CM$4>18,IF($D6<=CM$4,2,1),IF($C6<=CM$4,1,0))-CM6+$B6+2)) -> 0 | CP6: =IF(CO6=0,0,MAX(0,IF(CO$4>18,IF($D6<=CO$4,2,1),IF($C6<=CO$4,1,0))-CO6+$B6+2)) -> 0 | CR6: =IF(CQ6=0,0,MAX(0,IF(CQ$4>18,IF($D6<=CQ$4,2,1),IF($C6<=CQ$4,1,0))-CQ6+$B6+2)) -> 0 | CT6: =IF(CS6=0,0,MAX(0,IF(CS$4>18,IF($D6<=CS$4,2,1),IF($C6<=CS$4,1,0))-CS6+$B6+2)) -> 0 | CV6: =IF(CU6=0,0,MAX(0,IF(CU$4>18,IF($D6<=CU$4,2,1),IF($C6<=CU$4,1,0))-CU6+$B6+2)) -> 0 | CX6: =IF(CW6=0,0,MAX(0,IF(CW$4>18,IF($D6<=CW$4,2,1),IF($C6<=CW$4,1,0))-CW6+$B6+2)) -> 0 | CZ6: =IF(CY6=0,0,MAX(0,IF(CY$4>18,IF($D6<=CY$4,2,1),IF($C6<=CY$4,1,0))-CY6+$B6+2)) -> 0 | DB6: =IF(DA6=0,0,MAX(0,IF(DA$4>18,IF($D6<=DA$4,2,1),IF($C6<=DA$4,1,0))-DA6+$B6+2)) -> 0 | DD6: =IF(DC6=0,0,MAX(0,IF(DC$4>18,IF($D6<=DC$4,2,1),IF($C6<=DC$4,1,0))-DC6+$B6+2)) -> 0 | DF6: =IF(DE6=0,0,MAX(0,IF(DE$4>18,IF($D6<=DE$4,2,1),IF($C6<=DE$4,1,0))-DE6+$B6+2)) -> 0 | DH6: 2 | DI6: 4 | DJ6: 10 | DK6: =DJ6+18 -> 28 | DM6: =IF(DL6=0,0,MAX(0,IF(DL$4>18,IF($D6<=DL$4,2,1),IF($C6<=DL$4,1,0))-DL6+$B6+2)) -> 0 | DO6: =IF(DN6=0,0,MAX(0,IF(DN$4>18,IF($D6<=DN$4,2,1),IF($C6<=DN$4,1,0))-DN6+$B6+2)) -> 0 | DQ6: =IF(DP6=0,0,MAX(0,IF(DP$4>18,IF($D6<=DP$4,2,1),IF($C6<=DP$4,1,0))-DP6+$B6+2)) -> 0 | DS6: =IF(DR6=0,0,MAX(0,IF(DR$4>18,IF($D6<=DR$4,2,1),IF($C6<=DR$4,1,0))-DR6+$B6+2)) -> 0 | DU6: =IF(DT6=0,0,MAX(0,IF(DT$4>18,IF($D6<=DT$4,2,1),IF($C6<=DT$4,1,0))-DT6+$B6+2)) -> 0 | DW6: =IF(DV6=0,0,MAX(0,IF(DV$4>18,IF($D6<=DV$4,2,1),IF($C6<=DV$4,1,0))-DV6+$B6+2)) -> 0 | DY6: =IF(DX6=0,0,MAX(0,IF(DX$4>18,IF($D6<=DX$4,2,1),IF($C6<=DX$4,1,0))-DX6+$B6+2)) -> 0 | EA6: =IF(DZ6=0,0,MAX(0,IF(DZ$4>18,IF($D6<=DZ$4,2,1),IF($C6<=DZ$4,1,0))-DZ6+$B6+2)) -> 0 | EC6: =IF(EB6=0,0,MAX(0,IF(EB$4>18,IF($D6<=EB$4,2,1),IF($C6<=EB$4,1,0))-EB6+$B6+2)) -> 0 | EE6: =IF(ED6=0,0,MAX(0,IF(ED$4>18,IF($D6<=ED$4,2,1),IF($C6<=ED$4,1,0))-ED6+$B6+2)) -> 0 | EG6: =IF(EF6=0,0,MAX(0,IF(EF$4>18,IF($D6<=EF$4,2,1),IF($C6<=EF$4,1,0))-EF6+$B6+2)) -> 0 | EI6: =IF(EH6=0,0,MAX(0,IF(EH$4>18,IF($D6<=EH$4,2,1),IF($C6<=EH$4,1,0))-EH6+$B6+2)) -> 0 | EK6: =IF(EJ6=0,0,MAX(0,IF(EJ$4>18,IF($D6<=EJ$4,2,1),IF($C6<=EJ$4,1,0))-EJ6+$B6+2)) -> 0 | EM6: =IF(EL6=0,0,MAX(0,IF(EL$4>18,IF($D6<=EL$4,2,1),IF($C6<=EL$4,1,0))-EL6+$B6+2)) -> 0 | EO6: =IF(EN6=0,0,MAX(0,IF(EN$4>18,IF($D6<=EN$4,2,1),IF($C6<=EN$4,1,0))-EN6+$B6+2)) -> 0 | EQ6: =IF(EP6=0,0,MAX(0,IF(EP$4>18,IF($D6<=EP$4,2,1),IF($C6<=EP$4,1,0))-EP6+$B6+2)) -> 0 | ES6: 2 | ET6: 4 | EU6: 10 | EV6: =EU6+18 -> 28 | EX6: =IF(EW6=0,0,MAX(0,IF(EW$4>18,IF($D6<=EW$4,2,1),IF($C6<=EW$4,1,0))-EW6+$B6+2)) -> 0 | EZ6: =IF(EY6=0,0,MAX(0,IF(EY$4>18,IF($D6<=EY$4,2,1),IF($C6<=EY$4,1,0))-EY6+$B6+2)) -> 0 | FB6: =IF(FA6=0,0,MAX(0,IF(FA$4>18,IF($D6<=FA$4,2,1),IF($C6<=FA$4,1,0))-FA6+$B6+2)) -> 0 | FD6: =IF(FC6=0,0,MAX(0,IF(FC$4>18,IF($D6<=FC$4,2,1),IF($C6<=FC$4,1,0))-FC6+$B6+2)) -> 0 | FF6: =IF(FE6=0,0,MAX(0,IF(FE$4>18,IF($D6<=FE$4,2,1),IF($C6<=FE$4,1,0))-FE6+$B6+2)) -> 0 | FH6: =IF(FG6=0,0,MAX(0,IF(FG$4>18,IF($D6<=FG$4,2,1),IF($C6<=FG$4,1,0))-FG6+$B6+2)) -> 0 | FJ6: =IF(FI6=0,0,MAX(0,IF(FI$4>18,IF($D6<=FI$4,2,1),IF($C6<=FI$4,1,0))-FI6+$B6+2)) -> 0 | FL6: =IF(FK6=0,0,MAX(0,IF(FK$4>18,IF($D6<=FK$4,2,1),IF($C6<=FK$4,1,0))-FK6+$B6+2)) -> 0 | FN6: =IF(FM6=0,0,MAX(0,IF(FM$4>18,IF($D6<=FM$4,2,1),IF($C6<=FM$4,1,0))-FM6+$B6+2)) -> 0 | FP6: =IF(FO6=0,0,MAX(0,IF(FO$4>18,IF($D6<=FO$4,2,1),IF($C6<=FO$4,1,0))-FO6+$B6+2)) -> 0 | FR6: =IF(FQ6=0,0,MAX(0,IF(FQ$4>18,IF($D6<=FQ$4,2,1),IF($C6<=FQ$4,1,0))-FQ6+$B6+2)) -> 0 | FT6: =IF(FS6=0,0,MAX(0,IF(FS$4>18,IF($D6<=FS$4,2,1),IF($C6<=FS$4,1,0))-FS6+$B6+2)) -> 0 | FV6: =IF(FU6=0,0,MAX(0,IF(FU$4>18,IF($D6<=FU$4,2,1),IF($C6<=FU$4,1,0))-FU6+$B6+2)) -> 0 | FX6: =IF(FW6=0,0,MAX(0,IF(FW$4>18,IF($D6<=FW$4,2,1),IF($C6<=FW$4,1,0))-FW6+$B6+2)) -> 0 | FZ6: =IF(FY6=0,0,MAX(0,IF(FY$4>18,IF($D6<=FY$4,2,1),IF($C6<=FY$4,1,0))-FY6+$B6+2)) -> 0 | GB6: =IF(GA6=0,0,MAX(0,IF(GA$4>18,IF($D6<=GA$4,2,1),IF($C6<=GA$4,1,0))-GA6+$B6+2)) -> 0
A7: 3 | B7: 4 | C7: 2 | D7: =C7+18 -> 20 | F7: =IF(E7=0,0,MAX(0,IF(E$4>18,IF($D7<=E$4,2,1),IF($C7<=E$4,1,0))-E7+$B7+2)) -> 0 | H7: =IF(G7=0,0,MAX(0,IF(G$4>18,IF($D7<=G$4,2,1),IF($C7<=G$4,1,0))-G7+$B7+2)) -> 0 | J7: =IF(I7=0,0,MAX(0,IF(I$4>18,IF($D7<=I$4,2,1),IF($C7<=I$4,1,0))-I7+$B7+2)) -> 0 | L7: =IF(K7=0,0,MAX(0,IF(K$4>18,IF($D7<=K$4,2,1),IF($C7<=K$4,1,0))-K7+$B7+2)) -> 0 | N7: =IF(M7=0,0,MAX(0,IF(M$4>18,IF($D7<=M$4,2,1),IF($C7<=M$4,1,0))-M7+$B7+2)) -> 0 | P7: =IF(O7=0,0,MAX(0,IF(O$4>18,IF($D7<=O$4,2,1),IF($C7<=O$4,1,0))-O7+$B7+2)) -> 0 | R7: =IF(Q7=0,0,MAX(0,IF(Q$4>18,IF($D7<=Q$4,2,1),IF($C7<=Q$4,1,0))-Q7+$B7+2)) -> 0 | T7: =IF(S7=0,0,MAX(0,IF(S$4>18,IF($D7<=S$4,2,1),IF($C7<=S$4,1,0))-S7+$B7+2)) -> 0 | V7: =IF(U7=0,0,MAX(0,IF(U$4>18,IF($D7<=U$4,2,1),IF($C7<=U$4,1,0))-U7+$B7+2)) -> 0 | X7: =IF(W7=0,0,MAX(0,IF(W$4>18,IF($D7<=W$4,2,1),IF($C7<=W$4,1,0))-W7+$B7+2)) -> 0 | Z7: =IF(Y7=0,0,MAX(0,IF(Y$4>18,IF($D7<=Y$4,2,1),IF($C7<=Y$4,1,0))-Y7+$B7+2)) -> 0 | AB7: =IF(AA7=0,0,MAX(0,IF(AA$4>18,IF($D7<=AA$4,2,1),IF($C7<=AA$4,1,0))-AA7+$B7+2)) -> 0 | AD7: =IF(AC7=0,0,MAX(0,IF(AC$4>18,IF($D7<=AC$4,2,1),IF($C7<=AC$4,1,0))-AC7+$B7+2)) -> 0 | AF7: =IF(AE7=0,0,MAX(0,IF(AE$4>18,IF($D7<=AE$4,2,1),IF($C7<=AE$4,1,0))-AE7+$B7+2)) -> 0 | AH7: =IF(AG7=0,0,MAX(0,IF(AG$4>18,IF($D7<=AG$4,2,1),IF($C7<=AG$4,1,0))-AG7+$B7+2)) -> 0 | AJ7: =IF(AI7=0,0,MAX(0,IF(AI$4>18,IF($D7<=AI$4,2,1),IF($C7<=AI$4,1,0))-AI7+$B7+2)) -> 0 | AL7: 3 | AM7: 4 | AN7: 2 | AO7: =AN7+18 -> 20 | AQ7: =IF(AP7=0,0,MAX(0,IF(AP$4>18,IF($D7<=AP$4,2,1),IF($C7<=AP$4,1,0))-AP7+$B7+2)) -> 0 | AS7: =IF(AR7=0,0,MAX(0,IF(AR$4>18,IF($D7<=AR$4,2,1),IF($C7<=AR$4,1,0))-AR7+$B7+2)) -> 0 | AU7: =IF(AT7=0,0,MAX(0,IF(AT$4>18,IF($D7<=AT$4,2,1),IF($C7<=AT$4,1,0))-AT7+$B7+2)) -> 0 | AW7: =IF(AV7=0,0,MAX(0,IF(AV$4>18,IF($D7<=AV$4,2,1),IF($C7<=AV$4,1,0))-AV7+$B7+2)) -> 0 | AY7: =IF(AX7=0,0,MAX(0,IF(AX$4>18,IF($D7<=AX$4,2,1),IF($C7<=AX$4,1,0))-AX7+$B7+2)) -> 0 | BA7: =IF(AZ7=0,0,MAX(0,IF(AZ$4>18,IF($D7<=AZ$4,2,1),IF($C7<=AZ$4,1,0))-AZ7+$B7+2)) -> 0 | BC7: =IF(BB7=0,0,MAX(0,IF(BB$4>18,IF($D7<=BB$4,2,1),IF($C7<=BB$4,1,0))-BB7+$B7+2)) -> 0 | BE7: =IF(BD7=0,0,MAX(0,IF(BD$4>18,IF($D7<=BD$4,2,1),IF($C7<=BD$4,1,0))-BD7+$B7+2)) -> 0 | BG7: =IF(BF7=0,0,MAX(0,IF(BF$4>18,IF($D7<=BF$4,2,1),IF($C7<=BF$4,1,0))-BF7+$B7+2)) -> 0 | BI7: =IF(BH7=0,0,MAX(0,IF(BH$4>18,IF($D7<=BH$4,2,1),IF($C7<=BH$4,1,0))-BH7+$B7+2)) -> 0 | BK7: =IF(BJ7=0,0,MAX(0,IF(BJ$4>18,IF($D7<=BJ$4,2,1),IF($C7<=BJ$4,1,0))-BJ7+$B7+2)) -> 0 | BM7: =IF(BL7=0,0,MAX(0,IF(BL$4>18,IF($D7<=BL$4,2,1),IF($C7<=BL$4,1,0))-BL7+$B7+2)) -> 0 | BO7: =IF(BN7=0,0,MAX(0,IF(BN$4>18,IF($D7<=BN$4,2,1),IF($C7<=BN$4,1,0))-BN7+$B7+2)) -> 0 | BQ7: =IF(BP7=0,0,MAX(0,IF(BP$4>18,IF($D7<=BP$4,2,1),IF($C7<=BP$4,1,0))-BP7+$B7+2)) -> 0 | BS7: =IF(BR7=0,0,MAX(0,IF(BR$4>18,IF($D7<=BR$4,2,1),IF($C7<=BR$4,1,0))-BR7+$B7+2)) -> 0 | BU7: =IF(BT7=0,0,MAX(0,IF(BT$4>18,IF($D7<=BT$4,2,1),IF($C7<=BT$4,1,0))-BT7+$B7+2)) -> 0 | BW7: 3 | BX7: 4 | BY7: 2 | BZ7: =BY7+18 -> 20 | CB7: =IF(CA7=0,0,MAX(0,IF(CA$4>18,IF($D7<=CA$4,2,1),IF($C7<=CA$4,1,0))-CA7+$B7+2)) -> 0 | CD7: =IF(CC7=0,0,MAX(0,IF(CC$4>18,IF($D7<=CC$4,2,1),IF($C7<=CC$4,1,0))-CC7+$B7+2)) -> 0 | CF7: =IF(CE7=0,0,MAX(0,IF(CE$4>18,IF($D7<=CE$4,2,1),IF($C7<=CE$4,1,0))-CE7+$B7+2)) -> 0 | CH7: =IF(CG7=0,0,MAX(0,IF(CG$4>18,IF($D7<=CG$4,2,1),IF($C7<=CG$4,1,0))-CG7+$B7+2)) -> 0 | CJ7: =IF(CI7=0,0,MAX(0,IF(CI$4>18,IF($D7<=CI$4,2,1),IF($C7<=CI$4,1,0))-CI7+$B7+2)) -> 0 | CL7: =IF(CK7=0,0,MAX(0,IF(CK$4>18,IF($D7<=CK$4,2,1),IF($C7<=CK$4,1,0))-CK7+$B7+2)) -> 0 | CN7: =IF(CM7=0,0,MAX(0,IF(CM$4>18,IF($D7<=CM$4,2,1),IF($C7<=CM$4,1,0))-CM7+$B7+2)) -> 0 | CP7: =IF(CO7=0,0,MAX(0,IF(CO$4>18,IF($D7<=CO$4,2,1),IF($C7<=CO$4,1,0))-CO7+$B7+2)) -> 0 | CR7: =IF(CQ7=0,0,MAX(0,IF(CQ$4>18,IF($D7<=CQ$4,2,1),IF($C7<=CQ$4,1,0))-CQ7+$B7+2)) -> 0 | CT7: =IF(CS7=0,0,MAX(0,IF(CS$4>18,IF($D7<=CS$4,2,1),IF($C7<=CS$4,1,0))-CS7+$B7+2)) -> 0 | CV7: =IF(CU7=0,0,MAX(0,IF(CU$4>18,IF($D7<=CU$4,2,1),IF($C7<=CU$4,1,0))-CU7+$B7+2)) -> 0 | CX7: =IF(CW7=0,0,MAX(0,IF(CW$4>18,IF($D7<=CW$4,2,1),IF($C7<=CW$4,1,0))-CW7+$B7+2)) -> 0 | CZ7: =IF(CY7=0,0,MAX(0,IF(CY$4>18,IF($D7<=CY$4,2,1),IF($C7<=CY$4,1,0))-CY7+$B7+2)) -> 0 | DB7: =IF(DA7=0,0,MAX(0,IF(DA$4>18,IF($D7<=DA$4,2,1),IF($C7<=DA$4,1,0))-DA7+$B7+2)) -> 0 | DD7: =IF(DC7=0,0,MAX(0,IF(DC$4>18,IF($D7<=DC$4,2,1),IF($C7<=DC$4,1,0))-DC7+$B7+2)) -> 0 | DF7: =IF(DE7=0,0,MAX(0,IF(DE$4>18,IF($D7<=DE$4,2,1),IF($C7<=DE$4,1,0))-DE7+$B7+2)) -> 0 | DH7: 3 | DI7: 4 | DJ7: 2 | DK7: =DJ7+18 -> 20 | DM7: =IF(DL7=0,0,MAX(0,IF(DL$4>18,IF($D7<=DL$4,2,1),IF($C7<=DL$4,1,0))-DL7+$B7+2)) -> 0 | DO7: =IF(DN7=0,0,MAX(0,IF(DN$4>18,IF($D7<=DN$4,2,1),IF($C7<=DN$4,1,0))-DN7+$B7+2)) -> 0 | DQ7: =IF(DP7=0,0,MAX(0,IF(DP$4>18,IF($D7<=DP$4,2,1),IF($C7<=DP$4,1,0))-DP7+$B7+2)) -> 0 | DS7: =IF(DR7=0,0,MAX(0,IF(DR$4>18,IF($D7<=DR$4,2,1),IF($C7<=DR$4,1,0))-DR7+$B7+2)) -> 0 | DU7: =IF(DT7=0,0,MAX(0,IF(DT$4>18,IF($D7<=DT$4,2,1),IF($C7<=DT$4,1,0))-DT7+$B7+2)) -> 0 | DW7: =IF(DV7=0,0,MAX(0,IF(DV$4>18,IF($D7<=DV$4,2,1),IF($C7<=DV$4,1,0))-DV7+$B7+2)) -> 0 | DY7: =IF(DX7=0,0,MAX(0,IF(DX$4>18,IF($D7<=DX$4,2,1),IF($C7<=DX$4,1,0))-DX7+$B7+2)) -> 0 | EA7: =IF(DZ7=0,0,MAX(0,IF(DZ$4>18,IF($D7<=DZ$4,2,1),IF($C7<=DZ$4,1,0))-DZ7+$B7+2)) -> 0 | EC7: =IF(EB7=0,0,MAX(0,IF(EB$4>18,IF($D7<=EB$4,2,1),IF($C7<=EB$4,1,0))-EB7+$B7+2)) -> 0 | EE7: =IF(ED7=0,0,MAX(0,IF(ED$4>18,IF($D7<=ED$4,2,1),IF($C7<=ED$4,1,0))-ED7+$B7+2)) -> 0 | EG7: =IF(EF7=0,0,MAX(0,IF(EF$4>18,IF($D7<=EF$4,2,1),IF($C7<=EF$4,1,0))-EF7+$B7+2)) -> 0 | EI7: =IF(EH7=0,0,MAX(0,IF(EH$4>18,IF($D7<=EH$4,2,1),IF($C7<=EH$4,1,0))-EH7+$B7+2)) -> 0 | EK7: =IF(EJ7=0,0,MAX(0,IF(EJ$4>18,IF($D7<=EJ$4,2,1),IF($C7<=EJ$4,1,0))-EJ7+$B7+2)) -> 0 | EM7: =IF(EL7=0,0,MAX(0,IF(EL$4>18,IF($D7<=EL$4,2,1),IF($C7<=EL$4,1,0))-EL7+$B7+2)) -> 0 | EO7: =IF(EN7=0,0,MAX(0,IF(EN$4>18,IF($D7<=EN$4,2,1),IF($C7<=EN$4,1,0))-EN7+$B7+2)) -> 0 | EQ7: =IF(EP7=0,0,MAX(0,IF(EP$4>18,IF($D7<=EP$4,2,1),IF($C7<=EP$4,1,0))-EP7+$B7+2)) -> 0 | ES7: 3 | ET7: 4 | EU7: 2 | EV7: =EU7+18 -> 20 | EX7: =IF(EW7=0,0,MAX(0,IF(EW$4>18,IF($D7<=EW$4,2,1),IF($C7<=EW$4,1,0))-EW7+$B7+2)) -> 0 | EZ7: =IF(EY7=0,0,MAX(0,IF(EY$4>18,IF($D7<=EY$4,2,1),IF($C7<=EY$4,1,0))-EY7+$B7+2)) -> 0 | FB7: =IF(FA7=0,0,MAX(0,IF(FA$4>18,IF($D7<=FA$4,2,1),IF($C7<=FA$4,1,0))-FA7+$B7+2)) -> 0 | FD7: =IF(FC7=0,0,MAX(0,IF(FC$4>18,IF($D7<=FC$4,2,1),IF($C7<=FC$4,1,0))-FC7+$B7+2)) -> 0 | FF7: =IF(FE7=0,0,MAX(0,IF(FE$4>18,IF($D7<=FE$4,2,1),IF($C7<=FE$4,1,0))-FE7+$B7+2)) -> 0 | FH7: =IF(FG7=0,0,MAX(0,IF(FG$4>18,IF($D7<=FG$4,2,1),IF($C7<=FG$4,1,0))-FG7+$B7+2)) -> 0 | FJ7: =IF(FI7=0,0,MAX(0,IF(FI$4>18,IF($D7<=FI$4,2,1),IF($C7<=FI$4,1,0))-FI7+$B7+2)) -> 0 | FL7: =IF(FK7=0,0,MAX(0,IF(FK$4>18,IF($D7<=FK$4,2,1),IF($C7<=FK$4,1,0))-FK7+$B7+2)) -> 0 | FN7: =IF(FM7=0,0,MAX(0,IF(FM$4>18,IF($D7<=FM$4,2,1),IF($C7<=FM$4,1,0))-FM7+$B7+2)) -> 0 | FP7: =IF(FO7=0,0,MAX(0,IF(FO$4>18,IF($D7<=FO$4,2,1),IF($C7<=FO$4,1,0))-FO7+$B7+2)) -> 0 | FR7: =IF(FQ7=0,0,MAX(0,IF(FQ$4>18,IF($D7<=FQ$4,2,1),IF($C7<=FQ$4,1,0))-FQ7+$B7+2)) -> 0 | FT7: =IF(FS7=0,0,MAX(0,IF(FS$4>18,IF($D7<=FS$4,2,1),IF($C7<=FS$4,1,0))-FS7+$B7+2)) -> 0 | FV7: =IF(FU7=0,0,MAX(0,IF(FU$4>18,IF($D7<=FU$4,2,1),IF($C7<=FU$4,1,0))-FU7+$B7+2)) -> 0 | FX7: =IF(FW7=0,0,MAX(0,IF(FW$4>18,IF($D7<=FW$4,2,1),IF($C7<=FW$4,1,0))-FW7+$B7+2)) -> 0 | FZ7: =IF(FY7=0,0,MAX(0,IF(FY$4>18,IF($D7<=FY$4,2,1),IF($C7<=FY$4,1,0))-FY7+$B7+2)) -> 0 | GB7: =IF(GA7=0,0,MAX(0,IF(GA$4>18,IF($D7<=GA$4,2,1),IF($C7<=GA$4,1,0))-GA7+$B7+2)) -> 0
A8: 4 | B8: 4 | C8: 4 | D8: =C8+18 -> 22 | F8: =IF(E8=0,0,MAX(0,IF(E$4>18,IF($D8<=E$4,2,1),IF($C8<=E$4,1,0))-E8+$B8+2)) -> 0 | H8: =IF(G8=0,0,MAX(0,IF(G$4>18,IF($D8<=G$4,2,1),IF($C8<=G$4,1,0))-G8+$B8+2)) -> 0 | J8: =IF(I8=0,0,MAX(0,IF(I$4>18,IF($D8<=I$4,2,1),IF($C8<=I$4,1,0))-I8+$B8+2)) -> 0 | L8: =IF(K8=0,0,MAX(0,IF(K$4>18,IF($D8<=K$4,2,1),IF($C8<=K$4,1,0))-K8+$B8+2)) -> 0 | N8: =IF(M8=0,0,MAX(0,IF(M$4>18,IF($D8<=M$4,2,1),IF($C8<=M$4,1,0))-M8+$B8+2)) -> 0 | P8: =IF(O8=0,0,MAX(0,IF(O$4>18,IF($D8<=O$4,2,1),IF($C8<=O$4,1,0))-O8+$B8+2)) -> 0 | R8: =IF(Q8=0,0,MAX(0,IF(Q$4>18,IF($D8<=Q$4,2,1),IF($C8<=Q$4,1,0))-Q8+$B8+2)) -> 0 | T8: =IF(S8=0,0,MAX(0,IF(S$4>18,IF($D8<=S$4,2,1),IF($C8<=S$4,1,0))-S8+$B8+2)) -> 0 | V8: =IF(U8=0,0,MAX(0,IF(U$4>18,IF($D8<=U$4,2,1),IF($C8<=U$4,1,0))-U8+$B8+2)) -> 0 | X8: =IF(W8=0,0,MAX(0,IF(W$4>18,IF($D8<=W$4,2,1),IF($C8<=W$4,1,0))-W8+$B8+2)) -> 0 | Z8: =IF(Y8=0,0,MAX(0,IF(Y$4>18,IF($D8<=Y$4,2,1),IF($C8<=Y$4,1,0))-Y8+$B8+2)) -> 0 | AB8: =IF(AA8=0,0,MAX(0,IF(AA$4>18,IF($D8<=AA$4,2,1),IF($C8<=AA$4,1,0))-AA8+$B8+2)) -> 0 | AD8: =IF(AC8=0,0,MAX(0,IF(AC$4>18,IF($D8<=AC$4,2,1),IF($C8<=AC$4,1,0))-AC8+$B8+2)) -> 0 | AF8: =IF(AE8=0,0,MAX(0,IF(AE$4>18,IF($D8<=AE$4,2,1),IF($C8<=AE$4,1,0))-AE8+$B8+2)) -> 0 | AH8: =IF(AG8=0,0,MAX(0,IF(AG$4>18,IF($D8<=AG$4,2,1),IF($C8<=AG$4,1,0))-AG8+$B8+2)) -> 0 | AJ8: =IF(AI8=0,0,MAX(0,IF(AI$4>18,IF($D8<=AI$4,2,1),IF($C8<=AI$4,1,0))-AI8+$B8+2)) -> 0 | AL8: 4 | AM8: 4 | AN8: 4 | AO8: =AN8+18 -> 22 | AQ8: =IF(AP8=0,0,MAX(0,IF(AP$4>18,IF($D8<=AP$4,2,1),IF($C8<=AP$4,1,0))-AP8+$B8+2)) -> 0 | AS8: =IF(AR8=0,0,MAX(0,IF(AR$4>18,IF($D8<=AR$4,2,1),IF($C8<=AR$4,1,0))-AR8+$B8+2)) -> 0 | AU8: =IF(AT8=0,0,MAX(0,IF(AT$4>18,IF($D8<=AT$4,2,1),IF($C8<=AT$4,1,0))-AT8+$B8+2)) -> 0 | AW8: =IF(AV8=0,0,MAX(0,IF(AV$4>18,IF($D8<=AV$4,2,1),IF($C8<=AV$4,1,0))-AV8+$B8+2)) -> 0 | AY8: =IF(AX8=0,0,MAX(0,IF(AX$4>18,IF($D8<=AX$4,2,1),IF($C8<=AX$4,1,0))-AX8+$B8+2)) -> 0 | BA8: =IF(AZ8=0,0,MAX(0,IF(AZ$4>18,IF($D8<=AZ$4,2,1),IF($C8<=AZ$4,1,0))-AZ8+$B8+2)) -> 0 | BC8: =IF(BB8=0,0,MAX(0,IF(BB$4>18,IF($D8<=BB$4,2,1),IF($C8<=BB$4,1,0))-BB8+$B8+2)) -> 0 | BE8: =IF(BD8=0,0,MAX(0,IF(BD$4>18,IF($D8<=BD$4,2,1),IF($C8<=BD$4,1,0))-BD8+$B8+2)) -> 0 | BG8: =IF(BF8=0,0,MAX(0,IF(BF$4>18,IF($D8<=BF$4,2,1),IF($C8<=BF$4,1,0))-BF8+$B8+2)) -> 0 | BI8: =IF(BH8=0,0,MAX(0,IF(BH$4>18,IF($D8<=BH$4,2,1),IF($C8<=BH$4,1,0))-BH8+$B8+2)) -> 0 | BK8: =IF(BJ8=0,0,MAX(0,IF(BJ$4>18,IF($D8<=BJ$4,2,1),IF($C8<=BJ$4,1,0))-BJ8+$B8+2)) -> 0 | BM8: =IF(BL8=0,0,MAX(0,IF(BL$4>18,IF($D8<=BL$4,2,1),IF($C8<=BL$4,1,0))-BL8+$B8+2)) -> 0 | BO8: =IF(BN8=0,0,MAX(0,IF(BN$4>18,IF($D8<=BN$4,2,1),IF($C8<=BN$4,1,0))-BN8+$B8+2)) -> 0 | BQ8: =IF(BP8=0,0,MAX(0,IF(BP$4>18,IF($D8<=BP$4,2,1),IF($C8<=BP$4,1,0))-BP8+$B8+2)) -> 0 | BS8: =IF(BR8=0,0,MAX(0,IF(BR$4>18,IF($D8<=BR$4,2,1),IF($C8<=BR$4,1,0))-BR8+$B8+2)) -> 0 | BU8: =IF(BT8=0,0,MAX(0,IF(BT$4>18,IF($D8<=BT$4,2,1),IF($C8<=BT$4,1,0))-BT8+$B8+2)) -> 0 | BW8: 4 | BX8: 4 | BY8: 4 | BZ8: =BY8+18 -> 22 | CB8: =IF(CA8=0,0,MAX(0,IF(CA$4>18,IF($D8<=CA$4,2,1),IF($C8<=CA$4,1,0))-CA8+$B8+2)) -> 0 | CD8: =IF(CC8=0,0,MAX(0,IF(CC$4>18,IF($D8<=CC$4,2,1),IF($C8<=CC$4,1,0))-CC8+$B8+2)) -> 0 | CF8: =IF(CE8=0,0,MAX(0,IF(CE$4>18,IF($D8<=CE$4,2,1),IF($C8<=CE$4,1,0))-CE8+$B8+2)) -> 0 | CH8: =IF(CG8=0,0,MAX(0,IF(CG$4>18,IF($D8<=CG$4,2,1),IF($C8<=CG$4,1,0))-CG8+$B8+2)) -> 0 | CJ8: =IF(CI8=0,0,MAX(0,IF(CI$4>18,IF($D8<=CI$4,2,1),IF($C8<=CI$4,1,0))-CI8+$B8+2)) -> 0 | CL8: =IF(CK8=0,0,MAX(0,IF(CK$4>18,IF($D8<=CK$4,2,1),IF($C8<=CK$4,1,0))-CK8+$B8+2)) -> 0 | CN8: =IF(CM8=0,0,MAX(0,IF(CM$4>18,IF($D8<=CM$4,2,1),IF($C8<=CM$4,1,0))-CM8+$B8+2)) -> 0 | CP8: =IF(CO8=0,0,MAX(0,IF(CO$4>18,IF($D8<=CO$4,2,1),IF($C8<=CO$4,1,0))-CO8+$B8+2)) -> 0 | CR8: =IF(CQ8=0,0,MAX(0,IF(CQ$4>18,IF($D8<=CQ$4,2,1),IF($C8<=CQ$4,1,0))-CQ8+$B8+2)) -> 0 | CT8: =IF(CS8=0,0,MAX(0,IF(CS$4>18,IF($D8<=CS$4,2,1),IF($C8<=CS$4,1,0))-CS8+$B8+2)) -> 0 | CV8: =IF(CU8=0,0,MAX(0,IF(CU$4>18,IF($D8<=CU$4,2,1),IF($C8<=CU$4,1,0))-CU8+$B8+2)) -> 0 | CX8: =IF(CW8=0,0,MAX(0,IF(CW$4>18,IF($D8<=CW$4,2,1),IF($C8<=CW$4,1,0))-CW8+$B8+2)) -> 0 | CZ8: =IF(CY8=0,0,MAX(0,IF(CY$4>18,IF($D8<=CY$4,2,1),IF($C8<=CY$4,1,0))-CY8+$B8+2)) -> 0 | DB8: =IF(DA8=0,0,MAX(0,IF(DA$4>18,IF($D8<=DA$4,2,1),IF($C8<=DA$4,1,0))-DA8+$B8+2)) -> 0 | DD8: =IF(DC8=0,0,MAX(0,IF(DC$4>18,IF($D8<=DC$4,2,1),IF($C8<=DC$4,1,0))-DC8+$B8+2)) -> 0 | DF8: =IF(DE8=0,0,MAX(0,IF(DE$4>18,IF($D8<=DE$4,2,1),IF($C8<=DE$4,1,0))-DE8+$B8+2)) -> 0 | DH8: 4 | DI8: 4 | DJ8: 4 | DK8: =DJ8+18 -> 22 | DM8: =IF(DL8=0,0,MAX(0,IF(DL$4>18,IF($D8<=DL$4,2,1),IF($C8<=DL$4,1,0))-DL8+$B8+2)) -> 0 | DO8: =IF(DN8=0,0,MAX(0,IF(DN$4>18,IF($D8<=DN$4,2,1),IF($C8<=DN$4,1,0))-DN8+$B8+2)) -> 0 | DQ8: =IF(DP8=0,0,MAX(0,IF(DP$4>18,IF($D8<=DP$4,2,1),IF($C8<=DP$4,1,0))-DP8+$B8+2)) -> 0 | DS8: =IF(DR8=0,0,MAX(0,IF(DR$4>18,IF($D8<=DR$4,2,1),IF($C8<=DR$4,1,0))-DR8+$B8+2)) -> 0 | DU8: =IF(DT8=0,0,MAX(0,IF(DT$4>18,IF($D8<=DT$4,2,1),IF($C8<=DT$4,1,0))-DT8+$B8+2)) -> 0 | DW8: =IF(DV8=0,0,MAX(0,IF(DV$4>18,IF($D8<=DV$4,2,1),IF($C8<=DV$4,1,0))-DV8+$B8+2)) -> 0 | DY8: =IF(DX8=0,0,MAX(0,IF(DX$4>18,IF($D8<=DX$4,2,1),IF($C8<=DX$4,1,0))-DX8+$B8+2)) -> 0 | EA8: =IF(DZ8=0,0,MAX(0,IF(DZ$4>18,IF($D8<=DZ$4,2,1),IF($C8<=DZ$4,1,0))-DZ8+$B8+2)) -> 0 | EC8: =IF(EB8=0,0,MAX(0,IF(EB$4>18,IF($D8<=EB$4,2,1),IF($C8<=EB$4,1,0))-EB8+$B8+2)) -> 0 | EE8: =IF(ED8=0,0,MAX(0,IF(ED$4>18,IF($D8<=ED$4,2,1),IF($C8<=ED$4,1,0))-ED8+$B8+2)) -> 0 | EG8: =IF(EF8=0,0,MAX(0,IF(EF$4>18,IF($D8<=EF$4,2,1),IF($C8<=EF$4,1,0))-EF8+$B8+2)) -> 0 | EI8: =IF(EH8=0,0,MAX(0,IF(EH$4>18,IF($D8<=EH$4,2,1),IF($C8<=EH$4,1,0))-EH8+$B8+2)) -> 0 | EK8: =IF(EJ8=0,0,MAX(0,IF(EJ$4>18,IF($D8<=EJ$4,2,1),IF($C8<=EJ$4,1,0))-EJ8+$B8+2)) -> 0 | EM8: =IF(EL8=0,0,MAX(0,IF(EL$4>18,IF($D8<=EL$4,2,1),IF($C8<=EL$4,1,0))-EL8+$B8+2)) -> 0 | EO8: =IF(EN8=0,0,MAX(0,IF(EN$4>18,IF($D8<=EN$4,2,1),IF($C8<=EN$4,1,0))-EN8+$B8+2)) -> 0 | EQ8: =IF(EP8=0,0,MAX(0,IF(EP$4>18,IF($D8<=EP$4,2,1),IF($C8<=EP$4,1,0))-EP8+$B8+2)) -> 0 | ES8: 4 | ET8: 4 | EU8: 4 | EV8: =EU8+18 -> 22 | EX8: =IF(EW8=0,0,MAX(0,IF(EW$4>18,IF($D8<=EW$4,2,1),IF($C8<=EW$4,1,0))-EW8+$B8+2)) -> 0 | EZ8: =IF(EY8=0,0,MAX(0,IF(EY$4>18,IF($D8<=EY$4,2,1),IF($C8<=EY$4,1,0))-EY8+$B8+2)) -> 0 | FB8: =IF(FA8=0,0,MAX(0,IF(FA$4>18,IF($D8<=FA$4,2,1),IF($C8<=FA$4,1,0))-FA8+$B8+2)) -> 0 | FD8: =IF(FC8=0,0,MAX(0,IF(FC$4>18,IF($D8<=FC$4,2,1),IF($C8<=FC$4,1,0))-FC8+$B8+2)) -> 0 | FF8: =IF(FE8=0,0,MAX(0,IF(FE$4>18,IF($D8<=FE$4,2,1),IF($C8<=FE$4,1,0))-FE8+$B8+2)) -> 0 | FH8: =IF(FG8=0,0,MAX(0,IF(FG$4>18,IF($D8<=FG$4,2,1),IF($C8<=FG$4,1,0))-FG8+$B8+2)) -> 0 | FJ8: =IF(FI8=0,0,MAX(0,IF(FI$4>18,IF($D8<=FI$4,2,1),IF($C8<=FI$4,1,0))-FI8+$B8+2)) -> 0 | FL8: =IF(FK8=0,0,MAX(0,IF(FK$4>18,IF($D8<=FK$4,2,1),IF($C8<=FK$4,1,0))-FK8+$B8+2)) -> 0 | FN8: =IF(FM8=0,0,MAX(0,IF(FM$4>18,IF($D8<=FM$4,2,1),IF($C8<=FM$4,1,0))-FM8+$B8+2)) -> 0 | FP8: =IF(FO8=0,0,MAX(0,IF(FO$4>18,IF($D8<=FO$4,2,1),IF($C8<=FO$4,1,0))-FO8+$B8+2)) -> 0 | FR8: =IF(FQ8=0,0,MAX(0,IF(FQ$4>18,IF($D8<=FQ$4,2,1),IF($C8<=FQ$4,1,0))-FQ8+$B8+2)) -> 0 | FT8: =IF(FS8=0,0,MAX(0,IF(FS$4>18,IF($D8<=FS$4,2,1),IF($C8<=FS$4,1,0))-FS8+$B8+2)) -> 0 | FV8: =IF(FU8=0,0,MAX(0,IF(FU$4>18,IF($D8<=FU$4,2,1),IF($C8<=FU$4,1,0))-FU8+$B8+2)) -> 0 | FX8: =IF(FW8=0,0,MAX(0,IF(FW$4>18,IF($D8<=FW$4,2,1),IF($C8<=FW$4,1,0))-FW8+$B8+2)) -> 0 | FZ8: =IF(FY8=0,0,MAX(0,IF(FY$4>18,IF($D8<=FY$4,2,1),IF($C8<=FY$4,1,0))-FY8+$B8+2)) -> 0 | GB8: =IF(GA8=0,0,MAX(0,IF(GA$4>18,IF($D8<=GA$4,2,1),IF($C8<=GA$4,1,0))-GA8+$B8+2)) -> 0
